Workbook

Sheet 00_Índice
B1: Índice Template Presupuesto Dotacional
B7: Nombre Hoja | C7: Título | D7: Descripción | J7: Glosario
B8: 01_Identificación | C8: Identificación del Servicio / Contrato | D8: Contiene la información general del servicio, contrato y responsables, así como la caracterización de su continuidad, alcance y condición contractual al momento de la presupuestación. Esta hoja permite contextualizar la dotación presupuestada, identificando servicios continuos, en transición o nuevos, y entregando trazabilidad para el análisis posterior de desviaciones. | J8: Gerencia | L8: Unidad organizacional superior responsable del contrato.
J9: Superintendencia | L9: Subunidad organizacional dependiente de la gerencia que administra directamente el servicio.
J10: Área usuaria | L10: Área operacional o funcional que recibe y utiliza el servicio contratado.
J11: Área AdC MLP | L11: Área organizacional a la que pertenece el Administrador de Contrato.
J12: AdC MLP | L12: Administrador de Contrato designado formalmente por Minera Los Pelambres para la gestión del servicio.
J13: Número de contrato | L13: Identificador único del contrato en el sistema SAP.
J14: Nombre del servicio | L14: Denominación formal del servicio según el instrumento contractual vigente.
J15: Empresa | L15: Razón social de la empresa contratista adjudicada
J16: Tipo de contrato (PU/SA/Mixto) | L16: Modalidad contractual que define la estructura de pago PU Precio Unitario; SA Suma Alzada; Mixto combinación de ambas
J17: Vía financiamiento (OPEX/CAPEX) | L17: Clasificación presupuestaria del servicio según su fuente de financiamiento OPEX gasto operacional recurrente; CAPEX gasto asociado a inversión o proyecto.
J18: CECO o Elemento PEP | L18: Estructura contable donde se imputa el gasto del servicio CECO para operación Elemento PEP u Orden Interna para inversión
J19: Clase de Costo | L19: Clasificación contable del gasto conforme a la estructura SAP.
J20: Fecha inicio contrato | L20: Fecha formal de inicio establecida en el contrato.
... J28: Backoffice | L28: Indica si el contrato contempla dotación administrativa o de soporte no directamente operacional.
B29: 02_Dotación_Contractual | C29: Dotación Contractual Base | D29: Registra la dotación contractual vigente que sirve como línea base de comparación para el proceso de presupuestación y control dotacional. Incluye la caracterización de cargos, tipo de dotación, jornada y factor FTE, permitiendo identificar brechas entre lo contratado y lo presupuestado. | J29: Cargo | L29: Denominación del rol o función definida contractualmente para el servicio.
J30: Clasificación dotacional | L30: Categoría estandarizada que define el tipo de dotación según su fuente de financiamiento (OPEX/CAPEX), su carácter permanente o temporal y, cuando aplica, su modalidad especial (teletrabajo, fuera de faena o campaña). Permite distinguir dotación estructural de variaciones transitorias para efectos de control dotacional y presupuestario.
J33: Permanente/Temporal | L33: Condición estructural del cargo dentro del contrato, indicando si corresponde a dotación estable del servicio o a requerimiento transitorio.Cargo estructural del servicio, requerido de manera continua durante la vigencia contractual y necesario para la operación base.
J36: Alcance presupuestado | L36: Descripción del alcance considerado en el ejercicio presupuestario.
J37: Tipo temporal | L37: Clasificación específica aplicable cuando el cargo es temporal.
L38: Temporal continuo Dotación transitoria requerida de forma continua por un período definido.
L39: Temporal discontinuo Dotación transitoria que se activa en períodos o eventos específicos.
L40: Temporal parcial Dotación transitoria que cubre solo parte de la jornada o del alcance del servicio
J41: Nivel de madurez esperado (1/2/3) | L41: Nivel de desarrollo del control dotacional proyectado según estándar metodológico GST.
J42: Mantención mayor / campaña | L42: Dotación adicional asociada a actividades extraordinarias de mantención o campañas operacionales.
J43: Directa/Indirecta | L43: Naturaleza de la dotación respecto de la operación.
L44: Directa Dotación que ejecuta directamente la actividad principal del servicio.
L45: Indirecta Dotación de apoyo o soporte que no participa directamente en la ejecución operacional.
J46: Modalidad trabajo | L46: Esquema bajo el cual se ejecuta la función.
J47: % Teletrabajo | L47: Porcentaje de jornada ejecutado en modalidad remota.
J48: Turno | L48: Estructura de turno contractual asociada al cargo.
J49: Jornada | L49: Tipo de jornada laboral asociada.
J50: N° personas contractuales | L50: Cantidad de trabajadores comprometidos contractualmente para el cargo. Campo numérico.
J51: N° días presentes mes | L51: Cantidad de días efectivos considerados para el cálculo mensual.
J52: N° días mes calendario | L52: Total de días del mes calendario correspondiente. Campo numérico.
J53: Factor FTE mes | L53: Factor de equivalencia utilizado para convertir la dotación contractual a FTE mensual.
J54: HH día turno | L54: Horas hombre asociadas a un día de turno del cargo.
J55: FTE contractual (mes) | L55: Dotación equivalente a tiempo completo correspondiente al cargo en el mes. Campo calculado
J56: Observación contractual | L56: Campo de texto libre destinado a registrar aclaraciones relevantes sobre condiciones particulares del cargo.
...

Sheet 01_Identificación
A1: Gerencia | B1: Superintendencia | C1: Área usuaria | D1: Área AdC MLP | E1: AdC MLP | F1: Número de contrato | G1: Nombre del servicio | H1: Empresa | I1: Tipo de contrato (PU/SA/Mixto) | J1: Vía financiamiento (OPEX/CAPEX) | K1: Centro de costo | L1: Fecha inicio contrato | M1: Fecha término contrato | N1: Tipo continuidad del servicio | O1: Alcance presupuestado | P1: Fecha inicio efectiva | Q1: Fecha término efectiva | R1: Condición contractual al presupuestar | S1: Servicio origen/destino | T1: Impacto esperado en dotación | U1: Nivel de madurez esperado (1/2/3) | V1: Backoffice

Sheet 02_Dotación_Contractual
A1: Cargo | B1: Clasificación dotacional | C1: Permanente/Temporal | D1: Tipo temporal | E1: Directa/Indirecta | F1: Turno | G1: Jornada | H1: N° personas contractuales | I1: N° días presentes mes | J1: N° días mes calendario | K1: Factor FTE mes | L1: HH día turno | M1: FTE contractual (mes) | N1: Observación contractual | O1: Modalidad trabajo | P1: %Teletrabajo | Q1: *Validación de categorización por GST
K2: =IFERROR(VLOOKUP(J2,tbFactorMes,2,FALSE),"") | L2: =IFERROR(VLOOKUP(F2,tbTurnos,3,FALSE),"") | M2: =IFERROR((I2*L2)/K2,0) -> 0 | Q2: Check (si/no)
K3: =IFERROR(VLOOKUP(J3,tbFactorMes,2,FALSE),"") | L3: =IFERROR(VLOOKUP(F3,tbTurnos,3,FALSE),"") | M3: =IFERROR((I3*L3)/K3,0) -> 0
K4: =IFERROR(VLOOKUP(J4,tbFactorMes,2,FALSE),"") | L4: =IFERROR(VLOOKUP(F4,tbTurnos,3,FALSE),"") | M4: =IFERROR((I4*L4)/K4,0) -> 0
K5: =IFERROR(VLOOKUP(J5,tbFactorMes,2,FALSE),"") | L5: =IFERROR(VLOOKUP(F5,tbTurnos,3,FALSE),"") | M5: =IFERROR((I5*L5)/K5,0) -> 0
K6: =IFERROR(VLOOKUP(J6,tbFactorMes,2,FALSE),"") | L6: =IFERROR(VLOOKUP(F6,tbTurnos,3,FALSE),"") | M6: =IFERROR((I6*L6)/K6,0) -> 0
K7: =IFERROR(VLOOKUP(J7,tbFactorMes,2,FALSE),"") | L7: =IFERROR(VLOOKUP(F7,tbTurnos,3,FALSE),"") | M7: =IFERROR((I7*L7)/K7,0) -> 0
K8: =IFERROR(VLOOKUP(J8,tbFactorMes,2,FALSE),"") | L8: =IFERROR(VLOOKUP(F8,tbTurnos,3,FALSE),"") | M8: =IFERROR((I8*L8)/K8,0) -> 0
K9: =IFERROR(VLOOKUP(J9,tbFactorMes,2,FALSE),"") | L9: =IFERROR(VLOOKUP(F9,tbTurnos,3,FALSE),"") | M9: =IFERROR((I9*L9)/K9,0) -> 0
K10: =IFERROR(VLOOKUP(J10,tbFactorMes,2,FALSE),"") | L10: =IFERROR(VLOOKUP(F10,tbTurnos,3,FALSE),"") | M10: =IFERROR((I10*L10)/K10,0) -> 0
K11: =IFERROR(VLOOKUP(J11,tbFactorMes,2,FALSE),"") | L11: =IFERROR(VLOOKUP(F11,tbTurnos,3,FALSE),"") | M11: =IFERROR((I11*L11)/K11,0) -> 0
K12: =IFERROR(VLOOKUP(J12,tbFactorMes,2,FALSE),"") | L12: =IFERROR(VLOOKUP(F12,tbTurnos,3,FALSE),"") | M12: =IFERROR((I12*L12)/K12,0) -> 0
K13: =IFERROR(VLOOKUP(J13,tbFactorMes,2,FALSE),"") | L13: =IFERROR(VLOOKUP(F13,tbTurnos,3,FALSE),"") | M13: =IFERROR((I13*L13)/K13,0) -> 0
K14: =IFERROR(VLOOKUP(J14,tbFactorMes,2,FALSE),"") | L14: =IFERROR(VLOOKUP(F14,tbTurnos,3,FALSE),"") | M14: =IFERROR((I14*L14)/K14,0) -> 0
... K500: =IFERROR(VLOOKUP(J500,tbFactorMes,2,FALSE),"") | L500: =IFERROR(VLOOKUP(F500,tbTurnos,3,FALSE),"") | M500: =IFERROR((I500*L500)/K500,0) -> 0

Sheet 03_Supuestos_Ratios
A1: Tipo de servicio | B1: Actividad / frente de trabajo | C1: Unidad | D1: Cantidad mensual | E1: Rendimiento (HH por unidad) | F1: HH requeridas | G1: Fuente ratio (Histórico/Benchmark/BT) | H1: Comentarios
F2: =IFERROR(D2*E2,0) -> 0
F3: =IFERROR(D3*E3,0) -> 0
F4: =IFERROR(D4*E4,0) -> 0
F5: =IFERROR(D5*E5,0) -> 0
F6: =IFERROR(D6*E6,0) -> 0
F7: =IFERROR(D7*E7,0) -> 0
F8: =IFERROR(D8*E8,0) -> 0
F9: =IFERROR(D9*E9,0) -> 0
F10: =IFERROR(D10*E10,0) -> 0
F11: =IFERROR(D11*E11,0) -> 0
F12: =IFERROR(D12*E12,0) -> 0
F13: =IFERROR(D13*E13,0) -> 0
... F499: =IFERROR(D499*E499,0) -> 0

Sheet 04_Ppto_FTE_Mensual
A1: Cargo | B1: Clasificación dotacional (cerrada) | C1: Permanente/Temporal | D1: Tipo temporal | E1: Directa/Indirecta | F1: Turno | G1: Jornada | H1: Modalidad trabajo | I1: %Teletrabajo | J1: N° personas | K1: HH día turno (ref) | L1: Días presentes Ene | M1: Días mes Ene | N1: Factor mes Ene | O1: FTE Ene | P1: Días presentes Feb | Q1: Días mes Feb | R1: Factor mes Feb | S1: FTE Feb | T1: Días presentes Mar | U1: Días mes Mar | V1: Factor mes Mar | W1: FTE Mar | X1: Días presentes Abr | Y1: Días mes Abr | Z1: Factor mes Abr | AA1: FTE Abr | AB1: Días presentes May | AC1: Días mes May | AD1: Factor mes May | AE1: FTE May | AF1: Días presentes Jun | AG1: Días mes Jun | AH1: Factor mes Jun | AI1: FTE Jun | AJ1: Días presentes Jul | AK1: Días mes Jul | AL1: Factor mes Jul | AM1: FTE Jul | AN1: Días presentes Ago | AO1: Días mes Ago | AP1: Factor mes Ago | AQ1: FTE Ago | AR1: Días presentes Sep | AS1: Días mes Sep | AT1: Factor mes Sep | AU1: FTE Sep | AV1: Días presentes Oct | AW1: Días mes Oct | AX1: Factor mes Oct | AY1: FTE Oct | AZ1: Días presentes Nov | BA1: Días mes Nov | BB1: Factor mes Nov | BC1: FTE Nov | BD1: Días presentes Dic | BE1: Días mes Dic | BF1: Factor mes Dic | BG1: FTE Dic | BH1: FTE anual (suma meses) | BI1: FTE terreno anual | BJ1: Observaciones
K2: =IFERROR(VLOOKUP(F2,tbTurnos,3,FALSE),"") | N2: =IFERROR(VLOOKUP(M2,tbFactorMes[],2,FALSE),"") | O2: =IFERROR((L2*$K2)/N2,0)*$J2 -> 0 | R2: =IFERROR(VLOOKUP(Q2,tbFactorMes,2,FALSE),"") | S2: =IFERROR((P2*$K2)/R2,0)*$J2 -> 0 | V2: =IFERROR(VLOOKUP(U2,tbFactorMes,2,FALSE),"") | W2: =IFERROR((T2*$K2)/V2,0)*$J2 -> 0 | Z2: =IFERROR(VLOOKUP(Y2,tbFactorMes,2,FALSE),"") | AA2: =IFERROR((X2*$K2)/Z2,0)*$J2 -> 0 | AD2: =IFERROR(VLOOKUP(AC2,tbFactorMes,2,FALSE),"") | AE2: =IFERROR((AB2*$K2)/AD2,0)*$J2 -> 0 | AH2: =IFERROR(VLOOKUP(AG2,tbFactorMes,2,FALSE),"") | AI2: =IFERROR((AF2*$K2)/AH2,0)*$J2 -> 0 | AL2: =IFERROR(VLOOKUP(AK2,tbFactorMes,2,FALSE),"") | AM2: =IFERROR((AJ2*$K2)/AL2,0)*$J2 -> 0 | AP2: =IFERROR(VLOOKUP(AO2,tbFactorMes,2,FALSE),"") | AQ2: =IFERROR((AN2*$K2)/AP2,0)*$J2 -> 0 | AT2: =IFERROR(VLOOKUP(AS2,tbFactorMes,2,FALSE),"") | AU2: =IFERROR((AR2*$K2)/AT2,0)*$J2 -> 0 | AX2: =IFERROR(VLOOKUP(AW2,tbFactorMes,2,FALSE),"") | AY2: =IFERROR((AV2*$K2)/AX2,0)*$J2 -> 0 | BB2: =IFERROR(VLOOKUP(BA2,tbFactorMes,2,FALSE),"") | BC2: =IFERROR((AZ2*$K2)/BB2,0)*$J2 -> 0 | BF2: =IFERROR(VLOOKUP(BE2,tbFactorMes,2,FALSE),"") | BG2: =IFERROR((BD2*$K2)/BF2,0)*$J2 -> 0 | BH2: =IFERROR(SUM(O2,S2,W2,AA2,AE2,AI2,AM2,AQ2,AU2,AY2,BC2,BG2),0) -> 0 | BI2: =IFERROR(BH2*(1-$I2),0) -> 0
K3: =IFERROR(VLOOKUP(F3,tbTurnos,3,FALSE),"") | N3: =IFERROR(VLOOKUP(M3,tbFactorMes,2,FALSE),"") | O3: =IFERROR((L3*$K3)/N3,0)*$J3 -> 0 | R3: =IFERROR(VLOOKUP(Q3,tbFactorMes,2,FALSE),"") | S3: =IFERROR((P3*$K3)/R3,0)*$J3 -> 0 | V3: =IFERROR(VLOOKUP(U3,tbFactorMes,2,FALSE),"") | W3: =IFERROR((T3*$K3)/V3,0)*$J3 -> 0 | Z3: =IFERROR(VLOOKUP(Y3,tbFactorMes,2,FALSE),"") | AA3: =IFERROR((X3*$K3)/Z3,0)*$J3 -> 0 | AD3: =IFERROR(VLOOKUP(AC3,tbFactorMes,2,FALSE),"") | AE3: =IFERROR((AB3*$K3)/AD3,0)*$J3 -> 0 | AH3: =IFERROR(VLOOKUP(AG3,tbFactorMes,2,FALSE),"") | AI3: =IFERROR((AF3*$K3)/AH3,0)*$J3 -> 0 | AL3: =IFERROR(VLOOKUP(AK3,tbFactorMes,2,FALSE),"") | AM3: =IFERROR((AJ3*$K3)/AL3,0)*$J3 -> 0 | AP3: =IFERROR(VLOOKUP(AO3,tbFactorMes,2,FALSE),"") | AQ3: =IFERROR((AN3*$K3)/AP3,0)*$J3 -> 0 | AT3: =IFERROR(VLOOKUP(AS3,tbFactorMes,2,FALSE),"") | AU3: =IFERROR((AR3*$K3)/AT3,0)*$J3 -> 0 | AX3: =IFERROR(VLOOKUP(AW3,tbFactorMes,2,FALSE),"") | AY3: =IFERROR((AV3*$K3)/AX3,0)*$J3 -> 0 | BB3: =IFERROR(VLOOKUP(BA3,tbFactorMes,2,FALSE),"") | BC3: =IFERROR((AZ3*$K3)/BB3,0)*$J3 -> 0 | BF3: =IFERROR(VLOOKUP(BE3,tbFactorMes,2,FALSE),"") | BG3: =IFERROR((BD3*$K3)/BF3,0)*$J3 -> 0 | BH3: =IFERROR(SUM(O3,S3,W3,AA3,AE3,AI3,AM3,AQ3,AU3,AY3,BC3,BG3),0) -> 0 | BI3: =IFERROR(BH3*(1-$I3),0) -> 0
K4: =IFERROR(VLOOKUP(F4,tbTurnos,3,FALSE),"") | N4: =IFERROR(VLOOKUP(M4,tbFactorMes,2,FALSE),"") | O4: =IFERROR((L4*$K4)/N4,0)*$J4 -> 0 | R4: =IFERROR(VLOOKUP(Q4,tbFactorMes,2,FALSE),"") | S4: =IFERROR((P4*$K4)/R4,0)*$J4 -> 0 | V4: =IFERROR(VLOOKUP(U4,tbFactorMes,2,FALSE),"") | W4: =IFERROR((T4*$K4)/V4,0)*$J4 -> 0 | Z4: =IFERROR(VLOOKUP(Y4,tbFactorMes,2,FALSE),"") | AA4: =IFERROR((X4*$K4)/Z4,0)*$J4 -> 0 | AD4: =IFERROR(VLOOKUP(AC4,tbFactorMes,2,FALSE),"") | AE4: =IFERROR((AB4*$K4)/AD4,0)*$J4 -> 0 | AH4: =IFERROR(VLOOKUP(AG4,tbFactorMes,2,FALSE),"") | AI4: =IFERROR((AF4*$K4)/AH4,0)*$J4 -> 0 | AL4: =IFERROR(VLOOKUP(AK4,tbFactorMes,2,FALSE),"") | AM4: =IFERROR((AJ4*$K4)/AL4,0)*$J4 -> 0 | AP4: =IFERROR(VLOOKUP(AO4,tbFactorMes,2,FALSE),"") | AQ4: =IFERROR((AN4*$K4)/AP4,0)*$J4 -> 0 | AT4: =IFERROR(VLOOKUP(AS4,tbFactorMes,2,FALSE),"") | AU4: =IFERROR((AR4*$K4)/AT4,0)*$J4 -> 0 | AX4: =IFERROR(VLOOKUP(AW4,tbFactorMes,2,FALSE),"") | AY4: =IFERROR((AV4*$K4)/AX4,0)*$J4 -> 0 | BB4: =IFERROR(VLOOKUP(BA4,tbFactorMes,2,FALSE),"") | BC4: =IFERROR((AZ4*$K4)/BB4,0)*$J4 -> 0 | BF4: =IFERROR(VLOOKUP(BE4,tbFactorMes,2,FALSE),"") | BG4: =IFERROR((BD4*$K4)/BF4,0)*$J4 -> 0 | BH4: =IFERROR(SUM(O4,S4,W4,AA4,AE4,AI4,AM4,AQ4,AU4,AY4,BC4,BG4),0) -> 0 | BI4: =IFERROR(BH4*(1-$I4),0) -> 0
K5: =IFERROR(VLOOKUP(F5,tbTurnos,3,FALSE),"") | N5: =IFERROR(VLOOKUP(M5,tbFactorMes,2,FALSE),"") | O5: =IFERROR((L5*$K5)/N5,0)*$J5 -> 0 | R5: =IFERROR(VLOOKUP(Q5,tbFactorMes,2,FALSE),"") | S5: =IFERROR((P5*$K5)/R5,0)*$J5 -> 0 | V5: =IFERROR(VLOOKUP(U5,tbFactorMes,2,FALSE),"") | W5: =IFERROR((T5*$K5)/V5,0)*$J5 -> 0 | Z5: =IFERROR(VLOOKUP(Y5,tbFactorMes,2,FALSE),"") | AA5: =IFERROR((X5*$K5)/Z5,0)*$J5 -> 0 | AD5: =IFERROR(VLOOKUP(AC5,tbFactorMes,2,FALSE),"") | AE5: =IFERROR((AB5*$K5)/AD5,0)*$J5 -> 0 | AH5: =IFERROR(VLOOKUP(AG5,tbFactorMes,2,FALSE),"") | AI5: =IFERROR((AF5*$K5)/AH5,0)*$J5 -> 0 | AL5: =IFERROR(VLOOKUP(AK5,tbFactorMes,2,FALSE),"") | AM5: =IFERROR((AJ5*$K5)/AL5,0)*$J5 -> 0 | AP5: =IFERROR(VLOOKUP(AO5,tbFactorMes,2,FALSE),"") | AQ5: =IFERROR((AN5*$K5)/AP5,0)*$J5 -> 0 | AT5: =IFERROR(VLOOKUP(AS5,tbFactorMes,2,FALSE),"") | AU5: =IFERROR((AR5*$K5)/AT5,0)*$J5 -> 0 | AX5: =IFERROR(VLOOKUP(AW5,tbFactorMes,2,FALSE),"") | AY5: =IFERROR((AV5*$K5)/AX5,0)*$J5 -> 0 | BB5: =IFERROR(VLOOKUP(BA5,tbFactorMes,2,FALSE),"") | BC5: =IFERROR((AZ5*$K5)/BB5,0)*$J5 -> 0 | BF5: =IFERROR(VLOOKUP(BE5,tbFactorMes,2,FALSE),"") | BG5: =IFERROR((BD5*$K5)/BF5,0)*$J5 -> 0 | BH5: =IFERROR(SUM(O5,S5,W5,AA5,AE5,AI5,AM5,AQ5,AU5,AY5,BC5,BG5),0) -> 0 | BI5: =IFERROR(BH5*(1-$I5),0) -> 0
K6: =IFERROR(VLOOKUP(F6,tbTurnos,3,FALSE),"") | N6: =IFERROR(VLOOKUP(M6,tbFactorMes[],2,FALSE),"") | O6: =IFERROR((L6*$K6)/N6,0)*$J6 -> 0 | R6: =IFERROR(VLOOKUP(Q6,tbFactorMes,2,FALSE),"") | S6: =IFERROR((P6*$K6)/R6,0)*$J6 -> 0 | V6: =IFERROR(VLOOKUP(U6,tbFactorMes,2,FALSE),"") | W6: =IFERROR((T6*$K6)/V6,0)*$J6 -> 0 | Z6: =IFERROR(VLOOKUP(Y6,tbFactorMes,2,FALSE),"") | AA6: =IFERROR((X6*$K6)/Z6,0)*$J6 -> 0 | AD6: =IFERROR(VLOOKUP(AC6,tbFactorMes,2,FALSE),"") | AE6: =IFERROR((AB6*$K6)/AD6,0)*$J6 -> 0 | AH6: =IFERROR(VLOOKUP(AG6,tbFactorMes,2,FALSE),"") | AI6: =IFERROR((AF6*$K6)/AH6,0)*$J6 -> 0 | AL6: =IFERROR(VLOOKUP(AK6,tbFactorMes,2,FALSE),"") | AM6: =IFERROR((AJ6*$K6)/AL6,0)*$J6 -> 0 | AP6: =IFERROR(VLOOKUP(AO6,tbFactorMes,2,FALSE),"") | AQ6: =IFERROR((AN6*$K6)/AP6,0)*$J6 -> 0 | AT6: =IFERROR(VLOOKUP(AS6,tbFactorMes,2,FALSE),"") | AU6: =IFERROR((AR6*$K6)/AT6,0)*$J6 -> 0 | AX6: =IFERROR(VLOOKUP(AW6,tbFactorMes,2,FALSE),"") | AY6: =IFERROR((AV6*$K6)/AX6,0)*$J6 -> 0 | BB6: =IFERROR(VLOOKUP(BA6,tbFactorMes,2,FALSE),"") | BC6: =IFERROR((AZ6*$K6)/BB6,0)*$J6 -> 0 | BF6: =IFERROR(VLOOKUP(BE6,tbFactorMes,2,FALSE),"") | BG6: =IFERROR((BD6*$K6)/BF6,0)*$J6 -> 0 | BH6: =IFERROR(SUM(O6,S6,W6,AA6,AE6,AI6,AM6,AQ6,AU6,AY6,BC6,BG6),0) -> 0 | BI6: =IFERROR(BH6*(1-$I6),0) -> 0
K7: =IFERROR(VLOOKUP(F7,tbTurnos,3,FALSE),"") | N7: =IFERROR(VLOOKUP(M7,tbFactorMes[],2,FALSE),"") | O7: =IFERROR((L7*$K7)/N7,0)*$J7 -> 0 | R7: =IFERROR(VLOOKUP(Q7,tbFactorMes,2,FALSE),"") | S7: =IFERROR((P7*$K7)/R7,0)*$J7 -> 0 | V7: =IFERROR(VLOOKUP(U7,tbFactorMes,2,FALSE),"") | W7: =IFERROR((T7*$K7)/V7,0)*$J7 -> 0 | Z7: =IFERROR(VLOOKUP(Y7,tbFactorMes,2,FALSE),"") | AA7: =IFERROR((X7*$K7)/Z7,0)*$J7 -> 0 | AD7: =IFERROR(VLOOKUP(AC7,tbFactorMes,2,FALSE),"") | AE7: =IFERROR((AB7*$K7)/AD7,0)*$J7 -> 0 | AH7: =IFERROR(VLOOKUP(AG7,tbFactorMes,2,FALSE),"") | AI7: =IFERROR((AF7*$K7)/AH7,0)*$J7 -> 0 | AL7: =IFERROR(VLOOKUP(AK7,tbFactorMes,2,FALSE),"") | AM7: =IFERROR((AJ7*$K7)/AL7,0)*$J7 -> 0 | AP7: =IFERROR(VLOOKUP(AO7,tbFactorMes,2,FALSE),"") | AQ7: =IFERROR((AN7*$K7)/AP7,0)*$J7 -> 0 | AT7: =IFERROR(VLOOKUP(AS7,tbFactorMes,2,FALSE),"") | AU7: =IFERROR((AR7*$K7)/AT7,0)*$J7 -> 0 | AX7: =IFERROR(VLOOKUP(AW7,tbFactorMes,2,FALSE),"") | AY7: =IFERROR((AV7*$K7)/AX7,0)*$J7 -> 0 | BB7: =IFERROR(VLOOKUP(BA7,tbFactorMes,2,FALSE),"") | BC7: =IFERROR((AZ7*$K7)/BB7,0)*$J7 -> 0 | BF7: =IFERROR(VLOOKUP(BE7,tbFactorMes,2,FALSE),"") | BG7: =IFERROR((BD7*$K7)/BF7,0)*$J7 -> 0 | BH7: =IFERROR(SUM(O7,S7,W7,AA7,AE7,AI7,AM7,AQ7,AU7,AY7,BC7,BG7),0) -> 0 | BI7: =IFERROR(BH7*(1-$I7),0) -> 0
K8: =IFERROR(VLOOKUP(F8,tbTurnos,3,FALSE),"") | N8: =IFERROR(VLOOKUP(M8,tbFactorMes[],2,FALSE),"") | O8: =IFERROR((L8*$K8)/N8,0)*$J8 -> 0 | R8: =IFERROR(VLOOKUP(Q8,tbFactorMes,2,FALSE),"") | S8: =IFERROR((P8*$K8)/R8,0)*$J8 -> 0 | V8: =IFERROR(VLOOKUP(U8,tbFactorMes,2,FALSE),"") | W8: =IFERROR((T8*$K8)/V8,0)*$J8 -> 0 | Z8: =IFERROR(VLOOKUP(Y8,tbFactorMes,2,FALSE),"") | AA8: =IFERROR((X8*$K8)/Z8,0)*$J8 -> 0 | AD8: =IFERROR(VLOOKUP(AC8,tbFactorMes,2,FALSE),"") | AE8: =IFERROR((AB8*$K8)/AD8,0)*$J8 -> 0 | AH8: =IFERROR(VLOOKUP(AG8,tbFactorMes,2,FALSE),"") | AI8: =IFERROR((AF8*$K8)/AH8,0)*$J8 -> 0 | AL8: =IFERROR(VLOOKUP(AK8,tbFactorMes,2,FALSE),"") | AM8: =IFERROR((AJ8*$K8)/AL8,0)*$J8 -> 0 | AP8: =IFERROR(VLOOKUP(AO8,tbFactorMes,2,FALSE),"") | AQ8: =IFERROR((AN8*$K8)/AP8,0)*$J8 -> 0 | AT8: =IFERROR(VLOOKUP(AS8,tbFactorMes,2,FALSE),"") | AU8: =IFERROR((AR8*$K8)/AT8,0)*$J8 -> 0 | AX8: =IFERROR(VLOOKUP(AW8,tbFactorMes,2,FALSE),"") | AY8: =IFERROR((AV8*$K8)/AX8,0)*$J8 -> 0 | BB8: =IFERROR(VLOOKUP(BA8,tbFactorMes,2,FALSE),"") | BC8: =IFERROR((AZ8*$K8)/BB8,0)*$J8 -> 0 | BF8: =IFERROR(VLOOKUP(BE8,tbFactorMes,2,FALSE),"") | BG8: =IFERROR((BD8*$K8)/BF8,0)*$J8 -> 0 | BH8: =IFERROR(SUM(O8,S8,W8,AA8,AE8,AI8,AM8,AQ8,AU8,AY8,BC8,BG8),0) -> 0 | BI8: =IFERROR(BH8*(1-$I8),0) -> 0
K9: =IFERROR(VLOOKUP(F9,tbTurnos,3,FALSE),"") | N9: =IFERROR(VLOOKUP(M9,tbFactorMes[],2,FALSE),"") | O9: =IFERROR((L9*$K9)/N9,0)*$J9 -> 0 | R9: =IFERROR(VLOOKUP(Q9,tbFactorMes,2,FALSE),"") | S9: =IFERROR((P9*$K9)/R9,0)*$J9 -> 0 | V9: =IFERROR(VLOOKUP(U9,tbFactorMes,2,FALSE),"") | W9: =IFERROR((T9*$K9)/V9,0)*$J9 -> 0 | Z9: =IFERROR(VLOOKUP(Y9,tbFactorMes,2,FALSE),"") | AA9: =IFERROR((X9*$K9)/Z9,0)*$J9 -> 0 | AD9: =IFERROR(VLOOKUP(AC9,tbFactorMes,2,FALSE),"") | AE9: =IFERROR((AB9*$K9)/AD9,0)*$J9 -> 0 | AH9: =IFERROR(VLOOKUP(AG9,tbFactorMes,2,FALSE),"") | AI9: =IFERROR((AF9*$K9)/AH9,0)*$J9 -> 0 | AL9: =IFERROR(VLOOKUP(AK9,tbFactorMes,2,FALSE),"") | AM9: =IFERROR((AJ9*$K9)/AL9,0)*$J9 -> 0 | AP9: =IFERROR(VLOOKUP(AO9,tbFactorMes,2,FALSE),"") | AQ9: =IFERROR((AN9*$K9)/AP9,0)*$J9 -> 0 | AT9: =IFERROR(VLOOKUP(AS9,tbFactorMes,2,FALSE),"") | AU9: =IFERROR((AR9*$K9)/AT9,0)*$J9 -> 0 | AX9: =IFERROR(VLOOKUP(AW9,tbFactorMes,2,FALSE),"") | AY9: =IFERROR((AV9*$K9)/AX9,0)*$J9 -> 0 | BB9: =IFERROR(VLOOKUP(BA9,tbFactorMes,2,FALSE),"") | BC9: =IFERROR((AZ9*$K9)/BB9,0)*$J9 -> 0 | BF9: =IFERROR(VLOOKUP(BE9,tbFactorMes,2,FALSE),"") | BG9: =IFERROR((BD9*$K9)/BF9,0)*$J9 -> 0 | BH9: =IFERROR(SUM(O9,S9,W9,AA9,AE9,AI9,AM9,AQ9,AU9,AY9,BC9,BG9),0) -> 0 | BI9: =IFERROR(BH9*(1-$I9),0) -> 0
K10: =IFERROR(VLOOKUP(F10,tbTurnos,3,FALSE),"") | N10: =IFERROR(VLOOKUP(M10,tbFactorMes[],2,FALSE),"") | O10: =IFERROR((L10*$K10)/N10,0)*$J10 -> 0 | R10: =IFERROR(VLOOKUP(Q10,tbFactorMes,2,FALSE),"") | S10: =IFERROR((P10*$K10)/R10,0)*$J10 -> 0 | V10: =IFERROR(VLOOKUP(U10,tbFactorMes,2,FALSE),"") | W10: =IFERROR((T10*$K10)/V10,0)*$J10 -> 0 | Z10: =IFERROR(VLOOKUP(Y10,tbFactorMes,2,FALSE),"") | AA10: =IFERROR((X10*$K10)/Z10,0)*$J10 -> 0 | AD10: =IFERROR(VLOOKUP(AC10,tbFactorMes,2,FALSE),"") | AE10: =IFERROR((AB10*$K10)/AD10,0)*$J10 -> 0 | AH10: =IFERROR(VLOOKUP(AG10,tbFactorMes,2,FALSE),"") | AI10: =IFERROR((AF10*$K10)/AH10,0)*$J10 -> 0 | AL10: =IFERROR(VLOOKUP(AK10,tbFactorMes,2,FALSE),"") | AM10: =IFERROR((AJ10*$K10)/AL10,0)*$J10 -> 0 | AP10: =IFERROR(VLOOKUP(AO10,tbFactorMes,2,FALSE),"") | AQ10: =IFERROR((AN10*$K10)/AP10,0)*$J10 -> 0 | AT10: =IFERROR(VLOOKUP(AS10,tbFactorMes,2,FALSE),"") | AU10: =IFERROR((AR10*$K10)/AT10,0)*$J10 -> 0 | AX10: =IFERROR(VLOOKUP(AW10,tbFactorMes,2,FALSE),"") | AY10: =IFERROR((AV10*$K10)/AX10,0)*$J10 -> 0 | BB10: =IFERROR(VLOOKUP(BA10,tbFactorMes,2,FALSE),"") | BC10: =IFERROR((AZ10*$K10)/BB10,0)*$J10 -> 0 | BF10: =IFERROR(VLOOKUP(BE10,tbFactorMes,2,FALSE),"") | BG10: =IFERROR((BD10*$K10)/BF10,0)*$J10 -> 0 | BH10: =IFERROR(SUM(O10,S10,W10,AA10,AE10,AI10,AM10,AQ10,AU10,AY10,BC10,BG10),0) -> 0 | BI10: =IFERROR(BH10*(1-$I10),0) -> 0
K11: =IFERROR(VLOOKUP(F11,tbTurnos,3,FALSE),"") | N11: =IFERROR(VLOOKUP(M11,tbFactorMes[],2,FALSE),"") | O11: =IFERROR((L11*$K11)/N11,0)*$J11 -> 0 | R11: =IFERROR(VLOOKUP(Q11,tbFactorMes,2,FALSE),"") | S11: =IFERROR((P11*$K11)/R11,0)*$J11 -> 0 | V11: =IFERROR(VLOOKUP(U11,tbFactorMes,2,FALSE),"") | W11: =IFERROR((T11*$K11)/V11,0)*$J11 -> 0 | Z11: =IFERROR(VLOOKUP(Y11,tbFactorMes,2,FALSE),"") | AA11: =IFERROR((X11*$K11)/Z11,0)*$J11 -> 0 | AD11: =IFERROR(VLOOKUP(AC11,tbFactorMes,2,FALSE),"") | AE11: =IFERROR((AB11*$K11)/AD11,0)*$J11 -> 0 | AH11: =IFERROR(VLOOKUP(AG11,tbFactorMes,2,FALSE),"") | AI11: =IFERROR((AF11*$K11)/AH11,0)*$J11 -> 0 | AL11: =IFERROR(VLOOKUP(AK11,tbFactorMes,2,FALSE),"") | AM11: =IFERROR((AJ11*$K11)/AL11,0)*$J11 -> 0 | AP11: =IFERROR(VLOOKUP(AO11,tbFactorMes,2,FALSE),"") | AQ11: =IFERROR((AN11*$K11)/AP11,0)*$J11 -> 0 | AT11: =IFERROR(VLOOKUP(AS11,tbFactorMes,2,FALSE),"") | AU11: =IFERROR((AR11*$K11)/AT11,0)*$J11 -> 0 | AX11: =IFERROR(VLOOKUP(AW11,tbFactorMes,2,FALSE),"") | AY11: =IFERROR((AV11*$K11)/AX11,0)*$J11 -> 0 | BB11: =IFERROR(VLOOKUP(BA11,tbFactorMes,2,FALSE),"") | BC11: =IFERROR((AZ11*$K11)/BB11,0)*$J11 -> 0 | BF11: =IFERROR(VLOOKUP(BE11,tbFactorMes,2,FALSE),"") | BG11: =IFERROR((BD11*$K11)/BF11,0)*$J11 -> 0 | BH11: =IFERROR(SUM(O11,S11,W11,AA11,AE11,AI11,AM11,AQ11,AU11,AY11,BC11,BG11),0) -> 0 | BI11: =IFERROR(BH11*(1-$I11),0) -> 0
K12: =IFERROR(VLOOKUP(F12,tbTurnos,3,FALSE),"") | N12: =IFERROR(VLOOKUP(M12,tbFactorMes[],2,FALSE),"") | O12: =IFERROR((L12*$K12)/N12,0)*$J12 -> 0 | R12: =IFERROR(VLOOKUP(Q12,tbFactorMes,2,FALSE),"") | S12: =IFERROR((P12*$K12)/R12,0)*$J12 -> 0 | V12: =IFERROR(VLOOKUP(U12,tbFactorMes,2,FALSE),"") | W12: =IFERROR((T12*$K12)/V12,0)*$J12 -> 0 | Z12: =IFERROR(VLOOKUP(Y12,tbFactorMes,2,FALSE),"") | AA12: =IFERROR((X12*$K12)/Z12,0)*$J12 -> 0 | AD12: =IFERROR(VLOOKUP(AC12,tbFactorMes,2,FALSE),"") | AE12: =IFERROR((AB12*$K12)/AD12,0)*$J12 -> 0 | AH12: =IFERROR(VLOOKUP(AG12,tbFactorMes,2,FALSE),"") | AI12: =IFERROR((AF12*$K12)/AH12,0)*$J12 -> 0 | AL12: =IFERROR(VLOOKUP(AK12,tbFactorMes,2,FALSE),"") | AM12: =IFERROR((AJ12*$K12)/AL12,0)*$J12 -> 0 | AP12: =IFERROR(VLOOKUP(AO12,tbFactorMes,2,FALSE),"") | AQ12: =IFERROR((AN12*$K12)/AP12,0)*$J12 -> 0 | AT12: =IFERROR(VLOOKUP(AS12,tbFactorMes,2,FALSE),"") | AU12: =IFERROR((AR12*$K12)/AT12,0)*$J12 -> 0 | AX12: =IFERROR(VLOOKUP(AW12,tbFactorMes,2,FALSE),"") | AY12: =IFERROR((AV12*$K12)/AX12,0)*$J12 -> 0 | BB12: =IFERROR(VLOOKUP(BA12,tbFactorMes,2,FALSE),"") | BC12: =IFERROR((AZ12*$K12)/BB12,0)*$J12 -> 0 | BF12: =IFERROR(VLOOKUP(BE12,tbFactorMes,2,FALSE),"") | BG12: =IFERROR((BD12*$K12)/BF12,0)*$J12 -> 0 | BH12: =IFERROR(SUM(O12,S12,W12,AA12,AE12,AI12,AM12,AQ12,AU12,AY12,BC12,BG12),0) -> 0 | BI12: =IFERROR(BH12*(1-$I12),0) -> 0
K13: =IFERROR(VLOOKUP(F13,tbTurnos,3,FALSE),"") | N13: =IFERROR(VLOOKUP(M13,tbFactorMes[],2,FALSE),"") | O13: =IFERROR((L13*$K13)/N13,0)*$J13 -> 0 | R13: =IFERROR(VLOOKUP(Q13,tbFactorMes,2,FALSE),"") | S13: =IFERROR((P13*$K13)/R13,0)*$J13 -> 0 | V13: =IFERROR(VLOOKUP(U13,tbFactorMes,2,FALSE),"") | W13: =IFERROR((T13*$K13)/V13,0)*$J13 -> 0 | Z13: =IFERROR(VLOOKUP(Y13,tbFactorMes,2,FALSE),"") | AA13: =IFERROR((X13*$K13)/Z13,0)*$J13 -> 0 | AD13: =IFERROR(VLOOKUP(AC13,tbFactorMes,2,FALSE),"") | AE13: =IFERROR((AB13*$K13)/AD13,0)*$J13 -> 0 | AH13: =IFERROR(VLOOKUP(AG13,tbFactorMes,2,FALSE),"") | AI13: =IFERROR((AF13*$K13)/AH13,0)*$J13 -> 0 | AL13: =IFERROR(VLOOKUP(AK13,tbFactorMes,2,FALSE),"") | AM13: =IFERROR((AJ13*$K13)/AL13,0)*$J13 -> 0 | AP13: =IFERROR(VLOOKUP(AO13,tbFactorMes,2,FALSE),"") | AQ13: =IFERROR((AN13*$K13)/AP13,0)*$J13 -> 0 | AT13: =IFERROR(VLOOKUP(AS13,tbFactorMes,2,FALSE),"") | AU13: =IFERROR((AR13*$K13)/AT13,0)*$J13 -> 0 | AX13: =IFERROR(VLOOKUP(AW13,tbFactorMes,2,FALSE),"") | AY13: =IFERROR((AV13*$K13)/AX13,0)*$J13 -> 0 | BB13: =IFERROR(VLOOKUP(BA13,tbFactorMes,2,FALSE),"") | BC13: =IFERROR((AZ13*$K13)/BB13,0)*$J13 -> 0 | BF13: =IFERROR(VLOOKUP(BE13,tbFactorMes,2,FALSE),"") | BG13: =IFERROR((BD13*$K13)/BF13,0)*$J13 -> 0 | BH13: =IFERROR(SUM(O13,S13,W13,AA13,AE13,AI13,AM13,AQ13,AU13,AY13,BC13,BG13),0) -> 0 | BI13: =IFERROR(BH13*(1-$I13),0) -> 0
K14: =IFERROR(VLOOKUP(F14,tbTurnos,3,FALSE),"") | N14: =IFERROR(VLOOKUP(M14,tbFactorMes[],2,FALSE),"") | O14: =IFERROR((L14*$K14)/N14,0)*$J14 -> 0 | R14: =IFERROR(VLOOKUP(Q14,tbFactorMes,2,FALSE),"") | S14: =IFERROR((P14*$K14)/R14,0)*$J14 -> 0 | V14: =IFERROR(VLOOKUP(U14,tbFactorMes,2,FALSE),"") | W14: =IFERROR((T14*$K14)/V14,0)*$J14 -> 0 | Z14: =IFERROR(VLOOKUP(Y14,tbFactorMes,2,FALSE),"") | AA14: =IFERROR((X14*$K14)/Z14,0)*$J14 -> 0 | AD14: =IFERROR(VLOOKUP(AC14,tbFactorMes,2,FALSE),"") | AE14: =IFERROR((AB14*$K14)/AD14,0)*$J14 -> 0 | AH14: =IFERROR(VLOOKUP(AG14,tbFactorMes,2,FALSE),"") | AI14: =IFERROR((AF14*$K14)/AH14,0)*$J14 -> 0 | AL14: =IFERROR(VLOOKUP(AK14,tbFactorMes,2,FALSE),"") | AM14: =IFERROR((AJ14*$K14)/AL14,0)*$J14 -> 0 | AP14: =IFERROR(VLOOKUP(AO14,tbFactorMes,2,FALSE),"") | AQ14: =IFERROR((AN14*$K14)/AP14,0)*$J14 -> 0 | AT14: =IFERROR(VLOOKUP(AS14,tbFactorMes,2,FALSE),"") | AU14: =IFERROR((AR14*$K14)/AT14,0)*$J14 -> 0 | AX14: =IFERROR(VLOOKUP(AW14,tbFactorMes,2,FALSE),"") | AY14: =IFERROR((AV14*$K14)/AX14,0)*$J14 -> 0 | BB14: =IFERROR(VLOOKUP(BA14,tbFactorMes,2,FALSE),"") | BC14: =IFERROR((AZ14*$K14)/BB14,0)*$J14 -> 0 | BF14: =IFERROR(VLOOKUP(BE14,tbFactorMes,2,FALSE),"") | BG14: =IFERROR((BD14*$K14)/BF14,0)*$J14 -> 0 | BH14: =IFERROR(SUM(O14,S14,W14,AA14,AE14,AI14,AM14,AQ14,AU14,AY14,BC14,BG14),0) -> 0 | BI14: =IFERROR(BH14*(1-$I14),0) -> 0
K15: =IFERROR(VLOOKUP(F15,tbTurnos,3,FALSE),"") | N15: =IFERROR(VLOOKUP(M15,tbFactorMes[],2,FALSE),"") | O15: =IFERROR((L15*$K15)/N15,0)*$J15 -> 0 | R15: =IFERROR(VLOOKUP(Q15,tbFactorMes,2,FALSE),"") | S15: =IFERROR((P15*$K15)/R15,0)*$J15 -> 0 | V15: =IFERROR(VLOOKUP(U15,tbFactorMes,2,FALSE),"") | W15: =IFERROR((T15*$K15)/V15,0)*$J15 -> 0 | Z15: =IFERROR(VLOOKUP(Y15,tbFactorMes,2,FALSE),"") | AA15: =IFERROR((X15*$K15)/Z15,0)*$J15 -> 0 | AD15: =IFERROR(VLOOKUP(AC15,tbFactorMes,2,FALSE),"") | AE15: =IFERROR((AB15*$K15)/AD15,0)*$J15 -> 0 | AH15: =IFERROR(VLOOKUP(AG15,tbFactorMes,2,FALSE),"") | AI15: =IFERROR((AF15*$K15)/AH15,0)*$J15 -> 0 | AL15: =IFERROR(VLOOKUP(AK15,tbFactorMes,2,FALSE),"") | AM15: =IFERROR((AJ15*$K15)/AL15,0)*$J15 -> 0 | AP15: =IFERROR(VLOOKUP(AO15,tbFactorMes,2,FALSE),"") | AQ15: =IFERROR((AN15*$K15)/AP15,0)*$J15 -> 0 | AT15: =IFERROR(VLOOKUP(AS15,tbFactorMes,2,FALSE),"") | AU15: =IFERROR((AR15*$K15)/AT15,0)*$J15 -> 0 | AX15: =IFERROR(VLOOKUP(AW15,tbFactorMes,2,FALSE),"") | AY15: =IFERROR((AV15*$K15)/AX15,0)*$J15 -> 0 | BB15: =IFERROR(VLOOKUP(BA15,tbFactorMes,2,FALSE),"") | BC15: =IFERROR((AZ15*$K15)/BB15,0)*$J15 -> 0 | BF15: =IFERROR(VLOOKUP(BE15,tbFactorMes,2,FALSE),"") | BG15: =IFERROR((BD15*$K15)/BF15,0)*$J15 -> 0 | BH15: =IFERROR(SUM(O15,S15,W15,AA15,AE15,AI15,AM15,AQ15,AU15,AY15,BC15,BG15),0) -> 0 | BI15: =IFERROR(BH15*(1-$I15),0) -> 0
K16: =IFERROR(VLOOKUP(F16,tbTurnos,3,FALSE),"") | N16: =IFERROR(VLOOKUP(M16,tbFactorMes[],2,FALSE),"") | O16: =IFERROR((L16*$K16)/N16,0)*$J16 -> 0 | R16: =IFERROR(VLOOKUP(Q16,tbFactorMes,2,FALSE),"") | S16: =IFERROR((P16*$K16)/R16,0)*$J16 -> 0 | V16: =IFERROR(VLOOKUP(U16,tbFactorMes,2,FALSE),"") | W16: =IFERROR((T16*$K16)/V16,0)*$J16 -> 0 | Z16: =IFERROR(VLOOKUP(Y16,tbFactorMes,2,FALSE),"") | AA16: =IFERROR((X16*$K16)/Z16,0)*$J16 -> 0 | AD16: =IFERROR(VLOOKUP(AC16,tbFactorMes,2,FALSE),"") | AE16: =IFERROR((AB16*$K16)/AD16,0)*$J16 -> 0 | AH16: =IFERROR(VLOOKUP(AG16,tbFactorMes,2,FALSE),"") | AI16: =IFERROR((AF16*$K16)/AH16,0)*$J16 -> 0 | AL16: =IFERROR(VLOOKUP(AK16,tbFactorMes,2,FALSE),"") | AM16: =IFERROR((AJ16*$K16)/AL16,0)*$J16 -> 0 | AP16: =IFERROR(VLOOKUP(AO16,tbFactorMes,2,FALSE),"") | AQ16: =IFERROR((AN16*$K16)/AP16,0)*$J16 -> 0 | AT16: =IFERROR(VLOOKUP(AS16,tbFactorMes,2,FALSE),"") | AU16: =IFERROR((AR16*$K16)/AT16,0)*$J16 -> 0 | AX16: =IFERROR(VLOOKUP(AW16,tbFactorMes,2,FALSE),"") | AY16: =IFERROR((AV16*$K16)/AX16,0)*$J16 -> 0 | BB16: =IFERROR(VLOOKUP(BA16,tbFactorMes,2,FALSE),"") | BC16: =IFERROR((AZ16*$K16)/BB16,0)*$J16 -> 0 | BF16: =IFERROR(VLOOKUP(BE16,tbFactorMes,2,FALSE),"") | BG16: =IFERROR((BD16*$K16)/BF16,0)*$J16 -> 0 | BH16: =IFERROR(SUM(O16,S16,W16,AA16,AE16,AI16,AM16,AQ16,AU16,AY16,BC16,BG16),0) -> 0 | BI16: =IFERROR(BH16*(1-$I16),0) -> 0
K17: =IFERROR(VLOOKUP(F17,tbTurnos,3,FALSE),"") | N17: =IFERROR(VLOOKUP(M17,tbFactorMes[],2,FALSE),"") | O17: =IFERROR((L17*$K17)/N17,0)*$J17 -> 0 | R17: =IFERROR(VLOOKUP(Q17,tbFactorMes,2,FALSE),"") | S17: =IFERROR((P17*$K17)/R17,0)*$J17 -> 0 | V17: =IFERROR(VLOOKUP(U17,tbFactorMes,2,FALSE),"") | W17: =IFERROR((T17*$K17)/V17,0)*$J17 -> 0 | Z17: =IFERROR(VLOOKUP(Y17,tbFactorMes,2,FALSE),"") | AA17: =IFERROR((X17*$K17)/Z17,0)*$J17 -> 0 | AD17: =IFERROR(VLOOKUP(AC17,tbFactorMes,2,FALSE),"") | AE17: =IFERROR((AB17*$K17)/AD17,0)*$J17 -> 0 | AH17: =IFERROR(VLOOKUP(AG17,tbFactorMes,2,FALSE),"") | AI17: =IFERROR((AF17*$K17)/AH17,0)*$J17 -> 0 | AL17: =IFERROR(VLOOKUP(AK17,tbFactorMes,2,FALSE),"") | AM17: =IFERROR((AJ17*$K17)/AL17,0)*$J17 -> 0 | AP17: =IFERROR(VLOOKUP(AO17,tbFactorMes,2,FALSE),"") | AQ17: =IFERROR((AN17*$K17)/AP17,0)*$J17 -> 0 | AT17: =IFERROR(VLOOKUP(AS17,tbFactorMes,2,FALSE),"") | AU17: =IFERROR((AR17*$K17)/AT17,0)*$J17 -> 0 | AX17: =IFERROR(VLOOKUP(AW17,tbFactorMes,2,FALSE),"") | AY17: =IFERROR((AV17*$K17)/AX17,0)*$J17 -> 0 | BB17: =IFERROR(VLOOKUP(BA17,tbFactorMes,2,FALSE),"") | BC17: =IFERROR((AZ17*$K17)/BB17,0)*$J17 -> 0 | BF17: =IFERROR(VLOOKUP(BE17,tbFactorMes,2,FALSE),"") | BG17: =IFERROR((BD17*$K17)/BF17,0)*$J17 -> 0 | BH17: =IFERROR(SUM(O17,S17,W17,AA17,AE17,AI17,AM17,AQ17,AU17,AY17,BC17,BG17),0) -> 0 | BI17: =IFERROR(BH17*(1-$I17),0) -> 0
... K21: =IFERROR(VLOOKUP(F21,tbTurnos,3,FALSE),"") | N21: =IFERROR(VLOOKUP(M21,tbFactorMes[],2,FALSE),"") | O21: =IFERROR((L21*$K21)/N21,0)*$J21 -> 0 | R21: =IFERROR(VLOOKUP(Q21,tbFactorMes,2,FALSE),"") | S21: =IFERROR((P21*$K21)/R21,0)*$J21 -> 0 | V21: =IFERROR(VLOOKUP(U21,tbFactorMes,2,FALSE),"") | W21: =IFERROR((T21*$K21)/V21,0)*$J21 -> 0 | Z21: =IFERROR(VLOOKUP(Y21,tbFactorMes,2,FALSE),"") | AA21: =IFERROR((X21*$K21)/Z21,0)*$J21 -> 0 | AD21: =IFERROR(VLOOKUP(AC21,tbFactorMes,2,FALSE),"") | AE21: =IFERROR((AB21*$K21)/AD21,0)*$J21 -> 0 | AH21: =IFERROR(VLOOKUP(AG21,tbFactorMes,2,FALSE),"") | AI21: =IFERROR((AF21*$K21)/AH21,0)*$J21 -> 0 | AL21: =IFERROR(VLOOKUP(AK21,tbFactorMes,2,FALSE),"") | AM21: =IFERROR((AJ21*$K21)/AL21,0)*$J21 -> 0 | AP21: =IFERROR(VLOOKUP(AO21,tbFactorMes,2,FALSE),"") | AQ21: =IFERROR((AN21*$K21)/AP21,0)*$J21 -> 0 | AT21: =IFERROR(VLOOKUP(AS21,tbFactorMes,2,FALSE),"") | AU21: =IFERROR((AR21*$K21)/AT21,0)*$J21 -> 0 | AX21: =IFERROR(VLOOKUP(AW21,tbFactorMes,2,FALSE),"") | AY21: =IFERROR((AV21*$K21)/AX21,0)*$J21 -> 0 | BB21: =IFERROR(VLOOKUP(BA21,tbFactorMes,2,FALSE),"") | BC21: =IFERROR((AZ21*$K21)/BB21,0)*$J21 -> 0 | BF21: =IFERROR(VLOOKUP(BE21,tbFactorMes,2,FALSE),"") | BG21: =IFERROR((BD21*$K21)/BF21,0)*$J21 -> 0 | BH21: =IFERROR(SUM(O21,S21,W21,AA21,AE21,AI21,AM21,AQ21,AU21,AY21,BC21,BG21),0) -> 0 | BI21: =IFERROR(BH21*(1-$I21),0) -> 0
K22: =IFERROR(VLOOKUP(F22,tbTurnos,3,FALSE),"") | N22: =IFERROR(VLOOKUP(M22,tbFactorMes,2,FALSE),"") | O22: =IFERROR((L22*$K22)/N22,0)*$J22 -> 0 | R22: =IFERROR(VLOOKUP(Q22,tbFactorMes,2,FALSE),"") | S22: =IFERROR((P22*$K22)/R22,0)*$J22 -> 0 | V22: =IFERROR(VLOOKUP(U22,tbFactorMes,2,FALSE),"") | W22: =IFERROR((T22*$K22)/V22,0)*$J22 -> 0 | Z22: =IFERROR(VLOOKUP(Y22,tbFactorMes,2,FALSE),"") | AA22: =IFERROR((X22*$K22)/Z22,0)*$J22 -> 0 | AD22: =IFERROR(VLOOKUP(AC22,tbFactorMes,2,FALSE),"") | AE22: =IFERROR((AB22*$K22)/AD22,0)*$J22 -> 0 | AH22: =IFERROR(VLOOKUP(AG22,tbFactorMes,2,FALSE),"") | AI22: =IFERROR((AF22*$K22)/AH22,0)*$J22 -> 0 | AL22: =IFERROR(VLOOKUP(AK22,tbFactorMes,2,FALSE),"") | AM22: =IFERROR((AJ22*$K22)/AL22,0)*$J22 -> 0 | AP22: =IFERROR(VLOOKUP(AO22,tbFactorMes,2,FALSE),"") | AQ22: =IFERROR((AN22*$K22)/AP22,0)*$J22 -> 0 | AT22: =IFERROR(VLOOKUP(AS22,tbFactorMes,2,FALSE),"") | AU22: =IFERROR((AR22*$K22)/AT22,0)*$J22 -> 0 | AX22: =IFERROR(VLOOKUP(AW22,tbFactorMes,2,FALSE),"") | AY22: =IFERROR((AV22*$K22)/AX22,0)*$J22 -> 0 | BB22: =IFERROR(VLOOKUP(BA22,tbFactorMes,2,FALSE),"") | BC22: =IFERROR((AZ22*$K22)/BB22,0)*$J22 -> 0 | BF22: =IFERROR(VLOOKUP(BE22,tbFactorMes,2,FALSE),"") | BG22: =IFERROR((BD22*$K22)/BF22,0)*$J22 -> 0 | BH22: =IFERROR(SUM(O22,S22,W22,AA22,AE22,AI22,AM22,AQ22,AU22,AY22,BC22,BG22),0) -> 0 | BI22: =IFERROR(BH22*(1-$I22),0) -> 0
K23: =IFERROR(VLOOKUP(F23,tbTurnos,3,FALSE),"") | N23: =IFERROR(VLOOKUP(M23,tbFactorMes,2,FALSE),"") | O23: =IFERROR((L23*$K23)/N23,0)*$J23 -> 0 | R23: =IFERROR(VLOOKUP(Q23,tbFactorMes,2,FALSE),"") | S23: =IFERROR((P23*$K23)/R23,0)*$J23 -> 0 | V23: =IFERROR(VLOOKUP(U23,tbFactorMes,2,FALSE),"") | W23: =IFERROR((T23*$K23)/V23,0)*$J23 -> 0 | Z23: =IFERROR(VLOOKUP(Y23,tbFactorMes,2,FALSE),"") | AA23: =IFERROR((X23*$K23)/Z23,0)*$J23 -> 0 | AD23: =IFERROR(VLOOKUP(AC23,tbFactorMes,2,FALSE),"") | AE23: =IFERROR((AB23*$K23)/AD23,0)*$J23 -> 0 | AH23: =IFERROR(VLOOKUP(AG23,tbFactorMes,2,FALSE),"") | AI23: =IFERROR((AF23*$K23)/AH23,0)*$J23 -> 0 | AL23: =IFERROR(VLOOKUP(AK23,tbFactorMes,2,FALSE),"") | AM23: =IFERROR((AJ23*$K23)/AL23,0)*$J23 -> 0 | AP23: =IFERROR(VLOOKUP(AO23,tbFactorMes,2,FALSE),"") | AQ23: =IFERROR((AN23*$K23)/AP23,0)*$J23 -> 0 | AT23: =IFERROR(VLOOKUP(AS23,tbFactorMes,2,FALSE),"") | AU23: =IFERROR((AR23*$K23)/AT23,0)*$J23 -> 0 | AX23: =IFERROR(VLOOKUP(AW23,tbFactorMes,2,FALSE),"") | AY23: =IFERROR((AV23*$K23)/AX23,0)*$J23 -> 0 | BB23: =IFERROR(VLOOKUP(BA23,tbFactorMes,2,FALSE),"") | BC23: =IFERROR((AZ23*$K23)/BB23,0)*$J23 -> 0 | BF23: =IFERROR(VLOOKUP(BE23,tbFactorMes,2,FALSE),"") | BG23: =IFERROR((BD23*$K23)/BF23,0)*$J23 -> 0 | BH23: =IFERROR(SUM(O23,S23,W23,AA23,AE23,AI23,AM23,AQ23,AU23,AY23,BC23,BG23),0) -> 0 | BI23: =IFERROR(BH23*(1-$I23),0) -> 0
K24: =IFERROR(VLOOKUP(F24,tbTurnos,3,FALSE),"") | N24: =IFERROR(VLOOKUP(M24,tbFactorMes,2,FALSE),"") | O24: =IFERROR((L24*$K24)/N24,0)*$J24 -> 0 | R24: =IFERROR(VLOOKUP(Q24,tbFactorMes,2,FALSE),"") | S24: =IFERROR((P24*$K24)/R24,0)*$J24 -> 0 | V24: =IFERROR(VLOOKUP(U24,tbFactorMes,2,FALSE),"") | W24: =IFERROR((T24*$K24)/V24,0)*$J24 -> 0 | Z24: =IFERROR(VLOOKUP(Y24,tbFactorMes,2,FALSE),"") | AA24: =IFERROR((X24*$K24)/Z24,0)*$J24 -> 0 | AD24: =IFERROR(VLOOKUP(AC24,tbFactorMes,2,FALSE),"") | AE24: =IFERROR((AB24*$K24)/AD24,0)*$J24 -> 0 | AH24: =IFERROR(VLOOKUP(AG24,tbFactorMes,2,FALSE),"") | AI24: =IFERROR((AF24*$K24)/AH24,0)*$J24 -> 0 | AL24: =IFERROR(VLOOKUP(AK24,tbFactorMes,2,FALSE),"") | AM24: =IFERROR((AJ24*$K24)/AL24,0)*$J24 -> 0 | AP24: =IFERROR(VLOOKUP(AO24,tbFactorMes,2,FALSE),"") | AQ24: =IFERROR((AN24*$K24)/AP24,0)*$J24 -> 0 | AT24: =IFERROR(VLOOKUP(AS24,tbFactorMes,2,FALSE),"") | AU24: =IFERROR((AR24*$K24)/AT24,0)*$J24 -> 0 | AX24: =IFERROR(VLOOKUP(AW24,tbFactorMes,2,FALSE),"") | AY24: =IFERROR((AV24*$K24)/AX24,0)*$J24 -> 0 | BB24: =IFERROR(VLOOKUP(BA24,tbFactorMes,2,FALSE),"") | BC24: =IFERROR((AZ24*$K24)/BB24,0)*$J24 -> 0 | BF24: =IFERROR(VLOOKUP(BE24,tbFactorMes,2,FALSE),"") | BG24: =IFERROR((BD24*$K24)/BF24,0)*$J24 -> 0 | BH24: =IFERROR(SUM(O24,S24,W24,AA24,AE24,AI24,AM24,AQ24,AU24,AY24,BC24,BG24),0) -> 0 | BI24: =IFERROR(BH24*(1-$I24),0) -> 0
K25: =IFERROR(VLOOKUP(F25,tbTurnos,3,FALSE),"") | N25: =IFERROR(VLOOKUP(M25,tbFactorMes,2,FALSE),"") | O25: =IFERROR((L25*$K25)/N25,0)*$J25 -> 0 | R25: =IFERROR(VLOOKUP(Q25,tbFactorMes,2,FALSE),"") | S25: =IFERROR((P25*$K25)/R25,0)*$J25 -> 0 | V25: =IFERROR(VLOOKUP(U25,tbFactorMes,2,FALSE),"") | W25: =IFERROR((T25*$K25)/V25,0)*$J25 -> 0 | Z25: =IFERROR(VLOOKUP(Y25,tbFactorMes,2,FALSE),"") | AA25: =IFERROR((X25*$K25)/Z25,0)*$J25 -> 0 | AD25: =IFERROR(VLOOKUP(AC25,tbFactorMes,2,FALSE),"") | AE25: =IFERROR((AB25*$K25)/AD25,0)*$J25 -> 0 | AH25: =IFERROR(VLOOKUP(AG25,tbFactorMes,2,FALSE),"") | AI25: =IFERROR((AF25*$K25)/AH25,0)*$J25 -> 0 | AL25: =IFERROR(VLOOKUP(AK25,tbFactorMes,2,FALSE),"") | AM25: =IFERROR((AJ25*$K25)/AL25,0)*$J25 -> 0 | AP25: =IFERROR(VLOOKUP(AO25,tbFactorMes,2,FALSE),"") | AQ25: =IFERROR((AN25*$K25)/AP25,0)*$J25 -> 0 | AT25: =IFERROR(VLOOKUP(AS25,tbFactorMes,2,FALSE),"") | AU25: =IFERROR((AR25*$K25)/AT25,0)*$J25 -> 0 | AX25: =IFERROR(VLOOKUP(AW25,tbFactorMes,2,FALSE),"") | AY25: =IFERROR((AV25*$K25)/AX25,0)*$J25 -> 0 | BB25: =IFERROR(VLOOKUP(BA25,tbFactorMes,2,FALSE),"") | BC25: =IFERROR((AZ25*$K25)/BB25,0)*$J25 -> 0 | BF25: =IFERROR(VLOOKUP(BE25,tbFactorMes,2,FALSE),"") | BG25: =IFERROR((BD25*$K25)/BF25,0)*$J25 -> 0 | BH25: =IFERROR(SUM(O25,S25,W25,AA25,AE25,AI25,AM25,AQ25,AU25,AY25,BC25,BG25),0) -> 0 | BI25: =IFERROR(BH25*(1-$I25),0) -> 0
K26: =IFERROR(VLOOKUP(F26,tbTurnos,3,FALSE),"") | N26: =IFERROR(VLOOKUP(M26,tbFactorMes,2,FALSE),"") | O26: =IFERROR((L26*$K26)/N26,0)*$J26 -> 0 | R26: =IFERROR(VLOOKUP(Q26,tbFactorMes,2,FALSE),"") | S26: =IFERROR((P26*$K26)/R26,0)*$J26 -> 0 | V26: =IFERROR(VLOOKUP(U26,tbFactorMes,2,FALSE),"") | W26: =IFERROR((T26*$K26)/V26,0)*$J26 -> 0 | Z26: =IFERROR(VLOOKUP(Y26,tbFactorMes,2,FALSE),"") | AA26: =IFERROR((X26*$K26)/Z26,0)*$J26 -> 0 | AD26: =IFERROR(VLOOKUP(AC26,tbFactorMes,2,FALSE),"") | AE26: =IFERROR((AB26*$K26)/AD26,0)*$J26 -> 0 | AH26: =IFERROR(VLOOKUP(AG26,tbFactorMes,2,FALSE),"") | AI26: =IFERROR((AF26*$K26)/AH26,0)*$J26 -> 0 | AL26: =IFERROR(VLOOKUP(AK26,tbFactorMes,2,FALSE),"") | AM26: =IFERROR((AJ26*$K26)/AL26,0)*$J26 -> 0 | AP26: =IFERROR(VLOOKUP(AO26,tbFactorMes,2,FALSE),"") | AQ26: =IFERROR((AN26*$K26)/AP26,0)*$J26 -> 0 | AT26: =IFERROR(VLOOKUP(AS26,tbFactorMes,2,FALSE),"") | AU26: =IFERROR((AR26*$K26)/AT26,0)*$J26 -> 0 | AX26: =IFERROR(VLOOKUP(AW26,tbFactorMes,2,FALSE),"") | AY26: =IFERROR((AV26*$K26)/AX26,0)*$J26 -> 0 | BB26: =IFERROR(VLOOKUP(BA26,tbFactorMes,2,FALSE),"") | BC26: =IFERROR((AZ26*$K26)/BB26,0)*$J26 -> 0 | BF26: =IFERROR(VLOOKUP(BE26,tbFactorMes,2,FALSE),"") | BG26: =IFERROR((BD26*$K26)/BF26,0)*$J26 -> 0 | BH26: =IFERROR(SUM(O26,S26,W26,AA26,AE26,AI26,AM26,AQ26,AU26,AY26,BC26,BG26),0) -> 0 | BI26: =IFERROR(BH26*(1-$I26),0) -> 0
K27: =IFERROR(VLOOKUP(F27,tbTurnos,3,FALSE),"") | N27: =IFERROR(VLOOKUP(M27,tbFactorMes,2,FALSE),"") | O27: =IFERROR((L27*$K27)/N27,0)*$J27 -> 0 | R27: =IFERROR(VLOOKUP(Q27,tbFactorMes,2,FALSE),"") | S27: =IFERROR((P27*$K27)/R27,0)*$J27 -> 0 | V27: =IFERROR(VLOOKUP(U27,tbFactorMes,2,FALSE),"") | W27: =IFERROR((T27*$K27)/V27,0)*$J27 -> 0 | Z27: =IFERROR(VLOOKUP(Y27,tbFactorMes,2,FALSE),"") | AA27: =IFERROR((X27*$K27)/Z27,0)*$J27 -> 0 | AD27: =IFERROR(VLOOKUP(AC27,tbFactorMes,2,FALSE),"") | AE27: =IFERROR((AB27*$K27)/AD27,0)*$J27 -> 0 | AH27: =IFERROR(VLOOKUP(AG27,tbFactorMes,2,FALSE),"") | AI27: =IFERROR((AF27*$K27)/AH27,0)*$J27 -> 0 | AL27: =IFERROR(VLOOKUP(AK27,tbFactorMes,2,FALSE),"") | AM27: =IFERROR((AJ27*$K27)/AL27,0)*$J27 -> 0 | AP27: =IFERROR(VLOOKUP(AO27,tbFactorMes,2,FALSE),"") | AQ27: =IFERROR((AN27*$K27)/AP27,0)*$J27 -> 0 | AT27: =IFERROR(VLOOKUP(AS27,tbFactorMes,2,FALSE),"") | AU27: =IFERROR((AR27*$K27)/AT27,0)*$J27 -> 0 | AX27: =IFERROR(VLOOKUP(AW27,tbFactorMes,2,FALSE),"") | AY27: =IFERROR((AV27*$K27)/AX27,0)*$J27 -> 0 | BB27: =IFERROR(VLOOKUP(BA27,tbFactorMes,2,FALSE),"") | BC27: =IFERROR((AZ27*$K27)/BB27,0)*$J27 -> 0 | BF27: =IFERROR(VLOOKUP(BE27,tbFactorMes,2,FALSE),"") | BG27: =IFERROR((BD27*$K27)/BF27,0)*$J27 -> 0 | BH27: =IFERROR(SUM(O27,S27,W27,AA27,AE27,AI27,AM27,AQ27,AU27,AY27,BC27,BG27),0) -> 0 | BI27: =IFERROR(BH27*(1-$I27),0) -> 0
K28: =IFERROR(VLOOKUP(F28,tbTurnos,3,FALSE),"") | N28: =IFERROR(VLOOKUP(M28,tbFactorMes,2,FALSE),"") | O28: =IFERROR((L28*$K28)/N28,0)*$J28 -> 0 | R28: =IFERROR(VLOOKUP(Q28,tbFactorMes,2,FALSE),"") | S28: =IFERROR((P28*$K28)/R28,0)*$J28 -> 0 | V28: =IFERROR(VLOOKUP(U28,tbFactorMes,2,FALSE),"") | W28: =IFERROR((T28*$K28)/V28,0)*$J28 -> 0 | Z28: =IFERROR(VLOOKUP(Y28,tbFactorMes,2,FALSE),"") | AA28: =IFERROR((X28*$K28)/Z28,0)*$J28 -> 0 | AD28: =IFERROR(VLOOKUP(AC28,tbFactorMes,2,FALSE),"") | AE28: =IFERROR((AB28*$K28)/AD28,0)*$J28 -> 0 | AH28: =IFERROR(VLOOKUP(AG28,tbFactorMes,2,FALSE),"") | AI28: =IFERROR((AF28*$K28)/AH28,0)*$J28 -> 0 | AL28: =IFERROR(VLOOKUP(AK28,tbFactorMes,2,FALSE),"") | AM28: =IFERROR((AJ28*$K28)/AL28,0)*$J28 -> 0 | AP28: =IFERROR(VLOOKUP(AO28,tbFactorMes,2,FALSE),"") | AQ28: =IFERROR((AN28*$K28)/AP28,0)*$J28 -> 0 | AT28: =IFERROR(VLOOKUP(AS28,tbFactorMes,2,FALSE),"") | AU28: =IFERROR((AR28*$K28)/AT28,0)*$J28 -> 0 | AX28: =IFERROR(VLOOKUP(AW28,tbFactorMes,2,FALSE),"") | AY28: =IFERROR((AV28*$K28)/AX28,0)*$J28 -> 0 | BB28: =IFERROR(VLOOKUP(BA28,tbFactorMes,2,FALSE),"") | BC28: =IFERROR((AZ28*$K28)/BB28,0)*$J28 -> 0 | BF28: =IFERROR(VLOOKUP(BE28,tbFactorMes,2,FALSE),"") | BG28: =IFERROR((BD28*$K28)/BF28,0)*$J28 -> 0 | BH28: =IFERROR(SUM(O28,S28,W28,AA28,AE28,AI28,AM28,AQ28,AU28,AY28,BC28,BG28),0) -> 0 | BI28: =IFERROR(BH28*(1-$I28),0) -> 0
K29: =IFERROR(VLOOKUP(F29,tbTurnos,3,FALSE),"") | N29: =IFERROR(VLOOKUP(M29,tbFactorMes,2,FALSE),"") | O29: =IFERROR((L29*$K29)/N29,0)*$J29 -> 0 | R29: =IFERROR(VLOOKUP(Q29,tbFactorMes,2,FALSE),"") | S29: =IFERROR((P29*$K29)/R29,0)*$J29 -> 0 | V29: =IFERROR(VLOOKUP(U29,tbFactorMes,2,FALSE),"") | W29: =IFERROR((T29*$K29)/V29,0)*$J29 -> 0 | Z29: =IFERROR(VLOOKUP(Y29,tbFactorMes,2,FALSE),"") | AA29: =IFERROR((X29*$K29)/Z29,0)*$J29 -> 0 | AD29: =IFERROR(VLOOKUP(AC29,tbFactorMes,2,FALSE),"") | AE29: =IFERROR((AB29*$K29)/AD29,0)*$J29 -> 0 | AH29: =IFERROR(VLOOKUP(AG29,tbFactorMes,2,FALSE),"") | AI29: =IFERROR((AF29*$K29)/AH29,0)*$J29 -> 0 | AL29: =IFERROR(VLOOKUP(AK29,tbFactorMes,2,FALSE),"") | AM29: =IFERROR((AJ29*$K29)/AL29,0)*$J29 -> 0 | AP29: =IFERROR(VLOOKUP(AO29,tbFactorMes,2,FALSE),"") | AQ29: =IFERROR((AN29*$K29)/AP29,0)*$J29 -> 0 | AT29: =IFERROR(VLOOKUP(AS29,tbFactorMes,2,FALSE),"") | AU29: =IFERROR((AR29*$K29)/AT29,0)*$J29 -> 0 | AX29: =IFERROR(VLOOKUP(AW29,tbFactorMes,2,FALSE),"") | AY29: =IFERROR((AV29*$K29)/AX29,0)*$J29 -> 0 | BB29: =IFERROR(VLOOKUP(BA29,tbFactorMes,2,FALSE),"") | BC29: =IFERROR((AZ29*$K29)/BB29,0)*$J29 -> 0 | BF29: =IFERROR(VLOOKUP(BE29,tbFactorMes,2,FALSE),"") | BG29: =IFERROR((BD29*$K29)/BF29,0)*$J29 -> 0 | BH29: =IFERROR(SUM(O29,S29,W29,AA29,AE29,AI29,AM29,AQ29,AU29,AY29,BC29,BG29),0) -> 0 | BI29: =IFERROR(BH29*(1-$I29),0) -> 0
K30: =IFERROR(VLOOKUP(F30,tbTurnos,3,FALSE),"") | N30: =IFERROR(VLOOKUP(M30,tbFactorMes,2,FALSE),"") | O30: =IFERROR((L30*$K30)/N30,0)*$J30 -> 0 | R30: =IFERROR(VLOOKUP(Q30,tbFactorMes,2,FALSE),"") | S30: =IFERROR((P30*$K30)/R30,0)*$J30 -> 0 | V30: =IFERROR(VLOOKUP(U30,tbFactorMes,2,FALSE),"") | W30: =IFERROR((T30*$K30)/V30,0)*$J30 -> 0 | Z30: =IFERROR(VLOOKUP(Y30,tbFactorMes,2,FALSE),"") | AA30: =IFERROR((X30*$K30)/Z30,0)*$J30 -> 0 | AD30: =IFERROR(VLOOKUP(AC30,tbFactorMes,2,FALSE),"") | AE30: =IFERROR((AB30*$K30)/AD30,0)*$J30 -> 0 | AH30: =IFERROR(VLOOKUP(AG30,tbFactorMes,2,FALSE),"") | AI30: =IFERROR((AF30*$K30)/AH30,0)*$J30 -> 0 | AL30: =IFERROR(VLOOKUP(AK30,tbFactorMes,2,FALSE),"") | AM30: =IFERROR((AJ30*$K30)/AL30,0)*$J30 -> 0 | AP30: =IFERROR(VLOOKUP(AO30,tbFactorMes,2,FALSE),"") | AQ30: =IFERROR((AN30*$K30)/AP30,0)*$J30 -> 0 | AT30: =IFERROR(VLOOKUP(AS30,tbFactorMes,2,FALSE),"") | AU30: =IFERROR((AR30*$K30)/AT30,0)*$J30 -> 0 | AX30: =IFERROR(VLOOKUP(AW30,tbFactorMes,2,FALSE),"") | AY30: =IFERROR((AV30*$K30)/AX30,0)*$J30 -> 0 | BB30: =IFERROR(VLOOKUP(BA30,tbFactorMes,2,FALSE),"") | BC30: =IFERROR((AZ30*$K30)/BB30,0)*$J30 -> 0 | BF30: =IFERROR(VLOOKUP(BE30,tbFactorMes,2,FALSE),"") | BG30: =IFERROR((BD30*$K30)/BF30,0)*$J30 -> 0 | BH30: =IFERROR(SUM(O30,S30,W30,AA30,AE30,AI30,AM30,AQ30,AU30,AY30,BC30,BG30),0) -> 0 | BI30: =IFERROR(BH30*(1-$I30),0) -> 0
K31: =IFERROR(VLOOKUP(F31,tbTurnos,3,FALSE),"") | N31: =IFERROR(VLOOKUP(M31,tbFactorMes,2,FALSE),"") | O31: =IFERROR((L31*$K31)/N31,0)*$J31 -> 0 | R31: =IFERROR(VLOOKUP(Q31,tbFactorMes,2,FALSE),"") | S31: =IFERROR((P31*$K31)/R31,0)*$J31 -> 0 | V31: =IFERROR(VLOOKUP(U31,tbFactorMes,2,FALSE),"") | W31: =IFERROR((T31*$K31)/V31,0)*$J31 -> 0 | Z31: =IFERROR(VLOOKUP(Y31,tbFactorMes,2,FALSE),"") | AA31: =IFERROR((X31*$K31)/Z31,0)*$J31 -> 0 | AD31: =IFERROR(VLOOKUP(AC31,tbFactorMes,2,FALSE),"") | AE31: =IFERROR((AB31*$K31)/AD31,0)*$J31 -> 0 | AH31: =IFERROR(VLOOKUP(AG31,tbFactorMes,2,FALSE),"") | AI31: =IFERROR((AF31*$K31)/AH31,0)*$J31 -> 0 | AL31: =IFERROR(VLOOKUP(AK31,tbFactorMes,2,FALSE),"") | AM31: =IFERROR((AJ31*$K31)/AL31,0)*$J31 -> 0 | AP31: =IFERROR(VLOOKUP(AO31,tbFactorMes,2,FALSE),"") | AQ31: =IFERROR((AN31*$K31)/AP31,0)*$J31 -> 0 | AT31: =IFERROR(VLOOKUP(AS31,tbFactorMes,2,FALSE),"") | AU31: =IFERROR((AR31*$K31)/AT31,0)*$J31 -> 0 | AX31: =IFERROR(VLOOKUP(AW31,tbFactorMes,2,FALSE),"") | AY31: =IFERROR((AV31*$K31)/AX31,0)*$J31 -> 0 | BB31: =IFERROR(VLOOKUP(BA31,tbFactorMes,2,FALSE),"") | BC31: =IFERROR((AZ31*$K31)/BB31,0)*$J31 -> 0 | BF31: =IFERROR(VLOOKUP(BE31,tbFactorMes,2,FALSE),"") | BG31: =IFERROR((BD31*$K31)/BF31,0)*$J31 -> 0 | BH31: =IFERROR(SUM(O31,S31,W31,AA31,AE31,AI31,AM31,AQ31,AU31,AY31,BC31,BG31),0) -> 0 | BI31: =IFERROR(BH31*(1-$I31),0) -> 0
K32: =IFERROR(VLOOKUP(F32,tbTurnos,3,FALSE),"") | N32: =IFERROR(VLOOKUP(M32,tbFactorMes,2,FALSE),"") | O32: =IFERROR((L32*$K32)/N32,0)*$J32 -> 0 | R32: =IFERROR(VLOOKUP(Q32,tbFactorMes,2,FALSE),"") | S32: =IFERROR((P32*$K32)/R32,0)*$J32 -> 0 | V32: =IFERROR(VLOOKUP(U32,tbFactorMes,2,FALSE),"") | W32: =IFERROR((T32*$K32)/V32,0)*$J32 -> 0 | Z32: =IFERROR(VLOOKUP(Y32,tbFactorMes,2,FALSE),"") | AA32: =IFERROR((X32*$K32)/Z32,0)*$J32 -> 0 | AD32: =IFERROR(VLOOKUP(AC32,tbFactorMes,2,FALSE),"") | AE32: =IFERROR((AB32*$K32)/AD32,0)*$J32 -> 0 | AH32: =IFERROR(VLOOKUP(AG32,tbFactorMes,2,FALSE),"") | AI32: =IFERROR((AF32*$K32)/AH32,0)*$J32 -> 0 | AL32: =IFERROR(VLOOKUP(AK32,tbFactorMes,2,FALSE),"") | AM32: =IFERROR((AJ32*$K32)/AL32,0)*$J32 -> 0 | AP32: =IFERROR(VLOOKUP(AO32,tbFactorMes,2,FALSE),"") | AQ32: =IFERROR((AN32*$K32)/AP32,0)*$J32 -> 0 | AT32: =IFERROR(VLOOKUP(AS32,tbFactorMes,2,FALSE),"") | AU32: =IFERROR((AR32*$K32)/AT32,0)*$J32 -> 0 | AX32: =IFERROR(VLOOKUP(AW32,tbFactorMes,2,FALSE),"") | AY32: =IFERROR((AV32*$K32)/AX32,0)*$J32 -> 0 | BB32: =IFERROR(VLOOKUP(BA32,tbFactorMes,2,FALSE),"") | BC32: =IFERROR((AZ32*$K32)/BB32,0)*$J32 -> 0 | BF32: =IFERROR(VLOOKUP(BE32,tbFactorMes,2,FALSE),"") | BG32: =IFERROR((BD32*$K32)/BF32,0)*$J32 -> 0 | BH32: =IFERROR(SUM(O32,S32,W32,AA32,AE32,AI32,AM32,AQ32,AU32,AY32,BC32,BG32),0) -> 0 | BI32: =IFERROR(BH32*(1-$I32),0) -> 0
K33: =IFERROR(VLOOKUP(F33,tbTurnos,3,FALSE),"") | N33: =IFERROR(VLOOKUP(M33,tbFactorMes,2,FALSE),"") | O33: =IFERROR((L33*$K33)/N33,0)*$J33 -> 0 | R33: =IFERROR(VLOOKUP(Q33,tbFactorMes,2,FALSE),"") | S33: =IFERROR((P33*$K33)/R33,0)*$J33 -> 0 | V33: =IFERROR(VLOOKUP(U33,tbFactorMes,2,FALSE),"") | W33: =IFERROR((T33*$K33)/V33,0)*$J33 -> 0 | Z33: =IFERROR(VLOOKUP(Y33,tbFactorMes,2,FALSE),"") | AA33: =IFERROR((X33*$K33)/Z33,0)*$J33 -> 0 | AD33: =IFERROR(VLOOKUP(AC33,tbFactorMes,2,FALSE),"") | AE33: =IFERROR((AB33*$K33)/AD33,0)*$J33 -> 0 | AH33: =IFERROR(VLOOKUP(AG33,tbFactorMes,2,FALSE),"") | AI33: =IFERROR((AF33*$K33)/AH33,0)*$J33 -> 0 | AL33: =IFERROR(VLOOKUP(AK33,tbFactorMes,2,FALSE),"") | AM33: =IFERROR((AJ33*$K33)/AL33,0)*$J33 -> 0 | AP33: =IFERROR(VLOOKUP(AO33,tbFactorMes,2,FALSE),"") | AQ33: =IFERROR((AN33*$K33)/AP33,0)*$J33 -> 0 | AT33: =IFERROR(VLOOKUP(AS33,tbFactorMes,2,FALSE),"") | AU33: =IFERROR((AR33*$K33)/AT33,0)*$J33 -> 0 | AX33: =IFERROR(VLOOKUP(AW33,tbFactorMes,2,FALSE),"") | AY33: =IFERROR((AV33*$K33)/AX33,0)*$J33 -> 0 | BB33: =IFERROR(VLOOKUP(BA33,tbFactorMes,2,FALSE),"") | BC33: =IFERROR((AZ33*$K33)/BB33,0)*$J33 -> 0 | BF33: =IFERROR(VLOOKUP(BE33,tbFactorMes,2,FALSE),"") | BG33: =IFERROR((BD33*$K33)/BF33,0)*$J33 -> 0 | BH33: =IFERROR(SUM(O33,S33,W33,AA33,AE33,AI33,AM33,AQ33,AU33,AY33,BC33,BG33),0) -> 0 | BI33: =IFERROR(BH33*(1-$I33),0) -> 0
... K1000: =IFERROR(VLOOKUP(F1000,tbTurnos,3,FALSE),"") | N1000: =IFERROR(VLOOKUP(M1000,tbFactorMes,2,FALSE),"") | O1000: =IFERROR((L1000*$K1000)/N1000,0)*$J1000 -> 0 | R1000: =IFERROR(VLOOKUP(Q1000,tbFactorMes,2,FALSE),"") | S1000: =IFERROR((P1000*$K1000)/R1000,0)*$J1000 -> 0 | V1000: =IFERROR(VLOOKUP(U1000,tbFactorMes,2,FALSE),"") | W1000: =IFERROR((T1000*$K1000)/V1000,0)*$J1000 -> 0 | Z1000: =IFERROR(VLOOKUP(Y1000,tbFactorMes,2,FALSE),"") | AA1000: =IFERROR((X1000*$K1000)/Z1000,0)*$J1000 -> 0 | AD1000: =IFERROR(VLOOKUP(AC1000,tbFactorMes,2,FALSE),"") | AE1000: =IFERROR((AB1000*$K1000)/AD1000,0)*$J1000 -> 0 | AH1000: =IFERROR(VLOOKUP(AG1000,tbFactorMes,2,FALSE),"") | AI1000: =IFERROR((AF1000*$K1000)/AH1000,0)*$J1000 -> 0 | AL1000: =IFERROR(VLOOKUP(AK1000,tbFactorMes,2,FALSE),"") | AM1000: =IFERROR((AJ1000*$K1000)/AL1000,0)*$J1000 -> 0 | AP1000: =IFERROR(VLOOKUP(AO1000,tbFactorMes,2,FALSE),"") | AQ1000: =IFERROR((AN1000*$K1000)/AP1000,0)*$J1000 -> 0 | AT1000: =IFERROR(VLOOKUP(AS1000,tbFactorMes,2,FALSE),"") | AU1000: =IFERROR((AR1000*$K1000)/AT1000,0)*$J1000 -> 0 | AX1000: =IFERROR(VLOOKUP(AW1000,tbFactorMes,2,FALSE),"") | AY1000: =IFERROR((AV1000*$K1000)/AX1000,0)*$J1000 -> 0 | BB1000: =IFERROR(VLOOKUP(BA1000,tbFactorMes,2,FALSE),"") | BC1000: =IFERROR((AZ1000*$K1000)/BB1000,0)*$J1000 -> 0 | BF1000: =IFERROR(VLOOKUP(BE1000,tbFactorMes,2,FALSE),"") | BG1000: =IFERROR((BD1000*$K1000)/BF1000,0)*$J1000 -> 0 | BH1000: =IFERROR(SUM(O1000,S1000,W1000,AA1000,AE1000,AI1000,AM1000,AQ1000,AU1000,AY1000,BC1000,BG1000),0) -> 0 | BI1000: =IFERROR(BH1000*(1-$I1000),0) -> 0

Sheet 05_Benchmark
A1: Contrato comparable | B1: Año | C1: Tipo de servicio | D1: FTE referencia | E1: FTE propuesto (anual) | F1: Delta % | G1: ¿Dentro de rango? (±10%) | H1: Justificación
F2: =IFERROR((E2-D2)/D2,0) -> 0 | G2: =IF(ABS(F2)<=0.1,"Sí","No") -> Sí
F3: =IFERROR((E3-D3)/D3,0) -> 0 | G3: =IF(ABS(F3)<=0.1,"Sí","No") -> Sí
F4: =IFERROR((E4-D4)/D4,0) -> 0 | G4: =IF(ABS(F4)<=0.1,"Sí","No") -> Sí
F5: =IFERROR((E5-D5)/D5,0) -> 0 | G5: =IF(ABS(F5)<=0.1,"Sí","No") -> Sí
F6: =IFERROR((E6-D6)/D6,0) -> 0 | G6: =IF(ABS(F6)<=0.1,"Sí","No") -> Sí
F7: =IFERROR((E7-D7)/D7,0) -> 0 | G7: =IF(ABS(F7)<=0.1,"Sí","No") -> Sí
F8: =IFERROR((E8-D8)/D8,0) -> 0 | G8: =IF(ABS(F8)<=0.1,"Sí","No") -> Sí
F9: =IFERROR((E9-D9)/D9,0) -> 0 | G9: =IF(ABS(F9)<=0.1,"Sí","No") -> Sí
F10: =IFERROR((E10-D10)/D10,0) -> 0 | G10: =IF(ABS(F10)<=0.1,"Sí","No") -> Sí
F11: =IFERROR((E11-D11)/D11,0) -> 0 | G11: =IF(ABS(F11)<=0.1,"Sí","No") -> Sí
F12: =IFERROR((E12-D12)/D12,0) -> 0 | G12: =IF(ABS(F12)<=0.1,"Sí","No") -> Sí
F13: =IFERROR((E13-D13)/D13,0) -> 0 | G13: =IF(ABS(F13)<=0.1,"Sí","No") -> Sí
... F299: =IFERROR((E299-D299)/D299,0) -> 0 | G299: =IF(ABS(F299)<=0.1,"Sí","No") -> Sí

Sheet 06_Validación_GST
A1: Cumple rangos de razonabilidad (Sí/No) | B1: Cumple ratios técnicos (Sí/No) | C1: Cumple benchmark interno (Sí/No) | D1: Observaciones GST | E1: Ajuste aplicado (Sí/No) | F1: FTE original (anual) | G1: FTE ajustado (anual) | H1: Motivo ajuste | I1: Fecha validación | J1: Responsable validación | L1: *registro de si se validó la catego.
F2: =IFERROR('07_Resumen_Ejecutivo'!B3,0) -> 0 | G2: =IF(E2="Sí",G2,F2) -> 0 | L2: Sí
F3: =IFERROR('07_Resumen_Ejecutivo'!B3,0) -> 0 | G3: =IF(E3="Sí",G3,F3) -> 0 | L3: No
F4: =IFERROR('07_Resumen_Ejecutivo'!B3,0) -> 0 | G4: =IF(E4="Sí",G4,F4) -> 0
F5: =IFERROR('07_Resumen_Ejecutivo'!B3,0) -> 0 | G5: =IF(E5="Sí",G5,F5) -> 0
F6: =IFERROR('07_Resumen_Ejecutivo'!B3,0) -> 0 | G6: =IF(E6="Sí",G6,F6) -> 0
F7: =IFERROR('07_Resumen_Ejecutivo'!B3,0) -> 0 | G7: =IF(E7="Sí",G7,F7) -> 0
F8: =IFERROR('07_Resumen_Ejecutivo'!B3,0) -> 0 | G8: =IF(E8="Sí",G8,F8) -> 0
F9: =IFERROR('07_Resumen_Ejecutivo'!B3,0) -> 0 | G9: =IF(E9="Sí",G9,F9) -> 0
F10: =IFERROR('07_Resumen_Ejecutivo'!B3,0) -> 0 | G10: =IF(E10="Sí",G10,F10) -> 0
F11: =IFERROR('07_Resumen_Ejecutivo'!B3,0) -> 0 | G11: =IF(E11="Sí",G11,F11) -> 0
F12: =IFERROR('07_Resumen_Ejecutivo'!B3,0) -> 0 | G12: =IF(E12="Sí",G12,F12) -> 0
F13: =IFERROR('07_Resumen_Ejecutivo'!B3,0) -> 0 | G13: =IF(E13="Sí",G13,F13) -> 0
F14: =IFERROR('07_Resumen_Ejecutivo'!B3,0) -> 0 | G14: =IF(E14="Sí",G14,F14) -> 0
F15: =IFERROR('07_Resumen_Ejecutivo'!B3,0) -> 0 | G15: =IF(E15="Sí",G15,F15) -> 0
F16: =IFERROR('07_Resumen_Ejecutivo'!B3,0) -> 0 | G16: =IF(E16="Sí",G16,F16) -> 0
F17: =IFERROR('07_Resumen_Ejecutivo'!B3,0) -> 0 | G17: =IF(E17="Sí",G17,F17) -> 0
F18: =IFERROR('07_Resumen_Ejecutivo'!B3,0) -> 0 | G18: =IF(E18="Sí",G18,F18) -> 0
F19: =IFERROR('07_Resumen_Ejecutivo'!B3,0) -> 0 | G19: =IF(E19="Sí",G19,F19) -> 0
F20: =IFERROR('07_Resumen_Ejecutivo'!B3,0) -> 0 | G20: =IF(E20="Sí",G20,F20) -> 0
F21: =IFERROR('07_Resumen_Ejecutivo'!B3,0) -> 0 | G21: =IF(E21="Sí",G21,F21) -> 0
F22: =IFERROR('07_Resumen_Ejecutivo'!B3,0) -> 0 | G22: =IF(E22="Sí",G22,F22) -> 0
F23: =IFERROR('07_Resumen_Ejecutivo'!B3,0) -> 0 | G23: =IF(E23="Sí",G23,F23) -> 0
F24: =IFERROR('07_Resumen_Ejecutivo'!B3,0) -> 0 | G24: =IF(E24="Sí",G24,F24) -> 0
F25: =IFERROR('07_Resumen_Ejecutivo'!B3,0) -> 0 | G25: =IF(E25="Sí",G25,F25) -> 0
F26: =IFERROR('07_Resumen_Ejecutivo'!B3,0) -> 0 | G26: =IF(E26="Sí",G26,F26) -> 0
F27: =IFERROR('07_Resumen_Ejecutivo'!B3,0) -> 0 | G27: =IF(E27="Sí",G27,F27) -> 0
F28: =IFERROR('07_Resumen_Ejecutivo'!B3,0) -> 0 | G28: =IF(E28="Sí",G28,F28) -> 0
F29: =IFERROR('07_Resumen_Ejecutivo'!B3,0) -> 0 | G29: =IF(E29="Sí",G29,F29) -> 0
F30: =IFERROR('07_Resumen_Ejecutivo'!B3,0) -> 0 | G30: =IF(E30="Sí",G30,F30) -> 0
F31: =IFERROR('07_Resumen_Ejecutivo'!B3,0) -> 0 | G31: =IF(E31="Sí",G31,F31) -> 0
F32: =IFERROR('07_Resumen_Ejecutivo'!B3,0) -> 0 | G32: =IF(E32="Sí",G32,F32) -> 0
F33: =IFERROR('07_Resumen_Ejecutivo'!B3,0) -> 0 | G33: =IF(E33="Sí",G33,F33) -> 0
F34: =IFERROR('07_Resumen_Ejecutivo'!B3,0) -> 0 | G34: =IF(E34="Sí",G34,F34) -> 0
F35: =IFERROR('07_Resumen_Ejecutivo'!B3,0) -> 0 | G35: =IF(E35="Sí",G35,F35) -> 0
F36: =IFERROR('07_Resumen_Ejecutivo'!B3,0) -> 0 | G36: =IF(E36="Sí",G36,F36) -> 0
F37: =IFERROR('07_Resumen_Ejecutivo'!B3,0) -> 0 | G37: =IF(E37="Sí",G37,F37) -> 0
F38: =IFERROR('07_Resumen_Ejecutivo'!B3,0) -> 0 | G38: =IF(E38="Sí",G38,F38) -> 0
F39: =IFERROR('07_Resumen_Ejecutivo'!B3,0) -> 0 | G39: =IF(E39="Sí",G39,F39) -> 0
F40: =IFERROR('07_Resumen_Ejecutivo'!B3,0) -> 0 | G40: =IF(E40="Sí",G40,F40) -> 0
...

Sheet 07_Resumen_Ejecutivo
A1: Resumen Ejecutivo – Presupuesto Dotacional
A3: FTE contractual (anual estimado) | B3: =SUM('02_Dotación_Contractual'!MM) -> #NAME?
A4: FTE presupuestado (anual) | B4: =SUM('04_Ppto_FTE_Mensual'!BHBH) -> #NAME?
A5: Brecha % (ppto vs contractual) | B5: =IFERROR((B4-B3)/B3,0) -> 0
A6: FTE terreno (anual) | B6: =SUM('04_Ppto_FTE_Mensual'!BIBI) -> #NAME?
A7: % teletrabajo ponderado (referencial) | B7: =IFERROR(1-(B6/B4),0) -> 0

Sheet 96_Clasificacion_Dotacional
A1: Clasificación FTE (cerrada)
A2: CAPEX - Permanente (>6 meses)
A3: CAPEX - Temporal (<6 meses)
A4: CAPEX - Fuera de Faena MLP
A5: OPEX - Permanente (>6 meses)
A6: OPEX - Temporal (<6 meses)
A7: OPEX - Mantención Mayor / Campaña (Temporal)
A8: OPEX - Fuera de Faena MLP
A9: Teletrabajo - CAPEX Permanente
A10: Teletrabajo - CAPEX Temporal
A11: Teletrabajo - OPEX Permanente
A12: Teletrabajo - OPEX Temporal

Sheet 97_Factor_Mes
A1: N° días mes calendario | B1: Factor FTE mes
A2: 28 | B2: 168
A3: 29 | B3: 174
A4: 30 | B4: 180
A5: 31 | B5: 186

Sheet 98_Turnos_SIGA
A1: Turno | B1: Días laborables | C1: HH día turno
A2: 4x3 | B2: 4 | C2: 11.25
A3: 4x4 | B3: 4 | C3: 12
A4: 5x2 | B4: 5 | C4: 9
A5: 6x1 | B5: 6 | C5: 7.5
A6: 7x7 | B6: 7 | C6: 12
A7: 8x6 Ordinaria | B7: 8 | C7: 10
A8: 9x5 | B8: 9 | C8: 10
A9: 10x5 | B9: 10 | C9: 9
A10: 10x10 | B10: 10 | C10: 12
A11: 14x7 | B11: 14 | C11: 9.6
A12: 14x14 | B12: 14 | C12: 12
A13: 15x15 | B13: 15 | C13: 12
... A21: Temporal | B21: 5 | C21: 9

Sheet 99_Listas
A1: Listas para validaciones (hoja técnica)
A2: TipoContrato | B2: ViaFinanc | C2: Madurez | D2: Continuidad | E2: Alcance | F2: CondicionContractual | G2: ImpactoDotacion | H2: ModalidadTrabajo | I2: %Teletrabajo | J2: PermTemporal | K2: DirectaIndirecta | L2: TipoTemporal | M2: Turno | N2: Jornada
A3: PU | B3: OPEX | C3: 1 | D3: Continuo | E3: Año completo | F3: Contrato vigente | G3: Sin cambio relevante | H3: Presencial | I3: 0% | J3: Permanente | K3: Directa | L3: N/A | M3: 4x3 | N3: 12x4
A4: SA | B4: CAPEX | C4: 2 | D4: En transición / reemplazo | E4: Parcial (inicio o término durante el año) | F4: Contrato por relicitar | G4: Aumento esperado de dotación | H4: Teletrabajo | I4: 20% | J4: Temporal | K4: Indirecta | L4: Temporal continuo | M4: 4x4 | N4: 12x7
A5: Mixto | C5: 3 | D5: Nuevo / TBD | F5: Servicio nuevo sin contrato | G5: Disminución esperada de dotación | H5: Mixto | I5: 50% | L5: Temporal discontinuo | M5: 5x2 | N5: 8x5
I6: 80% | L6: Temporal parcial | M6: 6x1 | N6: Otra
I7: 100% | L7: Mantención mayor / campaña | M7: 7x7
M8: 8x6 Ordinaria
M9: 9x5
M10: 10x5
M11: 10x10
M12: 14x7
M13: 14x14
M14: 15x15
M15: 20x10
M16: Art.22 inc.2(4x3)
M17: Art.22 inc.2(5x2)
M18: Art.25 bis
M19: Art.26 bis
... M22: Temporal
