Workbook

Sheet Contrato
B1: REPORTE DOTACIONES + FTE | Z1: MES Y AÑO A INFORMAR | AH1: X
Z2: Julio | AE2: 2023
B5: NOMBRE EMPRESA | R5: RUT | Z5: Nº CONTRATO
Z7: (Nº SIGA 454000XXXX)
B9: ANTECEDENTES | H9: NOMBRES / APELLIDOS | R9: CORREOS | AB9: TELEFONOS
B11: ADC EECC
B12: RESPONSABLE RRHH
B13: ADC MLP
B14: RESPONSABLE REPORTE

Sheet Nomina_Perm_EnFaena
B1: A N T E C E D E N T E S G E N E R A L E S D E L T R A B A J A D O R P E R M A N E N T E | R1: ACOGIDOS A LEY 21.227 (PROTECCION AL EMPLEO) | T1: ACOGIDOS A LA LEY 21.220 | U1: JORNADA LABORAL | V1: Horas del mes (ingresar horas trabajadas correspondientes al turno de cada trabajador). Si el trabajador no estuvo presente, entonces registrar el valor 0 | BA1: Validaciones
B2: RUT | C2: NOMBRES | D2: APELLIDO PATERNO | E2: APELLIDO MATERNO | F2: FECHA NACIMIENTO | G2: TIPO CONTRATO | H2: TURNO | I2: CARGO | J2: FECHA INGRESO | K2: DOMICILIO PARTICULAR | L2: LOCALIDAD / CIUDAD | M2: REGION | N2: TELEFONO DE CONTACTO | O2: LUGAR DONDE PERNOCTAN | P2: N° DÍAS LICENCIA MEDICA | Q2: SEXO | R2: PACTO REDUCCION TEMPORAL | S2: PACTO SUSPENSION TEMPORAL | T2: TELETRABAJO | V2: 1 | W2: 2 | X2: 3 | Y2: 4 | Z2: 5 | AA2: 6 | AB2: 7 | AC2: 8 | AD2: 9 | AE2: 10 | AF2: 11 | AG2: 12 | AH2: 13 | AI2: 14 | AJ2: 15 | AK2: 16 | AL2: 17 | AM2: 18 | AN2: 19 | AO2: 20 | AP2: 21 | AQ2: 22 | AR2: 23 | AS2: 24 | AT2: 25 | AU2: 26 | AV2: 27 | AW2: 28 | AX2: 29 | AY2: 30 | AZ2: 31 | BA2: 1 | BB2: 2 | BC2: 3 | BD2: 4 | BE2: 5 | BF2: 6 | BG2: 7 | BH2: 8 | BI2: 9 | BJ2: 10 | BK2: 11 | BL2: 12 | BM2: 13 | BN2: 14 | BO2: 15 | BP2: 16 | BQ2: 17 | BR2: 18 | BS2: 19 | BT2: 20 | BU2: 21 | BV2: 22 | BW2: 23 | BX2: 24 | BY2: 25 | BZ2: 26 | CA2: 27 | CB2: 28 | CC2: 29 | CD2: 30 | CE2: 31
BA6: =IF(COUNTA($B6)=0,"",IFERROR(IF(V6<=VLOOKUP($H6,Listas!$J$2:$L$26,3,0),0,1),"T")) | BB6: =IF(COUNTA($B6)=0,"",IFERROR(IF(W6<=VLOOKUP($H6,Listas!$J$2:$L$26,3,0),0,1),"T")) | BC6: =IF(COUNTA($B6)=0,"",IFERROR(IF(X6<=VLOOKUP($H6,Listas!$J$2:$L$26,3,0),0,1),"T")) | BD6: =IF(COUNTA($B6)=0,"",IFERROR(IF(Y6<=VLOOKUP($H6,Listas!$J$2:$L$26,3,0),0,1),"T")) | BE6: =IF(COUNTA($B6)=0,"",IFERROR(IF(Z6<=VLOOKUP($H6,Listas!$J$2:$L$26,3,0),0,1),"T")) | BF6: =IF(COUNTA($B6)=0,"",IFERROR(IF(AA6<=VLOOKUP($H6,Listas!$J$2:$L$26,3,0),0,1),"T")) | BG6: =IF(COUNTA($B6)=0,"",IFERROR(IF(AB6<=VLOOKUP($H6,Listas!$J$2:$L$26,3,0),0,1),"T")) | BH6: =IF(COUNTA($B6)=0,"",IFERROR(IF(AC6<=VLOOKUP($H6,Listas!$J$2:$L$26,3,0),0,1),"T")) | ... CE6: =IF(COUNTA($B6)=0,"",IFERROR(IF(AZ6<=VLOOKUP($H6,Listas!$J$2:$L$26,3,0),0,1),"T"))
BA7: =IF(COUNTA($B7)=0,"",IFERROR(IF(V7<=VLOOKUP($H7,Listas!$J$2:$L$26,3,0),0,1),"T")) | BB7: =IF(COUNTA($B7)=0,"",IFERROR(IF(W7<=VLOOKUP($H7,Listas!$J$2:$L$26,3,0),0,1),"T")) | BC7: =IF(COUNTA($B7)=0,"",IFERROR(IF(X7<=VLOOKUP($H7,Listas!$J$2:$L$26,3,0),0,1),"T")) | BD7: =IF(COUNTA($B7)=0,"",IFERROR(IF(Y7<=VLOOKUP($H7,Listas!$J$2:$L$26,3,0),0,1),"T")) | BE7: =IF(COUNTA($B7)=0,"",IFERROR(IF(Z7<=VLOOKUP($H7,Listas!$J$2:$L$26,3,0),0,1),"T")) | BF7: =IF(COUNTA($B7)=0,"",IFERROR(IF(AA7<=VLOOKUP($H7,Listas!$J$2:$L$26,3,0),0,1),"T")) | BG7: =IF(COUNTA($B7)=0,"",IFERROR(IF(AB7<=VLOOKUP($H7,Listas!$J$2:$L$26,3,0),0,1),"T")) | BH7: =IF(COUNTA($B7)=0,"",IFERROR(IF(AC7<=VLOOKUP($H7,Listas!$J$2:$L$26,3,0),0,1),"T")) | ... CE7: =IF(COUNTA($B7)=0,"",IFERROR(IF(AZ7<=VLOOKUP($H7,Listas!$J$2:$L$26,3,0),0,1),"T"))
BA8: =IF(COUNTA($B8)=0,"",IFERROR(IF(V8<=VLOOKUP($H8,Listas!$J$2:$L$26,3,0),0,1),"T")) | BB8: =IF(COUNTA($B8)=0,"",IFERROR(IF(W8<=VLOOKUP($H8,Listas!$J$2:$L$26,3,0),0,1),"T")) | BC8: =IF(COUNTA($B8)=0,"",IFERROR(IF(X8<=VLOOKUP($H8,Listas!$J$2:$L$26,3,0),0,1),"T")) | BD8: =IF(COUNTA($B8)=0,"",IFERROR(IF(Y8<=VLOOKUP($H8,Listas!$J$2:$L$26,3,0),0,1),"T")) | BE8: =IF(COUNTA($B8)=0,"",IFERROR(IF(Z8<=VLOOKUP($H8,Listas!$J$2:$L$26,3,0),0,1),"T")) | BF8: =IF(COUNTA($B8)=0,"",IFERROR(IF(AA8<=VLOOKUP($H8,Listas!$J$2:$L$26,3,0),0,1),"T")) | BG8: =IF(COUNTA($B8)=0,"",IFERROR(IF(AB8<=VLOOKUP($H8,Listas!$J$2:$L$26,3,0),0,1),"T")) | BH8: =IF(COUNTA($B8)=0,"",IFERROR(IF(AC8<=VLOOKUP($H8,Listas!$J$2:$L$26,3,0),0,1),"T")) | ... CE8: =IF(COUNTA($B8)=0,"",IFERROR(IF(AZ8<=VLOOKUP($H8,Listas!$J$2:$L$26,3,0),0,1),"T"))
BA9: =IF(COUNTA($B9)=0,"",IFERROR(IF(V9<=VLOOKUP($H9,Listas!$J$2:$L$26,3,0),0,1),"T")) | BB9: =IF(COUNTA($B9)=0,"",IFERROR(IF(W9<=VLOOKUP($H9,Listas!$J$2:$L$26,3,0),0,1),"T")) | BC9: =IF(COUNTA($B9)=0,"",IFERROR(IF(X9<=VLOOKUP($H9,Listas!$J$2:$L$26,3,0),0,1),"T")) | BD9: =IF(COUNTA($B9)=0,"",IFERROR(IF(Y9<=VLOOKUP($H9,Listas!$J$2:$L$26,3,0),0,1),"T")) | BE9: =IF(COUNTA($B9)=0,"",IFERROR(IF(Z9<=VLOOKUP($H9,Listas!$J$2:$L$26,3,0),0,1),"T")) | BF9: =IF(COUNTA($B9)=0,"",IFERROR(IF(AA9<=VLOOKUP($H9,Listas!$J$2:$L$26,3,0),0,1),"T")) | BG9: =IF(COUNTA($B9)=0,"",IFERROR(IF(AB9<=VLOOKUP($H9,Listas!$J$2:$L$26,3,0),0,1),"T")) | BH9: =IF(COUNTA($B9)=0,"",IFERROR(IF(AC9<=VLOOKUP($H9,Listas!$J$2:$L$26,3,0),0,1),"T")) | ... CE9: =IF(COUNTA($B9)=0,"",IFERROR(IF(AZ9<=VLOOKUP($H9,Listas!$J$2:$L$26,3,0),0,1),"T"))
BA10: =IF(COUNTA($B10)=0,"",IFERROR(IF(V10<=VLOOKUP($H10,Listas!$J$2:$L$26,3,0),0,1),"T")) | BB10: =IF(COUNTA($B10)=0,"",IFERROR(IF(W10<=VLOOKUP($H10,Listas!$J$2:$L$26,3,0),0,1),"T")) | BC10: =IF(COUNTA($B10)=0,"",IFERROR(IF(X10<=VLOOKUP($H10,Listas!$J$2:$L$26,3,0),0,1),"T")) | BD10: =IF(COUNTA($B10)=0,"",IFERROR(IF(Y10<=VLOOKUP($H10,Listas!$J$2:$L$26,3,0),0,1),"T")) | BE10: =IF(COUNTA($B10)=0,"",IFERROR(IF(Z10<=VLOOKUP($H10,Listas!$J$2:$L$26,3,0),0,1),"T")) | BF10: =IF(COUNTA($B10)=0,"",IFERROR(IF(AA10<=VLOOKUP($H10,Listas!$J$2:$L$26,3,0),0,1),"T")) | BG10: =IF(COUNTA($B10)=0,"",IFERROR(IF(AB10<=VLOOKUP($H10,Listas!$J$2:$L$26,3,0),0,1),"T")) | BH10: =IF(COUNTA($B10)=0,"",IFERROR(IF(AC10<=VLOOKUP($H10,Listas!$J$2:$L$26,3,0),0,1),"T")) | ... CE10: =IF(COUNTA($B10)=0,"",IFERROR(IF(AZ10<=VLOOKUP($H10,Listas!$J$2:$L$26,3,0),0,1),"T"))
BA11: =IF(COUNTA($B11)=0,"",IFERROR(IF(V11<=VLOOKUP($H11,Listas!$J$2:$L$26,3,0),0,1),"T")) | BB11: =IF(COUNTA($B11)=0,"",IFERROR(IF(W11<=VLOOKUP($H11,Listas!$J$2:$L$26,3,0),0,1),"T")) | BC11: =IF(COUNTA($B11)=0,"",IFERROR(IF(X11<=VLOOKUP($H11,Listas!$J$2:$L$26,3,0),0,1),"T")) | BD11: =IF(COUNTA($B11)=0,"",IFERROR(IF(Y11<=VLOOKUP($H11,Listas!$J$2:$L$26,3,0),0,1),"T")) | BE11: =IF(COUNTA($B11)=0,"",IFERROR(IF(Z11<=VLOOKUP($H11,Listas!$J$2:$L$26,3,0),0,1),"T")) | BF11: =IF(COUNTA($B11)=0,"",IFERROR(IF(AA11<=VLOOKUP($H11,Listas!$J$2:$L$26,3,0),0,1),"T")) | BG11: =IF(COUNTA($B11)=0,"",IFERROR(IF(AB11<=VLOOKUP($H11,Listas!$J$2:$L$26,3,0),0,1),"T")) | BH11: =IF(COUNTA($B11)=0,"",IFERROR(IF(AC11<=VLOOKUP($H11,Listas!$J$2:$L$26,3,0),0,1),"T")) | ... CE11: =IF(COUNTA($B11)=0,"",IFERROR(IF(AZ11<=VLOOKUP($H11,Listas!$J$2:$L$26,3,0),0,1),"T"))
BA12: =IF(COUNTA($B12)=0,"",IFERROR(IF(V12<=VLOOKUP($H12,Listas!$J$2:$L$26,3,0),0,1),"T")) | BB12: =IF(COUNTA($B12)=0,"",IFERROR(IF(W12<=VLOOKUP($H12,Listas!$J$2:$L$26,3,0),0,1),"T")) | BC12: =IF(COUNTA($B12)=0,"",IFERROR(IF(X12<=VLOOKUP($H12,Listas!$J$2:$L$26,3,0),0,1),"T")) | BD12: =IF(COUNTA($B12)=0,"",IFERROR(IF(Y12<=VLOOKUP($H12,Listas!$J$2:$L$26,3,0),0,1),"T")) | BE12: =IF(COUNTA($B12)=0,"",IFERROR(IF(Z12<=VLOOKUP($H12,Listas!$J$2:$L$26,3,0),0,1),"T")) | BF12: =IF(COUNTA($B12)=0,"",IFERROR(IF(AA12<=VLOOKUP($H12,Listas!$J$2:$L$26,3,0),0,1),"T")) | BG12: =IF(COUNTA($B12)=0,"",IFERROR(IF(AB12<=VLOOKUP($H12,Listas!$J$2:$L$26,3,0),0,1),"T")) | BH12: =IF(COUNTA($B12)=0,"",IFERROR(IF(AC12<=VLOOKUP($H12,Listas!$J$2:$L$26,3,0),0,1),"T")) | ... CE12: =IF(COUNTA($B12)=0,"",IFERROR(IF(AZ12<=VLOOKUP($H12,Listas!$J$2:$L$26,3,0),0,1),"T"))
BA13: =IF(COUNTA($B13)=0,"",IFERROR(IF(V13<=VLOOKUP($H13,Listas!$J$2:$L$26,3,0),0,1),"T")) | BB13: =IF(COUNTA($B13)=0,"",IFERROR(IF(W13<=VLOOKUP($H13,Listas!$J$2:$L$26,3,0),0,1),"T")) | BC13: =IF(COUNTA($B13)=0,"",IFERROR(IF(X13<=VLOOKUP($H13,Listas!$J$2:$L$26,3,0),0,1),"T")) | BD13: =IF(COUNTA($B13)=0,"",IFERROR(IF(Y13<=VLOOKUP($H13,Listas!$J$2:$L$26,3,0),0,1),"T")) | BE13: =IF(COUNTA($B13)=0,"",IFERROR(IF(Z13<=VLOOKUP($H13,Listas!$J$2:$L$26,3,0),0,1),"T")) | BF13: =IF(COUNTA($B13)=0,"",IFERROR(IF(AA13<=VLOOKUP($H13,Listas!$J$2:$L$26,3,0),0,1),"T")) | BG13: =IF(COUNTA($B13)=0,"",IFERROR(IF(AB13<=VLOOKUP($H13,Listas!$J$2:$L$26,3,0),0,1),"T")) | BH13: =IF(COUNTA($B13)=0,"",IFERROR(IF(AC13<=VLOOKUP($H13,Listas!$J$2:$L$26,3,0),0,1),"T")) | ... CE13: =IF(COUNTA($B13)=0,"",IFERROR(IF(AZ13<=VLOOKUP($H13,Listas!$J$2:$L$26,3,0),0,1),"T"))
BA14: =IF(COUNTA($B14)=0,"",IFERROR(IF(V14<=VLOOKUP($H14,Listas!$J$2:$L$26,3,0),0,1),"T")) | BB14: =IF(COUNTA($B14)=0,"",IFERROR(IF(W14<=VLOOKUP($H14,Listas!$J$2:$L$26,3,0),0,1),"T")) | BC14: =IF(COUNTA($B14)=0,"",IFERROR(IF(X14<=VLOOKUP($H14,Listas!$J$2:$L$26,3,0),0,1),"T")) | BD14: =IF(COUNTA($B14)=0,"",IFERROR(IF(Y14<=VLOOKUP($H14,Listas!$J$2:$L$26,3,0),0,1),"T")) | BE14: =IF(COUNTA($B14)=0,"",IFERROR(IF(Z14<=VLOOKUP($H14,Listas!$J$2:$L$26,3,0),0,1),"T")) | BF14: =IF(COUNTA($B14)=0,"",IFERROR(IF(AA14<=VLOOKUP($H14,Listas!$J$2:$L$26,3,0),0,1),"T")) | BG14: =IF(COUNTA($B14)=0,"",IFERROR(IF(AB14<=VLOOKUP($H14,Listas!$J$2:$L$26,3,0),0,1),"T")) | BH14: =IF(COUNTA($B14)=0,"",IFERROR(IF(AC14<=VLOOKUP($H14,Listas!$J$2:$L$26,3,0),0,1),"T")) | ... CE14: =IF(COUNTA($B14)=0,"",IFERROR(IF(AZ14<=VLOOKUP($H14,Listas!$J$2:$L$26,3,0),0,1),"T"))
BA15: =IF(COUNTA($B15)=0,"",IFERROR(IF(V15<=VLOOKUP($H15,Listas!$J$2:$L$26,3,0),0,1),"T")) | BB15: =IF(COUNTA($B15)=0,"",IFERROR(IF(W15<=VLOOKUP($H15,Listas!$J$2:$L$26,3,0),0,1),"T")) | BC15: =IF(COUNTA($B15)=0,"",IFERROR(IF(X15<=VLOOKUP($H15,Listas!$J$2:$L$26,3,0),0,1),"T")) | BD15: =IF(COUNTA($B15)=0,"",IFERROR(IF(Y15<=VLOOKUP($H15,Listas!$J$2:$L$26,3,0),0,1),"T")) | BE15: =IF(COUNTA($B15)=0,"",IFERROR(IF(Z15<=VLOOKUP($H15,Listas!$J$2:$L$26,3,0),0,1),"T")) | BF15: =IF(COUNTA($B15)=0,"",IFERROR(IF(AA15<=VLOOKUP($H15,Listas!$J$2:$L$26,3,0),0,1),"T")) | BG15: =IF(COUNTA($B15)=0,"",IFERROR(IF(AB15<=VLOOKUP($H15,Listas!$J$2:$L$26,3,0),0,1),"T")) | BH15: =IF(COUNTA($B15)=0,"",IFERROR(IF(AC15<=VLOOKUP($H15,Listas!$J$2:$L$26,3,0),0,1),"T")) | ... CE15: =IF(COUNTA($B15)=0,"",IFERROR(IF(AZ15<=VLOOKUP($H15,Listas!$J$2:$L$26,3,0),0,1),"T"))
BA16: =IF(COUNTA($B16)=0,"",IFERROR(IF(V16<=VLOOKUP($H16,Listas!$J$2:$L$26,3,0),0,1),"T")) | BB16: =IF(COUNTA($B16)=0,"",IFERROR(IF(W16<=VLOOKUP($H16,Listas!$J$2:$L$26,3,0),0,1),"T")) | BC16: =IF(COUNTA($B16)=0,"",IFERROR(IF(X16<=VLOOKUP($H16,Listas!$J$2:$L$26,3,0),0,1),"T")) | BD16: =IF(COUNTA($B16)=0,"",IFERROR(IF(Y16<=VLOOKUP($H16,Listas!$J$2:$L$26,3,0),0,1),"T")) | BE16: =IF(COUNTA($B16)=0,"",IFERROR(IF(Z16<=VLOOKUP($H16,Listas!$J$2:$L$26,3,0),0,1),"T")) | BF16: =IF(COUNTA($B16)=0,"",IFERROR(IF(AA16<=VLOOKUP($H16,Listas!$J$2:$L$26,3,0),0,1),"T")) | BG16: =IF(COUNTA($B16)=0,"",IFERROR(IF(AB16<=VLOOKUP($H16,Listas!$J$2:$L$26,3,0),0,1),"T")) | BH16: =IF(COUNTA($B16)=0,"",IFERROR(IF(AC16<=VLOOKUP($H16,Listas!$J$2:$L$26,3,0),0,1),"T")) | ... CE16: =IF(COUNTA($B16)=0,"",IFERROR(IF(AZ16<=VLOOKUP($H16,Listas!$J$2:$L$26,3,0),0,1),"T"))
BA17: =IF(COUNTA($B17)=0,"",IFERROR(IF(V17<=VLOOKUP($H17,Listas!$J$2:$L$26,3,0),0,1),"T")) | BB17: =IF(COUNTA($B17)=0,"",IFERROR(IF(W17<=VLOOKUP($H17,Listas!$J$2:$L$26,3,0),0,1),"T")) | BC17: =IF(COUNTA($B17)=0,"",IFERROR(IF(X17<=VLOOKUP($H17,Listas!$J$2:$L$26,3,0),0,1),"T")) | BD17: =IF(COUNTA($B17)=0,"",IFERROR(IF(Y17<=VLOOKUP($H17,Listas!$J$2:$L$26,3,0),0,1),"T")) | BE17: =IF(COUNTA($B17)=0,"",IFERROR(IF(Z17<=VLOOKUP($H17,Listas!$J$2:$L$26,3,0),0,1),"T")) | BF17: =IF(COUNTA($B17)=0,"",IFERROR(IF(AA17<=VLOOKUP($H17,Listas!$J$2:$L$26,3,0),0,1),"T")) | BG17: =IF(COUNTA($B17)=0,"",IFERROR(IF(AB17<=VLOOKUP($H17,Listas!$J$2:$L$26,3,0),0,1),"T")) | BH17: =IF(COUNTA($B17)=0,"",IFERROR(IF(AC17<=VLOOKUP($H17,Listas!$J$2:$L$26,3,0),0,1),"T")) | ... CE17: =IF(COUNTA($B17)=0,"",IFERROR(IF(AZ17<=VLOOKUP($H17,Listas!$J$2:$L$26,3,0),0,1),"T"))
... BA596: =IF(COUNTA($B596)=0,"",IFERROR(IF(V596<=VLOOKUP($H596,Listas!$J$2:$L$26,3,0),0,1),"T")) | BB596: =IF(COUNTA($B596)=0,"",IFERROR(IF(W596<=VLOOKUP($H596,Listas!$J$2:$L$26,3,0),0,1),"T")) | BC596: =IF(COUNTA($B596)=0,"",IFERROR(IF(X596<=VLOOKUP($H596,Listas!$J$2:$L$26,3,0),0,1),"T")) | BD596: =IF(COUNTA($B596)=0,"",IFERROR(IF(Y596<=VLOOKUP($H596,Listas!$J$2:$L$26,3,0),0,1),"T")) | BE596: =IF(COUNTA($B596)=0,"",IFERROR(IF(Z596<=VLOOKUP($H596,Listas!$J$2:$L$26,3,0),0,1),"T")) | BF596: =IF(COUNTA($B596)=0,"",IFERROR(IF(AA596<=VLOOKUP($H596,Listas!$J$2:$L$26,3,0),0,1),"T")) | BG596: =IF(COUNTA($B596)=0,"",IFERROR(IF(AB596<=VLOOKUP($H596,Listas!$J$2:$L$26,3,0),0,1),"T")) | BH596: =IF(COUNTA($B596)=0,"",IFERROR(IF(AC596<=VLOOKUP($H596,Listas!$J$2:$L$26,3,0),0,1),"T")) | ... CE596: =IF(COUNTA($B596)=0,"",IFERROR(IF(AZ596<=VLOOKUP($H596,Listas!$J$2:$L$26,3,0),0,1),"T"))

Sheet Nomina_Perm_Fuera
B1: A N T E C E D E N T E S G E N E R A L E S D E L T R A B A J A D O R P E R M A N E N T E | R1: ACOGIDOS A LEY 21.227 (PROTECCION AL EMPLEO) | T1: ACOGIDOS A LA LEY 21.220 | U1: JORNADA LABORAL | V1: Horas del mes (ingresar horas trabajadas correspondientes al turno de cada trabajador). Si el trabajador no estuvo presente, entonces registrar el valor 0 | BA1: Validaciones
B2: RUT | C2: NOMBRES | D2: APELLIDO PATERNO | E2: APELLIDO MATERNO | F2: FECHA NACIMIENTO | G2: TIPO CONTRATO | H2: TURNO | I2: CARGO | J2: FECHA INGRESO | K2: DOMICILIO PARTICULAR | L2: LOCALIDAD / CIUDAD | M2: REGION | N2: TELEFONO DE CONTACTO | O2: LUGAR DONDE PERNOCTAN | P2: N° DÍAS LICENCIA MEDICA | Q2: SEXO | R2: PACTO REDUCCION TEMPORAL | S2: PACTO SUSPENSION TEMPORAL | T2: TELETRABAJO | V2: 1 | W2: 2 | X2: 3 | Y2: 4 | Z2: 5 | AA2: 6 | AB2: 7 | AC2: 8 | AD2: 9 | AE2: 10 | AF2: 11 | AG2: 12 | AH2: 13 | AI2: 14 | AJ2: 15 | AK2: 16 | AL2: 17 | AM2: 18 | AN2: 19 | AO2: 20 | AP2: 21 | AQ2: 22 | AR2: 23 | AS2: 24 | AT2: 25 | AU2: 26 | AV2: 27 | AW2: 28 | AX2: 29 | AY2: 30 | AZ2: 31 | BA2: 1 | BB2: 2 | BC2: 3 | BD2: 4 | BE2: 5 | BF2: 6 | BG2: 7 | BH2: 8 | BI2: 9 | BJ2: 10 | BK2: 11 | BL2: 12 | BM2: 13 | BN2: 14 | BO2: 15 | BP2: 16 | BQ2: 17 | BR2: 18 | BS2: 19 | BT2: 20 | BU2: 21 | BV2: 22 | BW2: 23 | BX2: 24 | BY2: 25 | BZ2: 26 | CA2: 27 | CB2: 28 | CC2: 29 | CD2: 30 | CE2: 31
BA6: =IF(COUNTA($B6)=0,"",IFERROR(IF(V6<=VLOOKUP($H6,Listas!$J$2:$L$26,3,0),0,1),"T")) | BB6: =IF(COUNTA($B6)=0,"",IFERROR(IF(W6<=VLOOKUP($H6,Listas!$J$2:$L$26,3,0),0,1),"T")) | BC6: =IF(COUNTA($B6)=0,"",IFERROR(IF(X6<=VLOOKUP($H6,Listas!$J$2:$L$26,3,0),0,1),"T")) | BD6: =IF(COUNTA($B6)=0,"",IFERROR(IF(Y6<=VLOOKUP($H6,Listas!$J$2:$L$26,3,0),0,1),"T")) | BE6: =IF(COUNTA($B6)=0,"",IFERROR(IF(Z6<=VLOOKUP($H6,Listas!$J$2:$L$26,3,0),0,1),"T")) | BF6: =IF(COUNTA($B6)=0,"",IFERROR(IF(AA6<=VLOOKUP($H6,Listas!$J$2:$L$26,3,0),0,1),"T")) | BG6: =IF(COUNTA($B6)=0,"",IFERROR(IF(AB6<=VLOOKUP($H6,Listas!$J$2:$L$26,3,0),0,1),"T")) | BH6: =IF(COUNTA($B6)=0,"",IFERROR(IF(AC6<=VLOOKUP($H6,Listas!$J$2:$L$26,3,0),0,1),"T")) | ... CE6: =IF(COUNTA($B6)=0,"",IFERROR(IF(AZ6<=VLOOKUP($H6,Listas!$J$2:$L$26,3,0),0,1),"T"))
BA7: =IF(COUNTA($B7)=0,"",IFERROR(IF(V7<=VLOOKUP($H7,Listas!$J$2:$L$26,3,0),0,1),"T")) | BB7: =IF(COUNTA($B7)=0,"",IFERROR(IF(W7<=VLOOKUP($H7,Listas!$J$2:$L$26,3,0),0,1),"T")) | BC7: =IF(COUNTA($B7)=0,"",IFERROR(IF(X7<=VLOOKUP($H7,Listas!$J$2:$L$26,3,0),0,1),"T")) | BD7: =IF(COUNTA($B7)=0,"",IFERROR(IF(Y7<=VLOOKUP($H7,Listas!$J$2:$L$26,3,0),0,1),"T")) | BE7: =IF(COUNTA($B7)=0,"",IFERROR(IF(Z7<=VLOOKUP($H7,Listas!$J$2:$L$26,3,0),0,1),"T")) | BF7: =IF(COUNTA($B7)=0,"",IFERROR(IF(AA7<=VLOOKUP($H7,Listas!$J$2:$L$26,3,0),0,1),"T")) | BG7: =IF(COUNTA($B7)=0,"",IFERROR(IF(AB7<=VLOOKUP($H7,Listas!$J$2:$L$26,3,0),0,1),"T")) | BH7: =IF(COUNTA($B7)=0,"",IFERROR(IF(AC7<=VLOOKUP($H7,Listas!$J$2:$L$26,3,0),0,1),"T")) | ... CE7: =IF(COUNTA($B7)=0,"",IFERROR(IF(AZ7<=VLOOKUP($H7,Listas!$J$2:$L$26,3,0),0,1),"T"))
BA8: =IF(COUNTA($B8)=0,"",IFERROR(IF(V8<=VLOOKUP($H8,Listas!$J$2:$L$26,3,0),0,1),"T")) | BB8: =IF(COUNTA($B8)=0,"",IFERROR(IF(W8<=VLOOKUP($H8,Listas!$J$2:$L$26,3,0),0,1),"T")) | BC8: =IF(COUNTA($B8)=0,"",IFERROR(IF(X8<=VLOOKUP($H8,Listas!$J$2:$L$26,3,0),0,1),"T")) | BD8: =IF(COUNTA($B8)=0,"",IFERROR(IF(Y8<=VLOOKUP($H8,Listas!$J$2:$L$26,3,0),0,1),"T")) | BE8: =IF(COUNTA($B8)=0,"",IFERROR(IF(Z8<=VLOOKUP($H8,Listas!$J$2:$L$26,3,0),0,1),"T")) | BF8: =IF(COUNTA($B8)=0,"",IFERROR(IF(AA8<=VLOOKUP($H8,Listas!$J$2:$L$26,3,0),0,1),"T")) | BG8: =IF(COUNTA($B8)=0,"",IFERROR(IF(AB8<=VLOOKUP($H8,Listas!$J$2:$L$26,3,0),0,1),"T")) | BH8: =IF(COUNTA($B8)=0,"",IFERROR(IF(AC8<=VLOOKUP($H8,Listas!$J$2:$L$26,3,0),0,1),"T")) | ... CE8: =IF(COUNTA($B8)=0,"",IFERROR(IF(AZ8<=VLOOKUP($H8,Listas!$J$2:$L$26,3,0),0,1),"T"))
BA9: =IF(COUNTA($B9)=0,"",IFERROR(IF(V9<=VLOOKUP($H9,Listas!$J$2:$L$26,3,0),0,1),"T")) | BB9: =IF(COUNTA($B9)=0,"",IFERROR(IF(W9<=VLOOKUP($H9,Listas!$J$2:$L$26,3,0),0,1),"T")) | BC9: =IF(COUNTA($B9)=0,"",IFERROR(IF(X9<=VLOOKUP($H9,Listas!$J$2:$L$26,3,0),0,1),"T")) | BD9: =IF(COUNTA($B9)=0,"",IFERROR(IF(Y9<=VLOOKUP($H9,Listas!$J$2:$L$26,3,0),0,1),"T")) | BE9: =IF(COUNTA($B9)=0,"",IFERROR(IF(Z9<=VLOOKUP($H9,Listas!$J$2:$L$26,3,0),0,1),"T")) | BF9: =IF(COUNTA($B9)=0,"",IFERROR(IF(AA9<=VLOOKUP($H9,Listas!$J$2:$L$26,3,0),0,1),"T")) | BG9: =IF(COUNTA($B9)=0,"",IFERROR(IF(AB9<=VLOOKUP($H9,Listas!$J$2:$L$26,3,0),0,1),"T")) | BH9: =IF(COUNTA($B9)=0,"",IFERROR(IF(AC9<=VLOOKUP($H9,Listas!$J$2:$L$26,3,0),0,1),"T")) | ... CE9: =IF(COUNTA($B9)=0,"",IFERROR(IF(AZ9<=VLOOKUP($H9,Listas!$J$2:$L$26,3,0),0,1),"T"))
BA10: =IF(COUNTA($B10)=0,"",IFERROR(IF(V10<=VLOOKUP($H10,Listas!$J$2:$L$26,3,0),0,1),"T")) | BB10: =IF(COUNTA($B10)=0,"",IFERROR(IF(W10<=VLOOKUP($H10,Listas!$J$2:$L$26,3,0),0,1),"T")) | BC10: =IF(COUNTA($B10)=0,"",IFERROR(IF(X10<=VLOOKUP($H10,Listas!$J$2:$L$26,3,0),0,1),"T")) | BD10: =IF(COUNTA($B10)=0,"",IFERROR(IF(Y10<=VLOOKUP($H10,Listas!$J$2:$L$26,3,0),0,1),"T")) | BE10: =IF(COUNTA($B10)=0,"",IFERROR(IF(Z10<=VLOOKUP($H10,Listas!$J$2:$L$26,3,0),0,1),"T")) | BF10: =IF(COUNTA($B10)=0,"",IFERROR(IF(AA10<=VLOOKUP($H10,Listas!$J$2:$L$26,3,0),0,1),"T")) | BG10: =IF(COUNTA($B10)=0,"",IFERROR(IF(AB10<=VLOOKUP($H10,Listas!$J$2:$L$26,3,0),0,1),"T")) | BH10: =IF(COUNTA($B10)=0,"",IFERROR(IF(AC10<=VLOOKUP($H10,Listas!$J$2:$L$26,3,0),0,1),"T")) | ... CE10: =IF(COUNTA($B10)=0,"",IFERROR(IF(AZ10<=VLOOKUP($H10,Listas!$J$2:$L$26,3,0),0,1),"T"))
BA11: =IF(COUNTA($B11)=0,"",IFERROR(IF(V11<=VLOOKUP($H11,Listas!$J$2:$L$26,3,0),0,1),"T")) | BB11: =IF(COUNTA($B11)=0,"",IFERROR(IF(W11<=VLOOKUP($H11,Listas!$J$2:$L$26,3,0),0,1),"T")) | BC11: =IF(COUNTA($B11)=0,"",IFERROR(IF(X11<=VLOOKUP($H11,Listas!$J$2:$L$26,3,0),0,1),"T")) | BD11: =IF(COUNTA($B11)=0,"",IFERROR(IF(Y11<=VLOOKUP($H11,Listas!$J$2:$L$26,3,0),0,1),"T")) | BE11: =IF(COUNTA($B11)=0,"",IFERROR(IF(Z11<=VLOOKUP($H11,Listas!$J$2:$L$26,3,0),0,1),"T")) | BF11: =IF(COUNTA($B11)=0,"",IFERROR(IF(AA11<=VLOOKUP($H11,Listas!$J$2:$L$26,3,0),0,1),"T")) | BG11: =IF(COUNTA($B11)=0,"",IFERROR(IF(AB11<=VLOOKUP($H11,Listas!$J$2:$L$26,3,0),0,1),"T")) | BH11: =IF(COUNTA($B11)=0,"",IFERROR(IF(AC11<=VLOOKUP($H11,Listas!$J$2:$L$26,3,0),0,1),"T")) | ... CE11: =IF(COUNTA($B11)=0,"",IFERROR(IF(AZ11<=VLOOKUP($H11,Listas!$J$2:$L$26,3,0),0,1),"T"))
BA12: =IF(COUNTA($B12)=0,"",IFERROR(IF(V12<=VLOOKUP($H12,Listas!$J$2:$L$26,3,0),0,1),"T")) | BB12: =IF(COUNTA($B12)=0,"",IFERROR(IF(W12<=VLOOKUP($H12,Listas!$J$2:$L$26,3,0),0,1),"T")) | BC12: =IF(COUNTA($B12)=0,"",IFERROR(IF(X12<=VLOOKUP($H12,Listas!$J$2:$L$26,3,0),0,1),"T")) | BD12: =IF(COUNTA($B12)=0,"",IFERROR(IF(Y12<=VLOOKUP($H12,Listas!$J$2:$L$26,3,0),0,1),"T")) | BE12: =IF(COUNTA($B12)=0,"",IFERROR(IF(Z12<=VLOOKUP($H12,Listas!$J$2:$L$26,3,0),0,1),"T")) | BF12: =IF(COUNTA($B12)=0,"",IFERROR(IF(AA12<=VLOOKUP($H12,Listas!$J$2:$L$26,3,0),0,1),"T")) | BG12: =IF(COUNTA($B12)=0,"",IFERROR(IF(AB12<=VLOOKUP($H12,Listas!$J$2:$L$26,3,0),0,1),"T")) | BH12: =IF(COUNTA($B12)=0,"",IFERROR(IF(AC12<=VLOOKUP($H12,Listas!$J$2:$L$26,3,0),0,1),"T")) | ... CE12: =IF(COUNTA($B12)=0,"",IFERROR(IF(AZ12<=VLOOKUP($H12,Listas!$J$2:$L$26,3,0),0,1),"T"))
BA13: =IF(COUNTA($B13)=0,"",IFERROR(IF(V13<=VLOOKUP($H13,Listas!$J$2:$L$26,3,0),0,1),"T")) | BB13: =IF(COUNTA($B13)=0,"",IFERROR(IF(W13<=VLOOKUP($H13,Listas!$J$2:$L$26,3,0),0,1),"T")) | BC13: =IF(COUNTA($B13)=0,"",IFERROR(IF(X13<=VLOOKUP($H13,Listas!$J$2:$L$26,3,0),0,1),"T")) | BD13: =IF(COUNTA($B13)=0,"",IFERROR(IF(Y13<=VLOOKUP($H13,Listas!$J$2:$L$26,3,0),0,1),"T")) | BE13: =IF(COUNTA($B13)=0,"",IFERROR(IF(Z13<=VLOOKUP($H13,Listas!$J$2:$L$26,3,0),0,1),"T")) | BF13: =IF(COUNTA($B13)=0,"",IFERROR(IF(AA13<=VLOOKUP($H13,Listas!$J$2:$L$26,3,0),0,1),"T")) | BG13: =IF(COUNTA($B13)=0,"",IFERROR(IF(AB13<=VLOOKUP($H13,Listas!$J$2:$L$26,3,0),0,1),"T")) | BH13: =IF(COUNTA($B13)=0,"",IFERROR(IF(AC13<=VLOOKUP($H13,Listas!$J$2:$L$26,3,0),0,1),"T")) | ... CE13: =IF(COUNTA($B13)=0,"",IFERROR(IF(AZ13<=VLOOKUP($H13,Listas!$J$2:$L$26,3,0),0,1),"T"))
BA14: =IF(COUNTA($B14)=0,"",IFERROR(IF(V14<=VLOOKUP($H14,Listas!$J$2:$L$26,3,0),0,1),"T")) | BB14: =IF(COUNTA($B14)=0,"",IFERROR(IF(W14<=VLOOKUP($H14,Listas!$J$2:$L$26,3,0),0,1),"T")) | BC14: =IF(COUNTA($B14)=0,"",IFERROR(IF(X14<=VLOOKUP($H14,Listas!$J$2:$L$26,3,0),0,1),"T")) | BD14: =IF(COUNTA($B14)=0,"",IFERROR(IF(Y14<=VLOOKUP($H14,Listas!$J$2:$L$26,3,0),0,1),"T")) | BE14: =IF(COUNTA($B14)=0,"",IFERROR(IF(Z14<=VLOOKUP($H14,Listas!$J$2:$L$26,3,0),0,1),"T")) | BF14: =IF(COUNTA($B14)=0,"",IFERROR(IF(AA14<=VLOOKUP($H14,Listas!$J$2:$L$26,3,0),0,1),"T")) | BG14: =IF(COUNTA($B14)=0,"",IFERROR(IF(AB14<=VLOOKUP($H14,Listas!$J$2:$L$26,3,0),0,1),"T")) | BH14: =IF(COUNTA($B14)=0,"",IFERROR(IF(AC14<=VLOOKUP($H14,Listas!$J$2:$L$26,3,0),0,1),"T")) | ... CE14: =IF(COUNTA($B14)=0,"",IFERROR(IF(AZ14<=VLOOKUP($H14,Listas!$J$2:$L$26,3,0),0,1),"T"))
BA15: =IF(COUNTA($B15)=0,"",IFERROR(IF(V15<=VLOOKUP($H15,Listas!$J$2:$L$26,3,0),0,1),"T")) | BB15: =IF(COUNTA($B15)=0,"",IFERROR(IF(W15<=VLOOKUP($H15,Listas!$J$2:$L$26,3,0),0,1),"T")) | BC15: =IF(COUNTA($B15)=0,"",IFERROR(IF(X15<=VLOOKUP($H15,Listas!$J$2:$L$26,3,0),0,1),"T")) | BD15: =IF(COUNTA($B15)=0,"",IFERROR(IF(Y15<=VLOOKUP($H15,Listas!$J$2:$L$26,3,0),0,1),"T")) | BE15: =IF(COUNTA($B15)=0,"",IFERROR(IF(Z15<=VLOOKUP($H15,Listas!$J$2:$L$26,3,0),0,1),"T")) | BF15: =IF(COUNTA($B15)=0,"",IFERROR(IF(AA15<=VLOOKUP($H15,Listas!$J$2:$L$26,3,0),0,1),"T")) | BG15: =IF(COUNTA($B15)=0,"",IFERROR(IF(AB15<=VLOOKUP($H15,Listas!$J$2:$L$26,3,0),0,1),"T")) | BH15: =IF(COUNTA($B15)=0,"",IFERROR(IF(AC15<=VLOOKUP($H15,Listas!$J$2:$L$26,3,0),0,1),"T")) | ... CE15: =IF(COUNTA($B15)=0,"",IFERROR(IF(AZ15<=VLOOKUP($H15,Listas!$J$2:$L$26,3,0),0,1),"T"))
BA16: =IF(COUNTA($B16)=0,"",IFERROR(IF(V16<=VLOOKUP($H16,Listas!$J$2:$L$26,3,0),0,1),"T")) | BB16: =IF(COUNTA($B16)=0,"",IFERROR(IF(W16<=VLOOKUP($H16,Listas!$J$2:$L$26,3,0),0,1),"T")) | BC16: =IF(COUNTA($B16)=0,"",IFERROR(IF(X16<=VLOOKUP($H16,Listas!$J$2:$L$26,3,0),0,1),"T")) | BD16: =IF(COUNTA($B16)=0,"",IFERROR(IF(Y16<=VLOOKUP($H16,Listas!$J$2:$L$26,3,0),0,1),"T")) | BE16: =IF(COUNTA($B16)=0,"",IFERROR(IF(Z16<=VLOOKUP($H16,Listas!$J$2:$L$26,3,0),0,1),"T")) | BF16: =IF(COUNTA($B16)=0,"",IFERROR(IF(AA16<=VLOOKUP($H16,Listas!$J$2:$L$26,3,0),0,1),"T")) | BG16: =IF(COUNTA($B16)=0,"",IFERROR(IF(AB16<=VLOOKUP($H16,Listas!$J$2:$L$26,3,0),0,1),"T")) | BH16: =IF(COUNTA($B16)=0,"",IFERROR(IF(AC16<=VLOOKUP($H16,Listas!$J$2:$L$26,3,0),0,1),"T")) | ... CE16: =IF(COUNTA($B16)=0,"",IFERROR(IF(AZ16<=VLOOKUP($H16,Listas!$J$2:$L$26,3,0),0,1),"T"))
BA17: =IF(COUNTA($B17)=0,"",IFERROR(IF(V17<=VLOOKUP($H17,Listas!$J$2:$L$26,3,0),0,1),"T")) | BB17: =IF(COUNTA($B17)=0,"",IFERROR(IF(W17<=VLOOKUP($H17,Listas!$J$2:$L$26,3,0),0,1),"T")) | BC17: =IF(COUNTA($B17)=0,"",IFERROR(IF(X17<=VLOOKUP($H17,Listas!$J$2:$L$26,3,0),0,1),"T")) | BD17: =IF(COUNTA($B17)=0,"",IFERROR(IF(Y17<=VLOOKUP($H17,Listas!$J$2:$L$26,3,0),0,1),"T")) | BE17: =IF(COUNTA($B17)=0,"",IFERROR(IF(Z17<=VLOOKUP($H17,Listas!$J$2:$L$26,3,0),0,1),"T")) | BF17: =IF(COUNTA($B17)=0,"",IFERROR(IF(AA17<=VLOOKUP($H17,Listas!$J$2:$L$26,3,0),0,1),"T")) | BG17: =IF(COUNTA($B17)=0,"",IFERROR(IF(AB17<=VLOOKUP($H17,Listas!$J$2:$L$26,3,0),0,1),"T")) | BH17: =IF(COUNTA($B17)=0,"",IFERROR(IF(AC17<=VLOOKUP($H17,Listas!$J$2:$L$26,3,0),0,1),"T")) | ... CE17: =IF(COUNTA($B17)=0,"",IFERROR(IF(AZ17<=VLOOKUP($H17,Listas!$J$2:$L$26,3,0),0,1),"T"))
... BA596: =IF(COUNTA($B596)=0,"",IFERROR(IF(V596<=VLOOKUP($H596,Listas!$J$2:$L$26,3,0),0,1),"T")) | BB596: =IF(COUNTA($B596)=0,"",IFERROR(IF(W596<=VLOOKUP($H596,Listas!$J$2:$L$26,3,0),0,1),"T")) | BC596: =IF(COUNTA($B596)=0,"",IFERROR(IF(X596<=VLOOKUP($H596,Listas!$J$2:$L$26,3,0),0,1),"T")) | BD596: =IF(COUNTA($B596)=0,"",IFERROR(IF(Y596<=VLOOKUP($H596,Listas!$J$2:$L$26,3,0),0,1),"T")) | BE596: =IF(COUNTA($B596)=0,"",IFERROR(IF(Z596<=VLOOKUP($H596,Listas!$J$2:$L$26,3,0),0,1),"T")) | BF596: =IF(COUNTA($B596)=0,"",IFERROR(IF(AA596<=VLOOKUP($H596,Listas!$J$2:$L$26,3,0),0,1),"T")) | BG596: =IF(COUNTA($B596)=0,"",IFERROR(IF(AB596<=VLOOKUP($H596,Listas!$J$2:$L$26,3,0),0,1),"T")) | BH596: =IF(COUNTA($B596)=0,"",IFERROR(IF(AC596<=VLOOKUP($H596,Listas!$J$2:$L$26,3,0),0,1),"T")) | ... CE596: =IF(COUNTA($B596)=0,"",IFERROR(IF(AZ596<=VLOOKUP($H596,Listas!$J$2:$L$26,3,0),0,1),"T"))

Sheet Nomina_Perm_Teletrabajo
B1: A N T E C E D E N T E S G E N E R A L E S D E L T R A B A J A D O R P E R M A N E N T E | R1: ACOGIDOS A LEY 21.227 (PROTECCION AL EMPLEO) | T1: ACOGIDOS A LA LEY 21.220 | U1: JORNADA LABORAL | V1: Horas del mes (ingresar horas trabajadas correspondientes al turno de cada trabajador). Si el trabajador no estuvo presente, entonces registrar el valor 0 | BA1: Validaciones
B2: RUT | C2: NOMBRES | D2: APELLIDO PATERNO | E2: APELLIDO MATERNO | F2: FECHA NACIMIENTO | G2: TIPO CONTRATO | H2: TURNO | I2: CARGO | J2: FECHA INGRESO | K2: DOMICILIO PARTICULAR | L2: LOCALIDAD / CIUDAD | M2: REGION | N2: TELEFONO DE CONTACTO | O2: LUGAR DONDE PERNOCTAN | P2: N° DÍAS LICENCIA MEDICA | Q2: SEXO | R2: PACTO REDUCCION TEMPORAL | S2: PACTO SUSPENSION TEMPORAL | T2: TELETRABAJO | V2: 1 | W2: 2 | X2: 3 | Y2: 4 | Z2: 5 | AA2: 6 | AB2: 7 | AC2: 8 | AD2: 9 | AE2: 10 | AF2: 11 | AG2: 12 | AH2: 13 | AI2: 14 | AJ2: 15 | AK2: 16 | AL2: 17 | AM2: 18 | AN2: 19 | AO2: 20 | AP2: 21 | AQ2: 22 | AR2: 23 | AS2: 24 | AT2: 25 | AU2: 26 | AV2: 27 | AW2: 28 | AX2: 29 | AY2: 30 | AZ2: 31 | BA2: 1 | BB2: 2 | BC2: 3 | BD2: 4 | BE2: 5 | BF2: 6 | BG2: 7 | BH2: 8 | BI2: 9 | BJ2: 10 | BK2: 11 | BL2: 12 | BM2: 13 | BN2: 14 | BO2: 15 | BP2: 16 | BQ2: 17 | BR2: 18 | BS2: 19 | BT2: 20 | BU2: 21 | BV2: 22 | BW2: 23 | BX2: 24 | BY2: 25 | BZ2: 26 | CA2: 27 | CB2: 28 | CC2: 29 | CD2: 30 | CE2: 31
BA6: =IF(COUNTA($B6)=0,"",IFERROR(IF(V6<=VLOOKUP($H6,Listas!$J$2:$L$26,3,0),0,1),"T")) | BB6: =IF(COUNTA($B6)=0,"",IFERROR(IF(W6<=VLOOKUP($H6,Listas!$J$2:$L$26,3,0),0,1),"T")) | BC6: =IF(COUNTA($B6)=0,"",IFERROR(IF(X6<=VLOOKUP($H6,Listas!$J$2:$L$26,3,0),0,1),"T")) | BD6: =IF(COUNTA($B6)=0,"",IFERROR(IF(Y6<=VLOOKUP($H6,Listas!$J$2:$L$26,3,0),0,1),"T")) | BE6: =IF(COUNTA($B6)=0,"",IFERROR(IF(Z6<=VLOOKUP($H6,Listas!$J$2:$L$26,3,0),0,1),"T")) | BF6: =IF(COUNTA($B6)=0,"",IFERROR(IF(AA6<=VLOOKUP($H6,Listas!$J$2:$L$26,3,0),0,1),"T")) | BG6: =IF(COUNTA($B6)=0,"",IFERROR(IF(AB6<=VLOOKUP($H6,Listas!$J$2:$L$26,3,0),0,1),"T")) | BH6: =IF(COUNTA($B6)=0,"",IFERROR(IF(AC6<=VLOOKUP($H6,Listas!$J$2:$L$26,3,0),0,1),"T")) | ... CE6: =IF(COUNTA($B6)=0,"",IFERROR(IF(AZ6<=VLOOKUP($H6,Listas!$J$2:$L$26,3,0),0,1),"T"))
BA7: =IF(COUNTA($B7)=0,"",IFERROR(IF(V7<=VLOOKUP($H7,Listas!$J$2:$L$26,3,0),0,1),"T")) | BB7: =IF(COUNTA($B7)=0,"",IFERROR(IF(W7<=VLOOKUP($H7,Listas!$J$2:$L$26,3,0),0,1),"T")) | BC7: =IF(COUNTA($B7)=0,"",IFERROR(IF(X7<=VLOOKUP($H7,Listas!$J$2:$L$26,3,0),0,1),"T")) | BD7: =IF(COUNTA($B7)=0,"",IFERROR(IF(Y7<=VLOOKUP($H7,Listas!$J$2:$L$26,3,0),0,1),"T")) | BE7: =IF(COUNTA($B7)=0,"",IFERROR(IF(Z7<=VLOOKUP($H7,Listas!$J$2:$L$26,3,0),0,1),"T")) | BF7: =IF(COUNTA($B7)=0,"",IFERROR(IF(AA7<=VLOOKUP($H7,Listas!$J$2:$L$26,3,0),0,1),"T")) | BG7: =IF(COUNTA($B7)=0,"",IFERROR(IF(AB7<=VLOOKUP($H7,Listas!$J$2:$L$26,3,0),0,1),"T")) | BH7: =IF(COUNTA($B7)=0,"",IFERROR(IF(AC7<=VLOOKUP($H7,Listas!$J$2:$L$26,3,0),0,1),"T")) | ... CE7: =IF(COUNTA($B7)=0,"",IFERROR(IF(AZ7<=VLOOKUP($H7,Listas!$J$2:$L$26,3,0),0,1),"T"))
BA8: =IF(COUNTA($B8)=0,"",IFERROR(IF(V8<=VLOOKUP($H8,Listas!$J$2:$L$26,3,0),0,1),"T")) | BB8: =IF(COUNTA($B8)=0,"",IFERROR(IF(W8<=VLOOKUP($H8,Listas!$J$2:$L$26,3,0),0,1),"T")) | BC8: =IF(COUNTA($B8)=0,"",IFERROR(IF(X8<=VLOOKUP($H8,Listas!$J$2:$L$26,3,0),0,1),"T")) | BD8: =IF(COUNTA($B8)=0,"",IFERROR(IF(Y8<=VLOOKUP($H8,Listas!$J$2:$L$26,3,0),0,1),"T")) | BE8: =IF(COUNTA($B8)=0,"",IFERROR(IF(Z8<=VLOOKUP($H8,Listas!$J$2:$L$26,3,0),0,1),"T")) | BF8: =IF(COUNTA($B8)=0,"",IFERROR(IF(AA8<=VLOOKUP($H8,Listas!$J$2:$L$26,3,0),0,1),"T")) | BG8: =IF(COUNTA($B8)=0,"",IFERROR(IF(AB8<=VLOOKUP($H8,Listas!$J$2:$L$26,3,0),0,1),"T")) | BH8: =IF(COUNTA($B8)=0,"",IFERROR(IF(AC8<=VLOOKUP($H8,Listas!$J$2:$L$26,3,0),0,1),"T")) | ... CE8: =IF(COUNTA($B8)=0,"",IFERROR(IF(AZ8<=VLOOKUP($H8,Listas!$J$2:$L$26,3,0),0,1),"T"))
BA9: =IF(COUNTA($B9)=0,"",IFERROR(IF(V9<=VLOOKUP($H9,Listas!$J$2:$L$26,3,0),0,1),"T")) | BB9: =IF(COUNTA($B9)=0,"",IFERROR(IF(W9<=VLOOKUP($H9,Listas!$J$2:$L$26,3,0),0,1),"T")) | BC9: =IF(COUNTA($B9)=0,"",IFERROR(IF(X9<=VLOOKUP($H9,Listas!$J$2:$L$26,3,0),0,1),"T")) | BD9: =IF(COUNTA($B9)=0,"",IFERROR(IF(Y9<=VLOOKUP($H9,Listas!$J$2:$L$26,3,0),0,1),"T")) | BE9: =IF(COUNTA($B9)=0,"",IFERROR(IF(Z9<=VLOOKUP($H9,Listas!$J$2:$L$26,3,0),0,1),"T")) | BF9: =IF(COUNTA($B9)=0,"",IFERROR(IF(AA9<=VLOOKUP($H9,Listas!$J$2:$L$26,3,0),0,1),"T")) | BG9: =IF(COUNTA($B9)=0,"",IFERROR(IF(AB9<=VLOOKUP($H9,Listas!$J$2:$L$26,3,0),0,1),"T")) | BH9: =IF(COUNTA($B9)=0,"",IFERROR(IF(AC9<=VLOOKUP($H9,Listas!$J$2:$L$26,3,0),0,1),"T")) | ... CE9: =IF(COUNTA($B9)=0,"",IFERROR(IF(AZ9<=VLOOKUP($H9,Listas!$J$2:$L$26,3,0),0,1),"T"))
BA10: =IF(COUNTA($B10)=0,"",IFERROR(IF(V10<=VLOOKUP($H10,Listas!$J$2:$L$26,3,0),0,1),"T")) | BB10: =IF(COUNTA($B10)=0,"",IFERROR(IF(W10<=VLOOKUP($H10,Listas!$J$2:$L$26,3,0),0,1),"T")) | BC10: =IF(COUNTA($B10)=0,"",IFERROR(IF(X10<=VLOOKUP($H10,Listas!$J$2:$L$26,3,0),0,1),"T")) | BD10: =IF(COUNTA($B10)=0,"",IFERROR(IF(Y10<=VLOOKUP($H10,Listas!$J$2:$L$26,3,0),0,1),"T")) | BE10: =IF(COUNTA($B10)=0,"",IFERROR(IF(Z10<=VLOOKUP($H10,Listas!$J$2:$L$26,3,0),0,1),"T")) | BF10: =IF(COUNTA($B10)=0,"",IFERROR(IF(AA10<=VLOOKUP($H10,Listas!$J$2:$L$26,3,0),0,1),"T")) | BG10: =IF(COUNTA($B10)=0,"",IFERROR(IF(AB10<=VLOOKUP($H10,Listas!$J$2:$L$26,3,0),0,1),"T")) | BH10: =IF(COUNTA($B10)=0,"",IFERROR(IF(AC10<=VLOOKUP($H10,Listas!$J$2:$L$26,3,0),0,1),"T")) | ... CE10: =IF(COUNTA($B10)=0,"",IFERROR(IF(AZ10<=VLOOKUP($H10,Listas!$J$2:$L$26,3,0),0,1),"T"))
BA11: =IF(COUNTA($B11)=0,"",IFERROR(IF(V11<=VLOOKUP($H11,Listas!$J$2:$L$26,3,0),0,1),"T")) | BB11: =IF(COUNTA($B11)=0,"",IFERROR(IF(W11<=VLOOKUP($H11,Listas!$J$2:$L$26,3,0),0,1),"T")) | BC11: =IF(COUNTA($B11)=0,"",IFERROR(IF(X11<=VLOOKUP($H11,Listas!$J$2:$L$26,3,0),0,1),"T")) | BD11: =IF(COUNTA($B11)=0,"",IFERROR(IF(Y11<=VLOOKUP($H11,Listas!$J$2:$L$26,3,0),0,1),"T")) | BE11: =IF(COUNTA($B11)=0,"",IFERROR(IF(Z11<=VLOOKUP($H11,Listas!$J$2:$L$26,3,0),0,1),"T")) | BF11: =IF(COUNTA($B11)=0,"",IFERROR(IF(AA11<=VLOOKUP($H11,Listas!$J$2:$L$26,3,0),0,1),"T")) | BG11: =IF(COUNTA($B11)=0,"",IFERROR(IF(AB11<=VLOOKUP($H11,Listas!$J$2:$L$26,3,0),0,1),"T")) | BH11: =IF(COUNTA($B11)=0,"",IFERROR(IF(AC11<=VLOOKUP($H11,Listas!$J$2:$L$26,3,0),0,1),"T")) | ... CE11: =IF(COUNTA($B11)=0,"",IFERROR(IF(AZ11<=VLOOKUP($H11,Listas!$J$2:$L$26,3,0),0,1),"T"))
BA12: =IF(COUNTA($B12)=0,"",IFERROR(IF(V12<=VLOOKUP($H12,Listas!$J$2:$L$26,3,0),0,1),"T")) | BB12: =IF(COUNTA($B12)=0,"",IFERROR(IF(W12<=VLOOKUP($H12,Listas!$J$2:$L$26,3,0),0,1),"T")) | BC12: =IF(COUNTA($B12)=0,"",IFERROR(IF(X12<=VLOOKUP($H12,Listas!$J$2:$L$26,3,0),0,1),"T")) | BD12: =IF(COUNTA($B12)=0,"",IFERROR(IF(Y12<=VLOOKUP($H12,Listas!$J$2:$L$26,3,0),0,1),"T")) | BE12: =IF(COUNTA($B12)=0,"",IFERROR(IF(Z12<=VLOOKUP($H12,Listas!$J$2:$L$26,3,0),0,1),"T")) | BF12: =IF(COUNTA($B12)=0,"",IFERROR(IF(AA12<=VLOOKUP($H12,Listas!$J$2:$L$26,3,0),0,1),"T")) | BG12: =IF(COUNTA($B12)=0,"",IFERROR(IF(AB12<=VLOOKUP($H12,Listas!$J$2:$L$26,3,0),0,1),"T")) | BH12: =IF(COUNTA($B12)=0,"",IFERROR(IF(AC12<=VLOOKUP($H12,Listas!$J$2:$L$26,3,0),0,1),"T")) | ... CE12: =IF(COUNTA($B12)=0,"",IFERROR(IF(AZ12<=VLOOKUP($H12,Listas!$J$2:$L$26,3,0),0,1),"T"))
BA13: =IF(COUNTA($B13)=0,"",IFERROR(IF(V13<=VLOOKUP($H13,Listas!$J$2:$L$26,3,0),0,1),"T")) | BB13: =IF(COUNTA($B13)=0,"",IFERROR(IF(W13<=VLOOKUP($H13,Listas!$J$2:$L$26,3,0),0,1),"T")) | BC13: =IF(COUNTA($B13)=0,"",IFERROR(IF(X13<=VLOOKUP($H13,Listas!$J$2:$L$26,3,0),0,1),"T")) | BD13: =IF(COUNTA($B13)=0,"",IFERROR(IF(Y13<=VLOOKUP($H13,Listas!$J$2:$L$26,3,0),0,1),"T")) | BE13: =IF(COUNTA($B13)=0,"",IFERROR(IF(Z13<=VLOOKUP($H13,Listas!$J$2:$L$26,3,0),0,1),"T")) | BF13: =IF(COUNTA($B13)=0,"",IFERROR(IF(AA13<=VLOOKUP($H13,Listas!$J$2:$L$26,3,0),0,1),"T")) | BG13: =IF(COUNTA($B13)=0,"",IFERROR(IF(AB13<=VLOOKUP($H13,Listas!$J$2:$L$26,3,0),0,1),"T")) | BH13: =IF(COUNTA($B13)=0,"",IFERROR(IF(AC13<=VLOOKUP($H13,Listas!$J$2:$L$26,3,0),0,1),"T")) | ... CE13: =IF(COUNTA($B13)=0,"",IFERROR(IF(AZ13<=VLOOKUP($H13,Listas!$J$2:$L$26,3,0),0,1),"T"))
BA14: =IF(COUNTA($B14)=0,"",IFERROR(IF(V14<=VLOOKUP($H14,Listas!$J$2:$L$26,3,0),0,1),"T")) | BB14: =IF(COUNTA($B14)=0,"",IFERROR(IF(W14<=VLOOKUP($H14,Listas!$J$2:$L$26,3,0),0,1),"T")) | BC14: =IF(COUNTA($B14)=0,"",IFERROR(IF(X14<=VLOOKUP($H14,Listas!$J$2:$L$26,3,0),0,1),"T")) | BD14: =IF(COUNTA($B14)=0,"",IFERROR(IF(Y14<=VLOOKUP($H14,Listas!$J$2:$L$26,3,0),0,1),"T")) | BE14: =IF(COUNTA($B14)=0,"",IFERROR(IF(Z14<=VLOOKUP($H14,Listas!$J$2:$L$26,3,0),0,1),"T")) | BF14: =IF(COUNTA($B14)=0,"",IFERROR(IF(AA14<=VLOOKUP($H14,Listas!$J$2:$L$26,3,0),0,1),"T")) | BG14: =IF(COUNTA($B14)=0,"",IFERROR(IF(AB14<=VLOOKUP($H14,Listas!$J$2:$L$26,3,0),0,1),"T")) | BH14: =IF(COUNTA($B14)=0,"",IFERROR(IF(AC14<=VLOOKUP($H14,Listas!$J$2:$L$26,3,0),0,1),"T")) | ... CE14: =IF(COUNTA($B14)=0,"",IFERROR(IF(AZ14<=VLOOKUP($H14,Listas!$J$2:$L$26,3,0),0,1),"T"))
BA15: =IF(COUNTA($B15)=0,"",IFERROR(IF(V15<=VLOOKUP($H15,Listas!$J$2:$L$26,3,0),0,1),"T")) | BB15: =IF(COUNTA($B15)=0,"",IFERROR(IF(W15<=VLOOKUP($H15,Listas!$J$2:$L$26,3,0),0,1),"T")) | BC15: =IF(COUNTA($B15)=0,"",IFERROR(IF(X15<=VLOOKUP($H15,Listas!$J$2:$L$26,3,0),0,1),"T")) | BD15: =IF(COUNTA($B15)=0,"",IFERROR(IF(Y15<=VLOOKUP($H15,Listas!$J$2:$L$26,3,0),0,1),"T")) | BE15: =IF(COUNTA($B15)=0,"",IFERROR(IF(Z15<=VLOOKUP($H15,Listas!$J$2:$L$26,3,0),0,1),"T")) | BF15: =IF(COUNTA($B15)=0,"",IFERROR(IF(AA15<=VLOOKUP($H15,Listas!$J$2:$L$26,3,0),0,1),"T")) | BG15: =IF(COUNTA($B15)=0,"",IFERROR(IF(AB15<=VLOOKUP($H15,Listas!$J$2:$L$26,3,0),0,1),"T")) | BH15: =IF(COUNTA($B15)=0,"",IFERROR(IF(AC15<=VLOOKUP($H15,Listas!$J$2:$L$26,3,0),0,1),"T")) | ... CE15: =IF(COUNTA($B15)=0,"",IFERROR(IF(AZ15<=VLOOKUP($H15,Listas!$J$2:$L$26,3,0),0,1),"T"))
BA16: =IF(COUNTA($B16)=0,"",IFERROR(IF(V16<=VLOOKUP($H16,Listas!$J$2:$L$26,3,0),0,1),"T")) | BB16: =IF(COUNTA($B16)=0,"",IFERROR(IF(W16<=VLOOKUP($H16,Listas!$J$2:$L$26,3,0),0,1),"T")) | BC16: =IF(COUNTA($B16)=0,"",IFERROR(IF(X16<=VLOOKUP($H16,Listas!$J$2:$L$26,3,0),0,1),"T")) | BD16: =IF(COUNTA($B16)=0,"",IFERROR(IF(Y16<=VLOOKUP($H16,Listas!$J$2:$L$26,3,0),0,1),"T")) | BE16: =IF(COUNTA($B16)=0,"",IFERROR(IF(Z16<=VLOOKUP($H16,Listas!$J$2:$L$26,3,0),0,1),"T")) | BF16: =IF(COUNTA($B16)=0,"",IFERROR(IF(AA16<=VLOOKUP($H16,Listas!$J$2:$L$26,3,0),0,1),"T")) | BG16: =IF(COUNTA($B16)=0,"",IFERROR(IF(AB16<=VLOOKUP($H16,Listas!$J$2:$L$26,3,0),0,1),"T")) | BH16: =IF(COUNTA($B16)=0,"",IFERROR(IF(AC16<=VLOOKUP($H16,Listas!$J$2:$L$26,3,0),0,1),"T")) | ... CE16: =IF(COUNTA($B16)=0,"",IFERROR(IF(AZ16<=VLOOKUP($H16,Listas!$J$2:$L$26,3,0),0,1),"T"))
BA17: =IF(COUNTA($B17)=0,"",IFERROR(IF(V17<=VLOOKUP($H17,Listas!$J$2:$L$26,3,0),0,1),"T")) | BB17: =IF(COUNTA($B17)=0,"",IFERROR(IF(W17<=VLOOKUP($H17,Listas!$J$2:$L$26,3,0),0,1),"T")) | BC17: =IF(COUNTA($B17)=0,"",IFERROR(IF(X17<=VLOOKUP($H17,Listas!$J$2:$L$26,3,0),0,1),"T")) | BD17: =IF(COUNTA($B17)=0,"",IFERROR(IF(Y17<=VLOOKUP($H17,Listas!$J$2:$L$26,3,0),0,1),"T")) | BE17: =IF(COUNTA($B17)=0,"",IFERROR(IF(Z17<=VLOOKUP($H17,Listas!$J$2:$L$26,3,0),0,1),"T")) | BF17: =IF(COUNTA($B17)=0,"",IFERROR(IF(AA17<=VLOOKUP($H17,Listas!$J$2:$L$26,3,0),0,1),"T")) | BG17: =IF(COUNTA($B17)=0,"",IFERROR(IF(AB17<=VLOOKUP($H17,Listas!$J$2:$L$26,3,0),0,1),"T")) | BH17: =IF(COUNTA($B17)=0,"",IFERROR(IF(AC17<=VLOOKUP($H17,Listas!$J$2:$L$26,3,0),0,1),"T")) | ... CE17: =IF(COUNTA($B17)=0,"",IFERROR(IF(AZ17<=VLOOKUP($H17,Listas!$J$2:$L$26,3,0),0,1),"T"))
... BA596: =IF(COUNTA($B596)=0,"",IFERROR(IF(V596<=VLOOKUP($H596,Listas!$J$2:$L$26,3,0),0,1),"T")) | BB596: =IF(COUNTA($B596)=0,"",IFERROR(IF(W596<=VLOOKUP($H596,Listas!$J$2:$L$26,3,0),0,1),"T")) | BC596: =IF(COUNTA($B596)=0,"",IFERROR(IF(X596<=VLOOKUP($H596,Listas!$J$2:$L$26,3,0),0,1),"T")) | BD596: =IF(COUNTA($B596)=0,"",IFERROR(IF(Y596<=VLOOKUP($H596,Listas!$J$2:$L$26,3,0),0,1),"T")) | BE596: =IF(COUNTA($B596)=0,"",IFERROR(IF(Z596<=VLOOKUP($H596,Listas!$J$2:$L$26,3,0),0,1),"T")) | BF596: =IF(COUNTA($B596)=0,"",IFERROR(IF(AA596<=VLOOKUP($H596,Listas!$J$2:$L$26,3,0),0,1),"T")) | BG596: =IF(COUNTA($B596)=0,"",IFERROR(IF(AB596<=VLOOKUP($H596,Listas!$J$2:$L$26,3,0),0,1),"T")) | BH596: =IF(COUNTA($B596)=0,"",IFERROR(IF(AC596<=VLOOKUP($H596,Listas!$J$2:$L$26,3,0),0,1),"T")) | ... CE596: =IF(COUNTA($B596)=0,"",IFERROR(IF(AZ596<=VLOOKUP($H596,Listas!$J$2:$L$26,3,0),0,1),"T"))

Sheet Desv_Perm
B2: DETALLE DESVINCULACION : "T R A B A J A D O R P E R M A N E N T E"
B6: A N T E C E D E N T E S G E N E R A L E S D E L T R A B A J A D O R D E S V I N C U L A D O E N E L P E R I O D O
B7: RUT | C7: NOMBRES | D7: APELLIDO PATERNO | E7: APELLIDO MATERNO | F7: FECHA INGRESO | G7: FECHA DE TERMINO | H7: CAUSAL | I7: CARGO LABORAL | J7: CIUDAD / LOCALIDAD

Sheet Nomina_Temp _EnFaena
B1: A N T E C E D E N T E S G E N E R A L E S D E L T R A B A J A D O R E S P O R A D I C O | R1: ACOGIDOS A LEY 21.227 (PROTECCION AL EMPLEO) | T1: ACOGIDOS A LA LEY 21.220 | U1: JORNADA LABORAL | V1: Horas del mes (ingresar horas trabajadas correspondientes al turno de cada trabajador). Si el trabajador no estuvo presente, entonces registrar el valor 0 | BA1: Validaciones
B2: RUT | C2: NOMBRES | D2: APELLIDO PATERNO | E2: APELLIDO MATERNO | F2: FECHA NACIMIENTO | G2: TIPO CONTRATO | H2: TURNO | I2: CARGO | J2: FECHA INGRESO | K2: DOMICILIO PARTICULAR | L2: LOCALIDAD / CIUDAD | M2: REGION | N2: TELEFONO DE CONTACTO | O2: LUGAR DONDE PERNOCTAN | P2: N° DÍAS LICENCIA MEDICA | Q2: SEXO | R2: PACTO REDUCCION TEMPORAL | S2: PACTO SUSPENSION TEMPORAL | T2: TELETRABAJO | V2: 1 | W2: 2 | X2: 3 | Y2: 4 | Z2: 5 | AA2: 6 | AB2: 7 | AC2: 8 | AD2: 9 | AE2: 10 | AF2: 11 | AG2: 12 | AH2: 13 | AI2: 14 | AJ2: 15 | AK2: 16 | AL2: 17 | AM2: 18 | AN2: 19 | AO2: 20 | AP2: 21 | AQ2: 22 | AR2: 23 | AS2: 24 | AT2: 25 | AU2: 26 | AV2: 27 | AW2: 28 | AX2: 29 | AY2: 30 | AZ2: 31 | BA2: 1 | BB2: 2 | BC2: 3 | BD2: 4 | BE2: 5 | BF2: 6 | BG2: 7 | BH2: 8 | BI2: 9 | BJ2: 10 | BK2: 11 | BL2: 12 | BM2: 13 | BN2: 14 | BO2: 15 | BP2: 16 | BQ2: 17 | BR2: 18 | BS2: 19 | BT2: 20 | BU2: 21 | BV2: 22 | BW2: 23 | BX2: 24 | BY2: 25 | BZ2: 26 | CA2: 27 | CB2: 28 | CC2: 29 | CD2: 30 | CE2: 31

Sheet Nomina_Temp_Fuera
B1: A N T E C E D E N T E S G E N E R A L E S D E L T R A B A J A D O R E S P O R A D I C O | R1: ACOGIDOS A LEY 21.227 (PROTECCION AL EMPLEO) | T1: ACOGIDOS A LA LEY 21.220 | U1: JORNADA LABORAL | V1: Horas del mes (ingresar horas trabajadas correspondientes al turno de cada trabajador). Si el trabajador no estuvo presente, entonces registrar el valor 0 | BA1: Validaciones
B2: RUT | C2: NOMBRES | D2: APELLIDO PATERNO | E2: APELLIDO MATERNO | F2: FECHA NACIMIENTO | G2: TIPO CONTRATO | H2: TURNO | I2: CARGO | J2: FECHA INGRESO | K2: DOMICILIO PARTICULAR | L2: LOCALIDAD / CIUDAD | M2: REGION | N2: TELEFONO DE CONTACTO | O2: LUGAR DONDE PERNOCTAN | P2: N° DÍAS LICENCIA MEDICA | Q2: SEXO | R2: PACTO REDUCCION TEMPORAL | S2: PACTO SUSPENSION TEMPORAL | T2: TELETRABAJO | V2: 1 | W2: 2 | X2: 3 | Y2: 4 | Z2: 5 | AA2: 6 | AB2: 7 | AC2: 8 | AD2: 9 | AE2: 10 | AF2: 11 | AG2: 12 | AH2: 13 | AI2: 14 | AJ2: 15 | AK2: 16 | AL2: 17 | AM2: 18 | AN2: 19 | AO2: 20 | AP2: 21 | AQ2: 22 | AR2: 23 | AS2: 24 | AT2: 25 | AU2: 26 | AV2: 27 | AW2: 28 | AX2: 29 | AY2: 30 | AZ2: 31 | BA2: 1 | BB2: 2 | BC2: 3 | BD2: 4 | BE2: 5 | BF2: 6 | BG2: 7 | BH2: 8 | BI2: 9 | BJ2: 10 | BK2: 11 | BL2: 12 | BM2: 13 | BN2: 14 | BO2: 15 | BP2: 16 | BQ2: 17 | BR2: 18 | BS2: 19 | BT2: 20 | BU2: 21 | BV2: 22 | BW2: 23 | BX2: 24 | BY2: 25 | BZ2: 26 | CA2: 27 | CB2: 28 | CC2: 29 | CD2: 30 | CE2: 31
BA3: =IF(COUNTA($B3)=0,"",IFERROR(IF(V3<=VLOOKUP($H3,Listas!$J$2:$L$26,3,0),0,1),"T")) | BB3: =IF(COUNTA($B3)=0,"",IFERROR(IF(W3<=VLOOKUP($H3,Listas!$J$2:$L$26,3,0),0,1),"T")) | BC3: =IF(COUNTA($B3)=0,"",IFERROR(IF(X3<=VLOOKUP($H3,Listas!$J$2:$L$26,3,0),0,1),"T")) | BD3: =IF(COUNTA($B3)=0,"",IFERROR(IF(Y3<=VLOOKUP($H3,Listas!$J$2:$L$26,3,0),0,1),"T")) | BE3: =IF(COUNTA($B3)=0,"",IFERROR(IF(Z3<=VLOOKUP($H3,Listas!$J$2:$L$26,3,0),0,1),"T")) | BF3: =IF(COUNTA($B3)=0,"",IFERROR(IF(AA3<=VLOOKUP($H3,Listas!$J$2:$L$26,3,0),0,1),"T")) | BG3: =IF(COUNTA($B3)=0,"",IFERROR(IF(AB3<=VLOOKUP($H3,Listas!$J$2:$L$26,3,0),0,1),"T")) | BH3: =IF(COUNTA($B3)=0,"",IFERROR(IF(AC3<=VLOOKUP($H3,Listas!$J$2:$L$26,3,0),0,1),"T")) | ... CE3: =IF(COUNTA($B3)=0,"",IFERROR(IF(AZ3<=VLOOKUP($H3,Listas!$J$2:$L$26,3,0),0,1),"T"))
BA4: =IF(COUNTA($B4)=0,"",IFERROR(IF(V4<=VLOOKUP($H4,Listas!$J$2:$L$26,3,0),0,1),"T")) | BB4: =IF(COUNTA($B4)=0,"",IFERROR(IF(W4<=VLOOKUP($H4,Listas!$J$2:$L$26,3,0),0,1),"T")) | BC4: =IF(COUNTA($B4)=0,"",IFERROR(IF(X4<=VLOOKUP($H4,Listas!$J$2:$L$26,3,0),0,1),"T")) | BD4: =IF(COUNTA($B4)=0,"",IFERROR(IF(Y4<=VLOOKUP($H4,Listas!$J$2:$L$26,3,0),0,1),"T")) | BE4: =IF(COUNTA($B4)=0,"",IFERROR(IF(Z4<=VLOOKUP($H4,Listas!$J$2:$L$26,3,0),0,1),"T")) | BF4: =IF(COUNTA($B4)=0,"",IFERROR(IF(AA4<=VLOOKUP($H4,Listas!$J$2:$L$26,3,0),0,1),"T")) | BG4: =IF(COUNTA($B4)=0,"",IFERROR(IF(AB4<=VLOOKUP($H4,Listas!$J$2:$L$26,3,0),0,1),"T")) | BH4: =IF(COUNTA($B4)=0,"",IFERROR(IF(AC4<=VLOOKUP($H4,Listas!$J$2:$L$26,3,0),0,1),"T")) | ... CE4: =IF(COUNTA($B4)=0,"",IFERROR(IF(AZ4<=VLOOKUP($H4,Listas!$J$2:$L$26,3,0),0,1),"T"))
BA5: =IF(COUNTA($B5)=0,"",IFERROR(IF(V5<=VLOOKUP($H5,Listas!$J$2:$L$26,3,0),0,1),"T")) | BB5: =IF(COUNTA($B5)=0,"",IFERROR(IF(W5<=VLOOKUP($H5,Listas!$J$2:$L$26,3,0),0,1),"T")) | BC5: =IF(COUNTA($B5)=0,"",IFERROR(IF(X5<=VLOOKUP($H5,Listas!$J$2:$L$26,3,0),0,1),"T")) | BD5: =IF(COUNTA($B5)=0,"",IFERROR(IF(Y5<=VLOOKUP($H5,Listas!$J$2:$L$26,3,0),0,1),"T")) | BE5: =IF(COUNTA($B5)=0,"",IFERROR(IF(Z5<=VLOOKUP($H5,Listas!$J$2:$L$26,3,0),0,1),"T")) | BF5: =IF(COUNTA($B5)=0,"",IFERROR(IF(AA5<=VLOOKUP($H5,Listas!$J$2:$L$26,3,0),0,1),"T")) | BG5: =IF(COUNTA($B5)=0,"",IFERROR(IF(AB5<=VLOOKUP($H5,Listas!$J$2:$L$26,3,0),0,1),"T")) | BH5: =IF(COUNTA($B5)=0,"",IFERROR(IF(AC5<=VLOOKUP($H5,Listas!$J$2:$L$26,3,0),0,1),"T")) | ... CE5: =IF(COUNTA($B5)=0,"",IFERROR(IF(AZ5<=VLOOKUP($H5,Listas!$J$2:$L$26,3,0),0,1),"T"))
BA6: =IF(COUNTA($B6)=0,"",IFERROR(IF(V6<=VLOOKUP($H6,Listas!$J$2:$L$26,3,0),0,1),"T")) | BB6: =IF(COUNTA($B6)=0,"",IFERROR(IF(W6<=VLOOKUP($H6,Listas!$J$2:$L$26,3,0),0,1),"T")) | BC6: =IF(COUNTA($B6)=0,"",IFERROR(IF(X6<=VLOOKUP($H6,Listas!$J$2:$L$26,3,0),0,1),"T")) | BD6: =IF(COUNTA($B6)=0,"",IFERROR(IF(Y6<=VLOOKUP($H6,Listas!$J$2:$L$26,3,0),0,1),"T")) | BE6: =IF(COUNTA($B6)=0,"",IFERROR(IF(Z6<=VLOOKUP($H6,Listas!$J$2:$L$26,3,0),0,1),"T")) | BF6: =IF(COUNTA($B6)=0,"",IFERROR(IF(AA6<=VLOOKUP($H6,Listas!$J$2:$L$26,3,0),0,1),"T")) | BG6: =IF(COUNTA($B6)=0,"",IFERROR(IF(AB6<=VLOOKUP($H6,Listas!$J$2:$L$26,3,0),0,1),"T")) | BH6: =IF(COUNTA($B6)=0,"",IFERROR(IF(AC6<=VLOOKUP($H6,Listas!$J$2:$L$26,3,0),0,1),"T")) | ... CE6: =IF(COUNTA($B6)=0,"",IFERROR(IF(AZ6<=VLOOKUP($H6,Listas!$J$2:$L$26,3,0),0,1),"T"))
BA7: =IF(COUNTA($B7)=0,"",IFERROR(IF(V7<=VLOOKUP($H7,Listas!$J$2:$L$26,3,0),0,1),"T")) | BB7: =IF(COUNTA($B7)=0,"",IFERROR(IF(W7<=VLOOKUP($H7,Listas!$J$2:$L$26,3,0),0,1),"T")) | BC7: =IF(COUNTA($B7)=0,"",IFERROR(IF(X7<=VLOOKUP($H7,Listas!$J$2:$L$26,3,0),0,1),"T")) | BD7: =IF(COUNTA($B7)=0,"",IFERROR(IF(Y7<=VLOOKUP($H7,Listas!$J$2:$L$26,3,0),0,1),"T")) | BE7: =IF(COUNTA($B7)=0,"",IFERROR(IF(Z7<=VLOOKUP($H7,Listas!$J$2:$L$26,3,0),0,1),"T")) | BF7: =IF(COUNTA($B7)=0,"",IFERROR(IF(AA7<=VLOOKUP($H7,Listas!$J$2:$L$26,3,0),0,1),"T")) | BG7: =IF(COUNTA($B7)=0,"",IFERROR(IF(AB7<=VLOOKUP($H7,Listas!$J$2:$L$26,3,0),0,1),"T")) | BH7: =IF(COUNTA($B7)=0,"",IFERROR(IF(AC7<=VLOOKUP($H7,Listas!$J$2:$L$26,3,0),0,1),"T")) | ... CE7: =IF(COUNTA($B7)=0,"",IFERROR(IF(AZ7<=VLOOKUP($H7,Listas!$J$2:$L$26,3,0),0,1),"T"))
BA8: =IF(COUNTA($B8)=0,"",IFERROR(IF(V8<=VLOOKUP($H8,Listas!$J$2:$L$26,3,0),0,1),"T")) | BB8: =IF(COUNTA($B8)=0,"",IFERROR(IF(W8<=VLOOKUP($H8,Listas!$J$2:$L$26,3,0),0,1),"T")) | BC8: =IF(COUNTA($B8)=0,"",IFERROR(IF(X8<=VLOOKUP($H8,Listas!$J$2:$L$26,3,0),0,1),"T")) | BD8: =IF(COUNTA($B8)=0,"",IFERROR(IF(Y8<=VLOOKUP($H8,Listas!$J$2:$L$26,3,0),0,1),"T")) | BE8: =IF(COUNTA($B8)=0,"",IFERROR(IF(Z8<=VLOOKUP($H8,Listas!$J$2:$L$26,3,0),0,1),"T")) | BF8: =IF(COUNTA($B8)=0,"",IFERROR(IF(AA8<=VLOOKUP($H8,Listas!$J$2:$L$26,3,0),0,1),"T")) | BG8: =IF(COUNTA($B8)=0,"",IFERROR(IF(AB8<=VLOOKUP($H8,Listas!$J$2:$L$26,3,0),0,1),"T")) | BH8: =IF(COUNTA($B8)=0,"",IFERROR(IF(AC8<=VLOOKUP($H8,Listas!$J$2:$L$26,3,0),0,1),"T")) | ... CE8: =IF(COUNTA($B8)=0,"",IFERROR(IF(AZ8<=VLOOKUP($H8,Listas!$J$2:$L$26,3,0),0,1),"T"))
BA9: =IF(COUNTA($B9)=0,"",IFERROR(IF(V9<=VLOOKUP($H9,Listas!$J$2:$L$26,3,0),0,1),"T")) | BB9: =IF(COUNTA($B9)=0,"",IFERROR(IF(W9<=VLOOKUP($H9,Listas!$J$2:$L$26,3,0),0,1),"T")) | BC9: =IF(COUNTA($B9)=0,"",IFERROR(IF(X9<=VLOOKUP($H9,Listas!$J$2:$L$26,3,0),0,1),"T")) | BD9: =IF(COUNTA($B9)=0,"",IFERROR(IF(Y9<=VLOOKUP($H9,Listas!$J$2:$L$26,3,0),0,1),"T")) | BE9: =IF(COUNTA($B9)=0,"",IFERROR(IF(Z9<=VLOOKUP($H9,Listas!$J$2:$L$26,3,0),0,1),"T")) | BF9: =IF(COUNTA($B9)=0,"",IFERROR(IF(AA9<=VLOOKUP($H9,Listas!$J$2:$L$26,3,0),0,1),"T")) | BG9: =IF(COUNTA($B9)=0,"",IFERROR(IF(AB9<=VLOOKUP($H9,Listas!$J$2:$L$26,3,0),0,1),"T")) | BH9: =IF(COUNTA($B9)=0,"",IFERROR(IF(AC9<=VLOOKUP($H9,Listas!$J$2:$L$26,3,0),0,1),"T")) | ... CE9: =IF(COUNTA($B9)=0,"",IFERROR(IF(AZ9<=VLOOKUP($H9,Listas!$J$2:$L$26,3,0),0,1),"T"))
BA10: =IF(COUNTA($B10)=0,"",IFERROR(IF(V10<=VLOOKUP($H10,Listas!$J$2:$L$26,3,0),0,1),"T")) | BB10: =IF(COUNTA($B10)=0,"",IFERROR(IF(W10<=VLOOKUP($H10,Listas!$J$2:$L$26,3,0),0,1),"T")) | BC10: =IF(COUNTA($B10)=0,"",IFERROR(IF(X10<=VLOOKUP($H10,Listas!$J$2:$L$26,3,0),0,1),"T")) | BD10: =IF(COUNTA($B10)=0,"",IFERROR(IF(Y10<=VLOOKUP($H10,Listas!$J$2:$L$26,3,0),0,1),"T")) | BE10: =IF(COUNTA($B10)=0,"",IFERROR(IF(Z10<=VLOOKUP($H10,Listas!$J$2:$L$26,3,0),0,1),"T")) | BF10: =IF(COUNTA($B10)=0,"",IFERROR(IF(AA10<=VLOOKUP($H10,Listas!$J$2:$L$26,3,0),0,1),"T")) | BG10: =IF(COUNTA($B10)=0,"",IFERROR(IF(AB10<=VLOOKUP($H10,Listas!$J$2:$L$26,3,0),0,1),"T")) | BH10: =IF(COUNTA($B10)=0,"",IFERROR(IF(AC10<=VLOOKUP($H10,Listas!$J$2:$L$26,3,0),0,1),"T")) | ... CE10: =IF(COUNTA($B10)=0,"",IFERROR(IF(AZ10<=VLOOKUP($H10,Listas!$J$2:$L$26,3,0),0,1),"T"))
BA11: =IF(COUNTA($B11)=0,"",IFERROR(IF(V11<=VLOOKUP($H11,Listas!$J$2:$L$26,3,0),0,1),"T")) | BB11: =IF(COUNTA($B11)=0,"",IFERROR(IF(W11<=VLOOKUP($H11,Listas!$J$2:$L$26,3,0),0,1),"T")) | BC11: =IF(COUNTA($B11)=0,"",IFERROR(IF(X11<=VLOOKUP($H11,Listas!$J$2:$L$26,3,0),0,1),"T")) | BD11: =IF(COUNTA($B11)=0,"",IFERROR(IF(Y11<=VLOOKUP($H11,Listas!$J$2:$L$26,3,0),0,1),"T")) | BE11: =IF(COUNTA($B11)=0,"",IFERROR(IF(Z11<=VLOOKUP($H11,Listas!$J$2:$L$26,3,0),0,1),"T")) | BF11: =IF(COUNTA($B11)=0,"",IFERROR(IF(AA11<=VLOOKUP($H11,Listas!$J$2:$L$26,3,0),0,1),"T")) | BG11: =IF(COUNTA($B11)=0,"",IFERROR(IF(AB11<=VLOOKUP($H11,Listas!$J$2:$L$26,3,0),0,1),"T")) | BH11: =IF(COUNTA($B11)=0,"",IFERROR(IF(AC11<=VLOOKUP($H11,Listas!$J$2:$L$26,3,0),0,1),"T")) | ... CE11: =IF(COUNTA($B11)=0,"",IFERROR(IF(AZ11<=VLOOKUP($H11,Listas!$J$2:$L$26,3,0),0,1),"T"))
BA12: =IF(COUNTA($B12)=0,"",IFERROR(IF(V12<=VLOOKUP($H12,Listas!$J$2:$L$26,3,0),0,1),"T")) | BB12: =IF(COUNTA($B12)=0,"",IFERROR(IF(W12<=VLOOKUP($H12,Listas!$J$2:$L$26,3,0),0,1),"T")) | BC12: =IF(COUNTA($B12)=0,"",IFERROR(IF(X12<=VLOOKUP($H12,Listas!$J$2:$L$26,3,0),0,1),"T")) | BD12: =IF(COUNTA($B12)=0,"",IFERROR(IF(Y12<=VLOOKUP($H12,Listas!$J$2:$L$26,3,0),0,1),"T")) | BE12: =IF(COUNTA($B12)=0,"",IFERROR(IF(Z12<=VLOOKUP($H12,Listas!$J$2:$L$26,3,0),0,1),"T")) | BF12: =IF(COUNTA($B12)=0,"",IFERROR(IF(AA12<=VLOOKUP($H12,Listas!$J$2:$L$26,3,0),0,1),"T")) | BG12: =IF(COUNTA($B12)=0,"",IFERROR(IF(AB12<=VLOOKUP($H12,Listas!$J$2:$L$26,3,0),0,1),"T")) | BH12: =IF(COUNTA($B12)=0,"",IFERROR(IF(AC12<=VLOOKUP($H12,Listas!$J$2:$L$26,3,0),0,1),"T")) | ... CE12: =IF(COUNTA($B12)=0,"",IFERROR(IF(AZ12<=VLOOKUP($H12,Listas!$J$2:$L$26,3,0),0,1),"T"))
BA13: =IF(COUNTA($B13)=0,"",IFERROR(IF(V13<=VLOOKUP($H13,Listas!$J$2:$L$26,3,0),0,1),"T")) | BB13: =IF(COUNTA($B13)=0,"",IFERROR(IF(W13<=VLOOKUP($H13,Listas!$J$2:$L$26,3,0),0,1),"T")) | BC13: =IF(COUNTA($B13)=0,"",IFERROR(IF(X13<=VLOOKUP($H13,Listas!$J$2:$L$26,3,0),0,1),"T")) | BD13: =IF(COUNTA($B13)=0,"",IFERROR(IF(Y13<=VLOOKUP($H13,Listas!$J$2:$L$26,3,0),0,1),"T")) | BE13: =IF(COUNTA($B13)=0,"",IFERROR(IF(Z13<=VLOOKUP($H13,Listas!$J$2:$L$26,3,0),0,1),"T")) | BF13: =IF(COUNTA($B13)=0,"",IFERROR(IF(AA13<=VLOOKUP($H13,Listas!$J$2:$L$26,3,0),0,1),"T")) | BG13: =IF(COUNTA($B13)=0,"",IFERROR(IF(AB13<=VLOOKUP($H13,Listas!$J$2:$L$26,3,0),0,1),"T")) | BH13: =IF(COUNTA($B13)=0,"",IFERROR(IF(AC13<=VLOOKUP($H13,Listas!$J$2:$L$26,3,0),0,1),"T")) | ... CE13: =IF(COUNTA($B13)=0,"",IFERROR(IF(AZ13<=VLOOKUP($H13,Listas!$J$2:$L$26,3,0),0,1),"T"))
BA14: =IF(COUNTA($B14)=0,"",IFERROR(IF(V14<=VLOOKUP($H14,Listas!$J$2:$L$26,3,0),0,1),"T")) | BB14: =IF(COUNTA($B14)=0,"",IFERROR(IF(W14<=VLOOKUP($H14,Listas!$J$2:$L$26,3,0),0,1),"T")) | BC14: =IF(COUNTA($B14)=0,"",IFERROR(IF(X14<=VLOOKUP($H14,Listas!$J$2:$L$26,3,0),0,1),"T")) | BD14: =IF(COUNTA($B14)=0,"",IFERROR(IF(Y14<=VLOOKUP($H14,Listas!$J$2:$L$26,3,0),0,1),"T")) | BE14: =IF(COUNTA($B14)=0,"",IFERROR(IF(Z14<=VLOOKUP($H14,Listas!$J$2:$L$26,3,0),0,1),"T")) | BF14: =IF(COUNTA($B14)=0,"",IFERROR(IF(AA14<=VLOOKUP($H14,Listas!$J$2:$L$26,3,0),0,1),"T")) | BG14: =IF(COUNTA($B14)=0,"",IFERROR(IF(AB14<=VLOOKUP($H14,Listas!$J$2:$L$26,3,0),0,1),"T")) | BH14: =IF(COUNTA($B14)=0,"",IFERROR(IF(AC14<=VLOOKUP($H14,Listas!$J$2:$L$26,3,0),0,1),"T")) | ... CE14: =IF(COUNTA($B14)=0,"",IFERROR(IF(AZ14<=VLOOKUP($H14,Listas!$J$2:$L$26,3,0),0,1),"T"))
... BA600: =IF(COUNTA($B600)=0,"",IFERROR(IF(V600<=VLOOKUP($H600,Listas!$J$2:$L$26,3,0),0,1),"T")) | BB600: =IF(COUNTA($B600)=0,"",IFERROR(IF(W600<=VLOOKUP($H600,Listas!$J$2:$L$26,3,0),0,1),"T")) | BC600: =IF(COUNTA($B600)=0,"",IFERROR(IF(X600<=VLOOKUP($H600,Listas!$J$2:$L$26,3,0),0,1),"T")) | BD600: =IF(COUNTA($B600)=0,"",IFERROR(IF(Y600<=VLOOKUP($H600,Listas!$J$2:$L$26,3,0),0,1),"T")) | BE600: =IF(COUNTA($B600)=0,"",IFERROR(IF(Z600<=VLOOKUP($H600,Listas!$J$2:$L$26,3,0),0,1),"T")) | BF600: =IF(COUNTA($B600)=0,"",IFERROR(IF(AA600<=VLOOKUP($H600,Listas!$J$2:$L$26,3,0),0,1),"T")) | BG600: =IF(COUNTA($B600)=0,"",IFERROR(IF(AB600<=VLOOKUP($H600,Listas!$J$2:$L$26,3,0),0,1),"T")) | BH600: =IF(COUNTA($B600)=0,"",IFERROR(IF(AC600<=VLOOKUP($H600,Listas!$J$2:$L$26,3,0),0,1),"T")) | ... CE600: =IF(COUNTA($B600)=0,"",IFERROR(IF(AZ600<=VLOOKUP($H600,Listas!$J$2:$L$26,3,0),0,1),"T"))

Sheet Nomina_Temp_Teletrabajo
B1: A N T E C E D E N T E S G E N E R A L E S D E L T R A B A J A D O R E S P O R A D I C O | R1: ACOGIDOS A LEY 21.227 (PROTECCION AL EMPLEO) | T1: ACOGIDOS A LA LEY 21.220 | U1: JORNADA LABORAL | V1: Horas del mes (ingresar horas trabajadas correspondientes al turno de cada trabajador). Si el trabajador no estuvo presente, entonces registrar el valor 0 | BA1: Validaciones
B2: RUT | C2: NOMBRES | D2: APELLIDO PATERNO | E2: APELLIDO MATERNO | F2: FECHA NACIMIENTO | G2: TIPO CONTRATO | H2: TURNO | I2: CARGO | J2: FECHA INGRESO | K2: DOMICILIO PARTICULAR | L2: LOCALIDAD / CIUDAD | M2: REGION | N2: TELEFONO DE CONTACTO | O2: LUGAR DONDE PERNOCTAN | P2: N° DÍAS LICENCIA MEDICA | Q2: SEXO | R2: PACTO REDUCCION TEMPORAL | S2: PACTO SUSPENSION TEMPORAL | T2: TELETRABAJO | V2: 1 | W2: 2 | X2: 3 | Y2: 4 | Z2: 5 | AA2: 6 | AB2: 7 | AC2: 8 | AD2: 9 | AE2: 10 | AF2: 11 | AG2: 12 | AH2: 13 | AI2: 14 | AJ2: 15 | AK2: 16 | AL2: 17 | AM2: 18 | AN2: 19 | AO2: 20 | AP2: 21 | AQ2: 22 | AR2: 23 | AS2: 24 | AT2: 25 | AU2: 26 | AV2: 27 | AW2: 28 | AX2: 29 | AY2: 30 | AZ2: 31 | BA2: 1 | BB2: 2 | BC2: 3 | BD2: 4 | BE2: 5 | BF2: 6 | BG2: 7 | BH2: 8 | BI2: 9 | BJ2: 10 | BK2: 11 | BL2: 12 | BM2: 13 | BN2: 14 | BO2: 15 | BP2: 16 | BQ2: 17 | BR2: 18 | BS2: 19 | BT2: 20 | BU2: 21 | BV2: 22 | BW2: 23 | BX2: 24 | BY2: 25 | BZ2: 26 | CA2: 27 | CB2: 28 | CC2: 29 | CD2: 30 | CE2: 31
BA3: =IF(COUNTA($B3)=0,"",IFERROR(IF(V3<=VLOOKUP($H3,Listas!$J$2:$L$26,3,0),0,1),"T")) | BB3: =IF(COUNTA($B3)=0,"",IFERROR(IF(W3<=VLOOKUP($H3,Listas!$J$2:$L$26,3,0),0,1),"T")) | BC3: =IF(COUNTA($B3)=0,"",IFERROR(IF(X3<=VLOOKUP($H3,Listas!$J$2:$L$26,3,0),0,1),"T")) | BD3: =IF(COUNTA($B3)=0,"",IFERROR(IF(Y3<=VLOOKUP($H3,Listas!$J$2:$L$26,3,0),0,1),"T")) | BE3: =IF(COUNTA($B3)=0,"",IFERROR(IF(Z3<=VLOOKUP($H3,Listas!$J$2:$L$26,3,0),0,1),"T")) | BF3: =IF(COUNTA($B3)=0,"",IFERROR(IF(AA3<=VLOOKUP($H3,Listas!$J$2:$L$26,3,0),0,1),"T")) | BG3: =IF(COUNTA($B3)=0,"",IFERROR(IF(AB3<=VLOOKUP($H3,Listas!$J$2:$L$26,3,0),0,1),"T")) | BH3: =IF(COUNTA($B3)=0,"",IFERROR(IF(AC3<=VLOOKUP($H3,Listas!$J$2:$L$26,3,0),0,1),"T")) | ... CE3: =IF(COUNTA($B3)=0,"",IFERROR(IF(AZ3<=VLOOKUP($H3,Listas!$J$2:$L$26,3,0),0,1),"T"))
BA4: =IF(COUNTA($B4)=0,"",IFERROR(IF(V4<=VLOOKUP($H4,Listas!$J$2:$L$26,3,0),0,1),"T")) | BB4: =IF(COUNTA($B4)=0,"",IFERROR(IF(W4<=VLOOKUP($H4,Listas!$J$2:$L$26,3,0),0,1),"T")) | BC4: =IF(COUNTA($B4)=0,"",IFERROR(IF(X4<=VLOOKUP($H4,Listas!$J$2:$L$26,3,0),0,1),"T")) | BD4: =IF(COUNTA($B4)=0,"",IFERROR(IF(Y4<=VLOOKUP($H4,Listas!$J$2:$L$26,3,0),0,1),"T")) | BE4: =IF(COUNTA($B4)=0,"",IFERROR(IF(Z4<=VLOOKUP($H4,Listas!$J$2:$L$26,3,0),0,1),"T")) | BF4: =IF(COUNTA($B4)=0,"",IFERROR(IF(AA4<=VLOOKUP($H4,Listas!$J$2:$L$26,3,0),0,1),"T")) | BG4: =IF(COUNTA($B4)=0,"",IFERROR(IF(AB4<=VLOOKUP($H4,Listas!$J$2:$L$26,3,0),0,1),"T")) | BH4: =IF(COUNTA($B4)=0,"",IFERROR(IF(AC4<=VLOOKUP($H4,Listas!$J$2:$L$26,3,0),0,1),"T")) | ... CE4: =IF(COUNTA($B4)=0,"",IFERROR(IF(AZ4<=VLOOKUP($H4,Listas!$J$2:$L$26,3,0),0,1),"T"))
BA5: =IF(COUNTA($B5)=0,"",IFERROR(IF(V5<=VLOOKUP($H5,Listas!$J$2:$L$26,3,0),0,1),"T")) | BB5: =IF(COUNTA($B5)=0,"",IFERROR(IF(W5<=VLOOKUP($H5,Listas!$J$2:$L$26,3,0),0,1),"T")) | BC5: =IF(COUNTA($B5)=0,"",IFERROR(IF(X5<=VLOOKUP($H5,Listas!$J$2:$L$26,3,0),0,1),"T")) | BD5: =IF(COUNTA($B5)=0,"",IFERROR(IF(Y5<=VLOOKUP($H5,Listas!$J$2:$L$26,3,0),0,1),"T")) | BE5: =IF(COUNTA($B5)=0,"",IFERROR(IF(Z5<=VLOOKUP($H5,Listas!$J$2:$L$26,3,0),0,1),"T")) | BF5: =IF(COUNTA($B5)=0,"",IFERROR(IF(AA5<=VLOOKUP($H5,Listas!$J$2:$L$26,3,0),0,1),"T")) | BG5: =IF(COUNTA($B5)=0,"",IFERROR(IF(AB5<=VLOOKUP($H5,Listas!$J$2:$L$26,3,0),0,1),"T")) | BH5: =IF(COUNTA($B5)=0,"",IFERROR(IF(AC5<=VLOOKUP($H5,Listas!$J$2:$L$26,3,0),0,1),"T")) | ... CE5: =IF(COUNTA($B5)=0,"",IFERROR(IF(AZ5<=VLOOKUP($H5,Listas!$J$2:$L$26,3,0),0,1),"T"))
BA6: =IF(COUNTA($B6)=0,"",IFERROR(IF(V6<=VLOOKUP($H6,Listas!$J$2:$L$26,3,0),0,1),"T")) | BB6: =IF(COUNTA($B6)=0,"",IFERROR(IF(W6<=VLOOKUP($H6,Listas!$J$2:$L$26,3,0),0,1),"T")) | BC6: =IF(COUNTA($B6)=0,"",IFERROR(IF(X6<=VLOOKUP($H6,Listas!$J$2:$L$26,3,0),0,1),"T")) | BD6: =IF(COUNTA($B6)=0,"",IFERROR(IF(Y6<=VLOOKUP($H6,Listas!$J$2:$L$26,3,0),0,1),"T")) | BE6: =IF(COUNTA($B6)=0,"",IFERROR(IF(Z6<=VLOOKUP($H6,Listas!$J$2:$L$26,3,0),0,1),"T")) | BF6: =IF(COUNTA($B6)=0,"",IFERROR(IF(AA6<=VLOOKUP($H6,Listas!$J$2:$L$26,3,0),0,1),"T")) | BG6: =IF(COUNTA($B6)=0,"",IFERROR(IF(AB6<=VLOOKUP($H6,Listas!$J$2:$L$26,3,0),0,1),"T")) | BH6: =IF(COUNTA($B6)=0,"",IFERROR(IF(AC6<=VLOOKUP($H6,Listas!$J$2:$L$26,3,0),0,1),"T")) | ... CE6: =IF(COUNTA($B6)=0,"",IFERROR(IF(AZ6<=VLOOKUP($H6,Listas!$J$2:$L$26,3,0),0,1),"T"))
BA7: =IF(COUNTA($B7)=0,"",IFERROR(IF(V7<=VLOOKUP($H7,Listas!$J$2:$L$26,3,0),0,1),"T")) | BB7: =IF(COUNTA($B7)=0,"",IFERROR(IF(W7<=VLOOKUP($H7,Listas!$J$2:$L$26,3,0),0,1),"T")) | BC7: =IF(COUNTA($B7)=0,"",IFERROR(IF(X7<=VLOOKUP($H7,Listas!$J$2:$L$26,3,0),0,1),"T")) | BD7: =IF(COUNTA($B7)=0,"",IFERROR(IF(Y7<=VLOOKUP($H7,Listas!$J$2:$L$26,3,0),0,1),"T")) | BE7: =IF(COUNTA($B7)=0,"",IFERROR(IF(Z7<=VLOOKUP($H7,Listas!$J$2:$L$26,3,0),0,1),"T")) | BF7: =IF(COUNTA($B7)=0,"",IFERROR(IF(AA7<=VLOOKUP($H7,Listas!$J$2:$L$26,3,0),0,1),"T")) | BG7: =IF(COUNTA($B7)=0,"",IFERROR(IF(AB7<=VLOOKUP($H7,Listas!$J$2:$L$26,3,0),0,1),"T")) | BH7: =IF(COUNTA($B7)=0,"",IFERROR(IF(AC7<=VLOOKUP($H7,Listas!$J$2:$L$26,3,0),0,1),"T")) | ... CE7: =IF(COUNTA($B7)=0,"",IFERROR(IF(AZ7<=VLOOKUP($H7,Listas!$J$2:$L$26,3,0),0,1),"T"))
BA8: =IF(COUNTA($B8)=0,"",IFERROR(IF(V8<=VLOOKUP($H8,Listas!$J$2:$L$26,3,0),0,1),"T")) | BB8: =IF(COUNTA($B8)=0,"",IFERROR(IF(W8<=VLOOKUP($H8,Listas!$J$2:$L$26,3,0),0,1),"T")) | BC8: =IF(COUNTA($B8)=0,"",IFERROR(IF(X8<=VLOOKUP($H8,Listas!$J$2:$L$26,3,0),0,1),"T")) | BD8: =IF(COUNTA($B8)=0,"",IFERROR(IF(Y8<=VLOOKUP($H8,Listas!$J$2:$L$26,3,0),0,1),"T")) | BE8: =IF(COUNTA($B8)=0,"",IFERROR(IF(Z8<=VLOOKUP($H8,Listas!$J$2:$L$26,3,0),0,1),"T")) | BF8: =IF(COUNTA($B8)=0,"",IFERROR(IF(AA8<=VLOOKUP($H8,Listas!$J$2:$L$26,3,0),0,1),"T")) | BG8: =IF(COUNTA($B8)=0,"",IFERROR(IF(AB8<=VLOOKUP($H8,Listas!$J$2:$L$26,3,0),0,1),"T")) | BH8: =IF(COUNTA($B8)=0,"",IFERROR(IF(AC8<=VLOOKUP($H8,Listas!$J$2:$L$26,3,0),0,1),"T")) | ... CE8: =IF(COUNTA($B8)=0,"",IFERROR(IF(AZ8<=VLOOKUP($H8,Listas!$J$2:$L$26,3,0),0,1),"T"))
BA9: =IF(COUNTA($B9)=0,"",IFERROR(IF(V9<=VLOOKUP($H9,Listas!$J$2:$L$26,3,0),0,1),"T")) | BB9: =IF(COUNTA($B9)=0,"",IFERROR(IF(W9<=VLOOKUP($H9,Listas!$J$2:$L$26,3,0),0,1),"T")) | BC9: =IF(COUNTA($B9)=0,"",IFERROR(IF(X9<=VLOOKUP($H9,Listas!$J$2:$L$26,3,0),0,1),"T")) | BD9: =IF(COUNTA($B9)=0,"",IFERROR(IF(Y9<=VLOOKUP($H9,Listas!$J$2:$L$26,3,0),0,1),"T")) | BE9: =IF(COUNTA($B9)=0,"",IFERROR(IF(Z9<=VLOOKUP($H9,Listas!$J$2:$L$26,3,0),0,1),"T")) | BF9: =IF(COUNTA($B9)=0,"",IFERROR(IF(AA9<=VLOOKUP($H9,Listas!$J$2:$L$26,3,0),0,1),"T")) | BG9: =IF(COUNTA($B9)=0,"",IFERROR(IF(AB9<=VLOOKUP($H9,Listas!$J$2:$L$26,3,0),0,1),"T")) | BH9: =IF(COUNTA($B9)=0,"",IFERROR(IF(AC9<=VLOOKUP($H9,Listas!$J$2:$L$26,3,0),0,1),"T")) | ... CE9: =IF(COUNTA($B9)=0,"",IFERROR(IF(AZ9<=VLOOKUP($H9,Listas!$J$2:$L$26,3,0),0,1),"T"))
BA10: =IF(COUNTA($B10)=0,"",IFERROR(IF(V10<=VLOOKUP($H10,Listas!$J$2:$L$26,3,0),0,1),"T")) | BB10: =IF(COUNTA($B10)=0,"",IFERROR(IF(W10<=VLOOKUP($H10,Listas!$J$2:$L$26,3,0),0,1),"T")) | BC10: =IF(COUNTA($B10)=0,"",IFERROR(IF(X10<=VLOOKUP($H10,Listas!$J$2:$L$26,3,0),0,1),"T")) | BD10: =IF(COUNTA($B10)=0,"",IFERROR(IF(Y10<=VLOOKUP($H10,Listas!$J$2:$L$26,3,0),0,1),"T")) | BE10: =IF(COUNTA($B10)=0,"",IFERROR(IF(Z10<=VLOOKUP($H10,Listas!$J$2:$L$26,3,0),0,1),"T")) | BF10: =IF(COUNTA($B10)=0,"",IFERROR(IF(AA10<=VLOOKUP($H10,Listas!$J$2:$L$26,3,0),0,1),"T")) | BG10: =IF(COUNTA($B10)=0,"",IFERROR(IF(AB10<=VLOOKUP($H10,Listas!$J$2:$L$26,3,0),0,1),"T")) | BH10: =IF(COUNTA($B10)=0,"",IFERROR(IF(AC10<=VLOOKUP($H10,Listas!$J$2:$L$26,3,0),0,1),"T")) | ... CE10: =IF(COUNTA($B10)=0,"",IFERROR(IF(AZ10<=VLOOKUP($H10,Listas!$J$2:$L$26,3,0),0,1),"T"))
BA11: =IF(COUNTA($B11)=0,"",IFERROR(IF(V11<=VLOOKUP($H11,Listas!$J$2:$L$26,3,0),0,1),"T")) | BB11: =IF(COUNTA($B11)=0,"",IFERROR(IF(W11<=VLOOKUP($H11,Listas!$J$2:$L$26,3,0),0,1),"T")) | BC11: =IF(COUNTA($B11)=0,"",IFERROR(IF(X11<=VLOOKUP($H11,Listas!$J$2:$L$26,3,0),0,1),"T")) | BD11: =IF(COUNTA($B11)=0,"",IFERROR(IF(Y11<=VLOOKUP($H11,Listas!$J$2:$L$26,3,0),0,1),"T")) | BE11: =IF(COUNTA($B11)=0,"",IFERROR(IF(Z11<=VLOOKUP($H11,Listas!$J$2:$L$26,3,0),0,1),"T")) | BF11: =IF(COUNTA($B11)=0,"",IFERROR(IF(AA11<=VLOOKUP($H11,Listas!$J$2:$L$26,3,0),0,1),"T")) | BG11: =IF(COUNTA($B11)=0,"",IFERROR(IF(AB11<=VLOOKUP($H11,Listas!$J$2:$L$26,3,0),0,1),"T")) | BH11: =IF(COUNTA($B11)=0,"",IFERROR(IF(AC11<=VLOOKUP($H11,Listas!$J$2:$L$26,3,0),0,1),"T")) | ... CE11: =IF(COUNTA($B11)=0,"",IFERROR(IF(AZ11<=VLOOKUP($H11,Listas!$J$2:$L$26,3,0),0,1),"T"))
